Workbook

Sheet CONTROL
B3: MODO | C3: LISTA | D3: COLOR
B4: VENTA | C4: AMARILLA | D4: BLANCO

Sheet CONFIG
A1: Lista | B1: Flete | C1: Ganancia | D1: Mosq | E1: Repartido | F1: Cobra | G1: Extra | J1: LISTAS | K1: COLORES | L1: LINEAS
A2: AMARILLA | B2: 0.06 | C2: 0.3 | D2: 0.6 | E2: 0.3 | F2: 0 | G2: 0.1 | J2: AMARILLA | K2: NEGRO | L2: HERRERO
A3: AZUL | B3: 0.1 | C3: 0.3 | D3: 0.6 | E3: 0.3 | F3: 0 | G3: 0.1 | J3: AZUL | K3: BLANCO | L3: MODENA
A4: VERDE | B4: 0.15 | C4: 0.35 | D4: 0.6 | E4: 0.3 | F4: 0 | G4: 0.1 | J4: VERDE | K4: BRONCE
A5: EMA | B5: 0.15 | C5: 0.4 | D5: 0.6 | E5: 0.3 | F5: 0 | G5: 0.1 | J5: EMA | K5: SIMIL MADERA
A6: GUILLE | B6: 0 | C6: 0.5 | D6: 0.6 | E6: 0 | F6: 0.242 | G6: 0.1 | J6: GUILLE
A9: COLOR | B9: % | D9: LINEA | F9: ANCHO_PUERTAS | H9: TIPO | I9: FACTOR
A10: NEGRO | B10: 0.3 | D10: HERRERO | F10: 0.8 | H10: CORREDIZO | I10: 1
A11: BLANCO | B11: 0 | D11: MODENA | F11: 0.7 | H11: ABRIR | I11: 1.05
A12: BRONCE | B12: 0.45 | F12: 0.9
A13: SIMIL MADERA | B13: 2.8
A18: LINEA | B18: LISTA | C18: DESCUENTO
A19: HERRERO | B19: AMARILLA | C19: 0.1
A20: HERRERO | B20: AZUL | C20: 0.12
A21: HERRERO | B21: VERDE | C21: 0.12
A22: MODENA | B22: AMARILLA | C22: 0.07
A23: MODENA | B23: AZUL | C23: 0.07
A24: MODENA | B24: VERDE | C24: 0.07
A31: TIPO | B31: FLETE | C31: GANANCIA | E31: PARAMETRO | F31: VALOR
A32: PVC | B32: 0.15 | C32: 0.4 | E32: DESCUENTO_GENERAL | F32: 0.05

Sheet ventana herrero
A1: MODO | B1: LINEA | C1: LISTA | D1: COLOR
A2: =CONTROL!B4 -> VENTA | B2: HERRERO | C2: =CONTROL!C4 -> AMARILLA | D2: =CONTROL!D4 -> BLANCO
A4: VENTANA HERRERO PAPU | G4: VENTANAS HERRERO VENTA
A6: medidas | B6: sin_vidrio | C6: guia | D6: mosquitero | E6: vidrio | G6: medidas | H6: vidrio_entero | I6: guia | J6: mosquitero | K6: vidrio rep
A7: 60x40 | B7: 23863 | C7: 6540 | D7: 8799 | E7: 2321 | G7: 60x40 | H7: {=IFERROR( ROUND( IF($A$2="COSTO", ((B7*(1+IFERROR(VLOOKUP($D$2,COLORES[],2,FALSE),0)))+E7) *(1-_xlfn.XLOOKUP(1,(DESC_PROV[LINEA]=$B$2)*(DESC_PROV[LISTA]=$C$2),DESC_PROV[DESCUENTO])), ((B7*(1+IFERROR(VLOOKUP($D$2,COLORES[],2,FALSE),0)))+E7) *(1-_xlfn.XLOOKUP(1,(DESC_PROV[LINEA]=$B$2)*(DESC_PROV[LISTA]=$C$2),DESC_PROV[DESCUENTO])) *(1+VLOOKUP($C$2,LISTAS[],2,FALSE)) *(1+0.1) ) /5,0)*5,0)} -> 27475 | I7: {=IFERROR( ROUND( IF($A$2="COSTO", ((B7*(1+IFERROR(VLOOKUP($D$2,COLORES[],2,FALSE),0)))+C7) *(1-_xlfn.XLOOKUP(1,(DESC_PROV[LINEA]=$B$2)*(DESC_PROV[LISTA]=$C$2),DESC_PROV[DESCUENTO])), ((B7*(1+IFERROR(VLOOKUP($D$2,COLORES[],2,FALSE),0)))+C7) *(1-_xlfn.XLOOKUP(1,(DESC_PROV[LINEA]=$B$2)*(DESC_PROV[LISTA]=$C$2),DESC_PROV[DESCUENTO])) *(1+VLOOKUP($C$2,LISTAS[],2,FALSE)) *(1+0.1) ) /5,0)*5,0)} -> 31905 | J7: {=IFERROR( ROUND( IF($A$2="COSTO", (D7*(1+IFERROR(VLOOKUP($D$2,COLORES[],2,FALSE),0))) *(1-_xlfn.XLOOKUP(1,(DESC_PROV[LINEA]=$B$2)*(DESC_PROV[LISTA]=$C$2),DESC_PROV[DESCUENTO])), (D7*(1+IFERROR(VLOOKUP($D$2,COLORES[],2,FALSE),0))) *(1-_xlfn.XLOOKUP(1,(DESC_PROV[LINEA]=$B$2)*(DESC_PROV[LISTA]=$C$2),DESC_PROV[DESCUENTO])) *(1+VLOOKUP($C$2,LISTAS[],2,FALSE)) *(1+0.1) ) /5,0)*5,0)} -> 9235 | K7: {=IFERROR( ROUND( IF($A$2="COSTO", ((B7*(1+IFERROR(VLOOKUP($D$2,COLORES[],2,FALSE),0)))+C7+E7) *(1-_xlfn.XLOOKUP(1,(DESC_PROV[LINEA]=$B$2)*(DESC_PROV[LISTA]=$C$2),DESC_PROV[DESCUENTO])), ((B7*(1+IFERROR(VLOOKUP($D$2,COLORES[],2,FALSE),0)))+C7+E7) *(1-_xlfn.XLOOKUP(1,(DESC_PROV[LINEA]=$B$2)*(DESC_PROV[LISTA]=$C$2),DESC_PROV[DESCUENTO])) *(1+VLOOKUP($C$2,LISTAS[],2,FALSE)) *(1+0.1) ) /5,0)*5,0)} -> 34340
A8: 80x40 | B8: 29288 | C8: 6540 | D8: 9874 | E8: 3249 | G8: 80x40 | H8: {=IFERROR( ROUND( IF($A$2="COSTO", ((B8*(1+IFERROR(VLOOKUP($D$2,COLORES[],2,FALSE),0)))+E8) *(1-_xlfn.XLOOKUP(1,(DESC_PROV[LINEA]=$B$2)*(DESC_PROV[LISTA]=$C$2),DESC_PROV[DESCUENTO])), ((B8*(1+IFERROR(VLOOKUP($D$2,COLORES[],2,FALSE),0)))+E8) *(1-_xlfn.XLOOKUP(1,(DESC_PROV[LINEA]=$B$2)*(DESC_PROV[LISTA]=$C$2),DESC_PROV[DESCUENTO])) *(1+VLOOKUP($C$2,LISTAS[],2,FALSE)) *(1+VLOOKUP($C$2,LISTAS[],3,FALSE)) ) /5,0)*5,0)} -> 40350 | I8: {=IFERROR( ROUND( IF($A$2="COSTO", ((B8*(1+IFERROR(VLOOKUP($D$2,COLORES[],2,FALSE),0))) + C8 + E8) *(1-_xlfn.XLOOKUP(1,(DESC_PROV[LINEA]=$B$2)*(DESC_PROV[LISTA]=$C$2),DESC_PROV[DESCUENTO])), ((B8*(1+IFERROR(VLOOKUP($D$2,COLORES[],2,FALSE),0))) + C8 + E8) *(1-_xlfn.XLOOKUP(1,(DESC_PROV[LINEA]=$B$2)*(DESC_PROV[LISTA]=$C$2),DESC_PROV[DESCUENTO])) *(1+VLOOKUP($C$2,LISTAS[],2,FALSE)) *(1+VLOOKUP($C$2,LISTAS[],3,FALSE)) ) /5,0)*5,0)} -> 48465 | J8: {=IFERROR( ROUND( IF($A$2="COSTO", (D8*(1+IFERROR(VLOOKUP($D$2,COLORES[],2,FALSE),0))) *(1-_xlfn.XLOOKUP(1,(DESC_PROV[LINEA]=$B$2)*(DESC_PROV[LISTA]=$C$2),DESC_PROV[DESCUENTO])), (D8*(1+IFERROR(VLOOKUP($D$2,COLORES[],2,FALSE),0))) *(1-_xlfn.XLOOKUP(1,(DESC_PROV[LINEA]=$B$2)*(DESC_PROV[LISTA]=$C$2),DESC_PROV[DESCUENTO])) *(1+VLOOKUP($C$2,LISTAS[],2,FALSE)) *(1+VLOOKUP($C$2,LISTAS[],4,FALSE)) ) /5,0)*5,0)} -> 15070 | K8: {=IFERROR( ROUND( IF($A$2="COSTO", (B8*(1+IFERROR(VLOOKUP($D$2,COLORES[],2,FALSE),0))+E8) *(1+VLOOKUP($C$2,LISTAS[],5,FALSE)) *(1-_xlfn.XLOOKUP(1,(DESC_PROV[LINEA]=$B$2)*(DESC_PROV[LISTA]=$C$2),DESC_PROV[DESCUENTO])), (B8*(1+IFERROR(VLOOKUP($D$2,COLORES[],2,FALSE),0))+E8) *(1-_xlfn.XLOOKUP(1,(DESC_PROV[LINEA]=$B$2)*(DESC_PROV[LISTA]=$C$2),DESC_PROV[DESCUENTO])) *(1+VLOOKUP($C$2,LISTAS[],5,FALSE)) *(1+VLOOKUP($C$2,LISTAS[],2,FALSE)) *(1+VLOOKUP($C$2,LISTAS[],3,FALSE)) ) /5,0)*5,0)} -> 52460
A9: 100x40 | B9: 31536 | C9: 6540 | D9: 11321 | E9: 4177 | G9: 100x40 | H9: {=IFERROR( ROUND( IF($A$2="COSTO", ((B9*(1+IFERROR(VLOOKUP($D$2,COLORES[],2,FALSE),0)))+E9) *(1-_xlfn.XLOOKUP(1,(DESC_PROV[LINEA]=$B$2)*(DESC_PROV[LISTA]=$C$2),DESC_PROV[DESCUENTO])), ((B9*(1+IFERROR(VLOOKUP($D$2,COLORES[],2,FALSE),0)))+E9) *(1-_xlfn.XLOOKUP(1,(DESC_PROV[LINEA]=$B$2)*(DESC_PROV[LISTA]=$C$2),DESC_PROV[DESCUENTO])) *(1+VLOOKUP($C$2,LISTAS[],2,FALSE)) *(1+VLOOKUP($C$2,LISTAS[],3,FALSE)) ) /5,0)*5,0)} -> 44290 | I9: {=IFERROR( ROUND( IF($A$2="COSTO", ((B9*(1+IFERROR(VLOOKUP($D$2,COLORES[],2,FALSE),0))) + C9 + E9) *(1-_xlfn.XLOOKUP(1,(DESC_PROV[LINEA]=$B$2)*(DESC_PROV[LISTA]=$C$2),DESC_PROV[DESCUENTO])), ((B9*(1+IFERROR(VLOOKUP($D$2,COLORES[],2,FALSE),0))) + C9 + E9) *(1-_xlfn.XLOOKUP(1,(DESC_PROV[LINEA]=$B$2)*(DESC_PROV[LISTA]=$C$2),DESC_PROV[DESCUENTO])) *(1+VLOOKUP($C$2,LISTAS[],2,FALSE)) *(1+VLOOKUP($C$2,LISTAS[],3,FALSE)) ) /5,0)*5,0)} -> 52400 | J9: {=IFERROR( ROUND( IF($A$2="COSTO", (D9*(1+IFERROR(VLOOKUP($D$2,COLORES[],2,FALSE),0))) *(1-_xlfn.XLOOKUP(1,(DESC_PROV[LINEA]=$B$2)*(DESC_PROV[LISTA]=$C$2),DESC_PROV[DESCUENTO])), (D9*(1+IFERROR(VLOOKUP($D$2,COLORES[],2,FALSE),0))) *(1-_xlfn.XLOOKUP(1,(DESC_PROV[LINEA]=$B$2)*(DESC_PROV[LISTA]=$C$2),DESC_PROV[DESCUENTO])) *(1+VLOOKUP($C$2,LISTAS[],2,FALSE)) *(1+VLOOKUP($C$2,LISTAS[],4,FALSE)) ) /5,0)*5,0)} -> 17280 | K9: {=IFERROR( ROUND( IF($A$2="COSTO", (B9*(1+IFERROR(VLOOKUP($D$2,COLORES[],2,FALSE),0))+E9) *(1+VLOOKUP($C$2,LISTAS[],5,FALSE)) *(1-_xlfn.XLOOKUP(1,(DESC_PROV[LINEA]=$B$2)*(DESC_PROV[LISTA]=$C$2),DESC_PROV[DESCUENTO])), (B9*(1+IFERROR(VLOOKUP($D$2,COLORES[],2,FALSE),0))+E9) *(1-_xlfn.XLOOKUP(1,(DESC_PROV[LINEA]=$B$2)*(DESC_PROV[LISTA]=$C$2),DESC_PROV[DESCUENTO])) *(1+VLOOKUP($C$2,LISTAS[],5,FALSE)) *(1+VLOOKUP($C$2,LISTAS[],2,FALSE)) *(1+VLOOKUP($C$2,LISTAS[],3,FALSE)) ) /5,0)*5,0)} -> 57580
A10: 120x40 | B10: 34843 | C10: 6540 | D10: 12768 | E10: 5116 | G10: 120x40 | H10: {=IFERROR( ROUND( IF($A$2="COSTO", ((B10*(1+IFERROR(VLOOKUP($D$2,COLORES[],2,FALSE),0)))+E10) *(1-_xlfn.XLOOKUP(1,(DESC_PROV[LINEA]=$B$2)*(DESC_PROV[LISTA]=$C$2),DESC_PROV[DESCUENTO])), ((B10*(1+IFERROR(VLOOKUP($D$2,COLORES[],2,FALSE),0)))+E10) *(1-_xlfn.XLOOKUP(1,(DESC_PROV[LINEA]=$B$2)*(DESC_PROV[LISTA]=$C$2),DESC_PROV[DESCUENTO])) *(1+VLOOKUP($C$2,LISTAS[],2,FALSE)) *(1+VLOOKUP($C$2,LISTAS[],3,FALSE)) ) /5,0)*5,0)} -> 49555 | I10: {=IFERROR( ROUND( IF($A$2="COSTO", ((B10*(1+IFERROR(VLOOKUP($D$2,COLORES[],2,FALSE),0))) + C10 + E10) *(1-_xlfn.XLOOKUP(1,(DESC_PROV[LINEA]=$B$2)*(DESC_PROV[LISTA]=$C$2),DESC_PROV[DESCUENTO])), ((B10*(1+IFERROR(VLOOKUP($D$2,COLORES[],2,FALSE),0))) + C10 + E10) *(1-_xlfn.XLOOKUP(1,(DESC_PROV[LINEA]=$B$2)*(DESC_PROV[LISTA]=$C$2),DESC_PROV[DESCUENTO])) *(1+VLOOKUP($C$2,LISTAS[],2,FALSE)) *(1+VLOOKUP($C$2,LISTAS[],3,FALSE)) ) /5,0)*5,0)} -> 57670 | J10: {=IFERROR( ROUND( IF($A$2="COSTO", (D10*(1+IFERROR(VLOOKUP($D$2,COLORES[],2,FALSE),0))) *(1-_xlfn.XLOOKUP(1,(DESC_PROV[LINEA]=$B$2)*(DESC_PROV[LISTA]=$C$2),DESC_PROV[DESCUENTO])), (D10*(1+IFERROR(VLOOKUP($D$2,COLORES[],2,FALSE),0))) *(1-_xlfn.XLOOKUP(1,(DESC_PROV[LINEA]=$B$2)*(DESC_PROV[LISTA]=$C$2),DESC_PROV[DESCUENTO])) *(1+VLOOKUP($C$2,LISTAS[],2,FALSE)) *(1+VLOOKUP($C$2,LISTAS[],4,FALSE)) ) /5,0)*5,0)} -> 19490 | K10: {=IFERROR( ROUND( IF($A$2="COSTO", (B10*(1+IFERROR(VLOOKUP($D$2,COLORES[],2,FALSE),0))+E10) *(1+VLOOKUP($C$2,LISTAS[],5,FALSE)) *(1-_xlfn.XLOOKUP(1,(DESC_PROV[LINEA]=$B$2)*(DESC_PROV[LISTA]=$C$2),DESC_PROV[DESCUENTO])), (B10*(1+IFERROR(VLOOKUP($D$2,COLORES[],2,FALSE),0))+E10) *(1-_xlfn.XLOOKUP(1,(DESC_PROV[LINEA]=$B$2)*(DESC_PROV[LISTA]=$C$2),DESC_PROV[DESCUENTO])) *(1+VLOOKUP($C$2,LISTAS[],5,FALSE)) *(1+VLOOKUP($C$2,LISTAS[],2,FALSE)) *(1+VLOOKUP($C$2,LISTAS[],3,FALSE)) ) /5,0)*5,0)} -> 64425
A11: 150x40 | B11: 40334 | C11: 6540 | D11: 14939 | E11: 6497 | G11: 150x40 | H11: {=IFERROR( ROUND( IF($A$2="COSTO", ((B11*(1+IFERROR(VLOOKUP($D$2,COLORES[],2,FALSE),0)))+E11) *(1-_xlfn.XLOOKUP(1,(DESC_PROV[LINEA]=$B$2)*(DESC_PROV[LISTA]=$C$2),DESC_PROV[DESCUENTO])), ((B11*(1+IFERROR(VLOOKUP($D$2,COLORES[],2,FALSE),0)))+E11) *(1-_xlfn.XLOOKUP(1,(DESC_PROV[LINEA]=$B$2)*(DESC_PROV[LISTA]=$C$2),DESC_PROV[DESCUENTO])) *(1+VLOOKUP($C$2,LISTAS[],2,FALSE)) *(1+VLOOKUP($C$2,LISTAS[],3,FALSE)) ) /5,0)*5,0)} -> 58080 | I11: {=IFERROR( ROUND( IF($A$2="COSTO", ((B11*(1+IFERROR(VLOOKUP($D$2,COLORES[],2,FALSE),0))) + C11 + E11) *(1-_xlfn.XLOOKUP(1,(DESC_PROV[LINEA]=$B$2)*(DESC_PROV[LISTA]=$C$2),DESC_PROV[DESCUENTO])), ((B11*(1+IFERROR(VLOOKUP($D$2,COLORES[],2,FALSE),0))) + C11 + E11) *(1-_xlfn.XLOOKUP(1,(DESC_PROV[LINEA]=$B$2)*(DESC_PROV[LISTA]=$C$2),DESC_PROV[DESCUENTO])) *(1+VLOOKUP($C$2,LISTAS[],2,FALSE)) *(1+VLOOKUP($C$2,LISTAS[],3,FALSE)) ) /5,0)*5,0)} -> 66190 | J11: {=IFERROR( ROUND( IF($A$2="COSTO", (D11*(1+IFERROR(VLOOKUP($D$2,COLORES[],2,FALSE),0))) *(1-_xlfn.XLOOKUP(1,(DESC_PROV[LINEA]=$B$2)*(DESC_PROV[LISTA]=$C$2),DESC_PROV[DESCUENTO])), (D11*(1+IFERROR(VLOOKUP($D$2,COLORES[],2,FALSE),0))) *(1-_xlfn.XLOOKUP(1,(DESC_PROV[LINEA]=$B$2)*(DESC_PROV[LISTA]=$C$2),DESC_PROV[DESCUENTO])) *(1+VLOOKUP($C$2,LISTAS[],2,FALSE)) *(1+VLOOKUP($C$2,LISTAS[],4,FALSE)) ) /5,0)*5,0)} -> 22805 | K11: {=IFERROR( ROUND( IF($A$2="COSTO", (B11*(1+IFERROR(VLOOKUP($D$2,COLORES[],2,FALSE),0))+E11) *(1+VLOOKUP($C$2,LISTAS[],5,FALSE)) *(1-_xlfn.XLOOKUP(1,(DESC_PROV[LINEA]=$B$2)*(DESC_PROV[LISTA]=$C$2),DESC_PROV[DESCUENTO])), (B11*(1+IFERROR(VLOOKUP($D$2,COLORES[],2,FALSE),0))+E11) *(1-_xlfn.XLOOKUP(1,(DESC_PROV[LINEA]=$B$2)*(DESC_PROV[LISTA]=$C$2),DESC_PROV[DESCUENTO])) *(1+VLOOKUP($C$2,LISTAS[],5,FALSE)) *(1+VLOOKUP($C$2,LISTAS[],2,FALSE)) *(1+VLOOKUP($C$2,LISTAS[],3,FALSE)) ) /5,0)*5,0)} -> 75505
A12: 180x40 | B12: 44765 | C12: 6540 | D12: 17109 | E12: 7895 | G12: 180x40 | H12: {=IFERROR( ROUND( IF($A$2="COSTO", ((B12*(1+IFERROR(VLOOKUP($D$2,COLORES[],2,FALSE),0)))+E12) *(1-_xlfn.XLOOKUP(1,(DESC_PROV[LINEA]=$B$2)*(DESC_PROV[LISTA]=$C$2),DESC_PROV[DESCUENTO])), ((B12*(1+IFERROR(VLOOKUP($D$2,COLORES[],2,FALSE),0)))+E12) *(1-_xlfn.XLOOKUP(1,(DESC_PROV[LINEA]=$B$2)*(DESC_PROV[LISTA]=$C$2),DESC_PROV[DESCUENTO])) *(1+VLOOKUP($C$2,LISTAS[],2,FALSE)) *(1+VLOOKUP($C$2,LISTAS[],3,FALSE)) ) /5,0)*5,0)} -> 65310 | I12: {=IFERROR( ROUND( IF($A$2="COSTO", ((B12*(1+IFERROR(VLOOKUP($D$2,COLORES[],2,FALSE),0))) + C12 + E12) *(1-_xlfn.XLOOKUP(1,(DESC_PROV[LINEA]=$B$2)*(DESC_PROV[LISTA]=$C$2),DESC_PROV[DESCUENTO])), ((B12*(1+IFERROR(VLOOKUP($D$2,COLORES[],2,FALSE),0))) + C12 + E12) *(1-_xlfn.XLOOKUP(1,(DESC_PROV[LINEA]=$B$2)*(DESC_PROV[LISTA]=$C$2),DESC_PROV[DESCUENTO])) *(1+VLOOKUP($C$2,LISTAS[],2,FALSE)) *(1+VLOOKUP($C$2,LISTAS[],3,FALSE)) ) /5,0)*5,0)} -> 73420 | J12: {=IFERROR( ROUND( IF($A$2="COSTO", (D12*(1+IFERROR(VLOOKUP($D$2,COLORES[],2,FALSE),0))) *(1-_xlfn.XLOOKUP(1,(DESC_PROV[LINEA]=$B$2)*(DESC_PROV[LISTA]=$C$2),DESC_PROV[DESCUENTO])), (D12*(1+IFERROR(VLOOKUP($D$2,COLORES[],2,FALSE),0))) *(1-_xlfn.XLOOKUP(1,(DESC_PROV[LINEA]=$B$2)*(DESC_PROV[LISTA]=$C$2),DESC_PROV[DESCUENTO])) *(1+VLOOKUP($C$2,LISTAS[],2,FALSE)) *(1+VLOOKUP($C$2,LISTAS[],4,FALSE)) ) /5,0)*5,0)} -> 26115 | K12: {=IFERROR( ROUND( IF($A$2="COSTO", (B12*(1+IFERROR(VLOOKUP($D$2,COLORES[],2,FALSE),0))+E12) *(1+VLOOKUP($C$2,LISTAS[],5,FALSE)) *(1-_xlfn.XLOOKUP(1,(DESC_PROV[LINEA]=$B$2)*(DESC_PROV[LISTA]=$C$2),DESC_PROV[DESCUENTO])), (B12*(1+IFERROR(VLOOKUP($D$2,COLORES[],2,FALSE),0))+E12) *(1-_xlfn.XLOOKUP(1,(DESC_PROV[LINEA]=$B$2)*(DESC_PROV[LISTA]=$C$2),DESC_PROV[DESCUENTO])) *(1+VLOOKUP($C$2,LISTAS[],5,FALSE)) *(1+VLOOKUP($C$2,LISTAS[],2,FALSE)) *(1+VLOOKUP($C$2,LISTAS[],3,FALSE)) ) /5,0)*5,0)} -> 84900
A13: 200x40 | B13: 49660 | C13: 6540 | D13: 18556 | E13: 8823 | G13: 200x40 | H13: {=IFERROR( ROUND( IF($A$2="COSTO", ((B13*(1+IFERROR(VLOOKUP($D$2,COLORES[],2,FALSE),0)))+E13) *(1-_xlfn.XLOOKUP(1,(DESC_PROV[LINEA]=$B$2)*(DESC_PROV[LISTA]=$C$2),DESC_PROV[DESCUENTO])), ((B13*(1+IFERROR(VLOOKUP($D$2,COLORES[],2,FALSE),0)))+E13) *(1-_xlfn.XLOOKUP(1,(DESC_PROV[LINEA]=$B$2)*(DESC_PROV[LISTA]=$C$2),DESC_PROV[DESCUENTO])) *(1+VLOOKUP($C$2,LISTAS[],2,FALSE)) *(1+VLOOKUP($C$2,LISTAS[],3,FALSE)) ) /5,0)*5,0)} -> 72530 | I13: {=IFERROR( ROUND( IF($A$2="COSTO", ((B13*(1+IFERROR(VLOOKUP($D$2,COLORES[],2,FALSE),0))) + C13 + E13) *(1-_xlfn.XLOOKUP(1,(DESC_PROV[LINEA]=$B$2)*(DESC_PROV[LISTA]=$C$2),DESC_PROV[DESCUENTO])), ((B13*(1+IFERROR(VLOOKUP($D$2,COLORES[],2,FALSE),0))) + C13 + E13) *(1-_xlfn.XLOOKUP(1,(DESC_PROV[LINEA]=$B$2)*(DESC_PROV[LISTA]=$C$2),DESC_PROV[DESCUENTO])) *(1+VLOOKUP($C$2,LISTAS[],2,FALSE)) *(1+VLOOKUP($C$2,LISTAS[],3,FALSE)) ) /5,0)*5,0)} -> 80640 | J13: {=IFERROR( ROUND( IF($A$2="COSTO", (D13*(1+IFERROR(VLOOKUP($D$2,COLORES[],2,FALSE),0))) *(1-_xlfn.XLOOKUP(1,(DESC_PROV[LINEA]=$B$2)*(DESC_PROV[LISTA]=$C$2),DESC_PROV[DESCUENTO])), (D13*(1+IFERROR(VLOOKUP($D$2,COLORES[],2,FALSE),0))) *(1-_xlfn.XLOOKUP(1,(DESC_PROV[LINEA]=$B$2)*(DESC_PROV[LISTA]=$C$2),DESC_PROV[DESCUENTO])) *(1+VLOOKUP($C$2,LISTAS[],2,FALSE)) *(1+VLOOKUP($C$2,LISTAS[],4,FALSE)) ) /5,0)*5,0)} -> 28325 | K13: {=IFERROR( ROUND( IF($A$2="COSTO", (B13*(1+IFERROR(VLOOKUP($D$2,COLORES[],2,FALSE),0))+E13) *(1+VLOOKUP($C$2,LISTAS[],5,FALSE)) *(1-_xlfn.XLOOKUP(1,(DESC_PROV[LINEA]=$B$2)*(DESC_PROV[LISTA]=$C$2),DESC_PROV[DESCUENTO])), (B13*(1+IFERROR(VLOOKUP($D$2,COLORES[],2,FALSE),0))+E13) *(1-_xlfn.XLOOKUP(1,(DESC_PROV[LINEA]=$B$2)*(DESC_PROV[LISTA]=$C$2),DESC_PROV[DESCUENTO])) *(1+VLOOKUP($C$2,LISTAS[],5,FALSE)) *(1+VLOOKUP($C$2,LISTAS[],2,FALSE)) *(1+VLOOKUP($C$2,LISTAS[],3,FALSE)) ) /5,0)*5,0)} -> 94290
A14: 60x60 | B14: 28445 | C14: 9809 | D14: 11108 | E14: 3871 | G14: 60x60 | H14: {=IFERROR( ROUND( IF($A$2="COSTO", ((B14*(1+IFERROR(VLOOKUP($D$2,COLORES[],2,FALSE),0)))+E14) *(1-_xlfn.XLOOKUP(1,(DESC_PROV[LINEA]=$B$2)*(DESC_PROV[LISTA]=$C$2),DESC_PROV[DESCUENTO])), ((B14*(1+IFERROR(VLOOKUP($D$2,COLORES[],2,FALSE),0)))+E14) *(1-_xlfn.XLOOKUP(1,(DESC_PROV[LINEA]=$B$2)*(DESC_PROV[LISTA]=$C$2),DESC_PROV[DESCUENTO])) *(1+VLOOKUP($C$2,LISTAS[],2,FALSE)) *(1+VLOOKUP($C$2,LISTAS[],3,FALSE)) ) /5,0)*5,0)} -> 40080 | I14: {=IFERROR( ROUND( IF($A$2="COSTO", ((B14*(1+IFERROR(VLOOKUP($D$2,COLORES[],2,FALSE),0))) + C14 + E14) *(1-_xlfn.XLOOKUP(1,(DESC_PROV[LINEA]=$B$2)*(DESC_PROV[LISTA]=$C$2),DESC_PROV[DESCUENTO])), ((B14*(1+IFERROR(VLOOKUP($D$2,COLORES[],2,FALSE),0))) + C14 + E14) *(1-_xlfn.XLOOKUP(1,(DESC_PROV[LINEA]=$B$2)*(DESC_PROV[LISTA]=$C$2),DESC_PROV[DESCUENTO])) *(1+VLOOKUP($C$2,LISTAS[],2,FALSE)) *(1+VLOOKUP($C$2,LISTAS[],3,FALSE)) ) /5,0)*5,0)} -> 52245 | J14: {=IFERROR( ROUND( IF($A$2="COSTO", (D14*(1+IFERROR(VLOOKUP($D$2,COLORES[],2,FALSE),0))) *(1-_xlfn.XLOOKUP(1,(DESC_PROV[LINEA]=$B$2)*(DESC_PROV[LISTA]=$C$2),DESC_PROV[DESCUENTO])), (D14*(1+IFERROR(VLOOKUP($D$2,COLORES[],2,FALSE),0))) *(1-_xlfn.XLOOKUP(1,(DESC_PROV[LINEA]=$B$2)*(DESC_PROV[LISTA]=$C$2),DESC_PROV[DESCUENTO])) *(1+VLOOKUP($C$2,LISTAS[],2,FALSE)) *(1+VLOOKUP($C$2,LISTAS[],4,FALSE)) ) /5,0)*5,0)} -> 16955 | K14: {=IFERROR( ROUND( IF($A$2="COSTO", (B14*(1+IFERROR(VLOOKUP($D$2,COLORES[],2,FALSE),0))+E14) *(1+VLOOKUP($C$2,LISTAS[],5,FALSE)) *(1-_xlfn.XLOOKUP(1,(DESC_PROV[LINEA]=$B$2)*(DESC_PROV[LISTA]=$C$2),DESC_PROV[DESCUENTO])), (B14*(1+IFERROR(VLOOKUP($D$2,COLORES[],2,FALSE),0))+E14) *(1-_xlfn.XLOOKUP(1,(DESC_PROV[LINEA]=$B$2)*(DESC_PROV[LISTA]=$C$2),DESC_PROV[DESCUENTO])) *(1+VLOOKUP($C$2,LISTAS[],5,FALSE)) *(1+VLOOKUP($C$2,LISTAS[],2,FALSE)) *(1+VLOOKUP($C$2,LISTAS[],3,FALSE)) ) /5,0)*5,0)} -> 52100
A15: 80x60 | B15: 34399 | C15: 9809 | D15: 12768 | E15: 5416 | G15: 80x60 | H15: {=IFERROR( ROUND( IF($A$2="COSTO", ((B15*(1+IFERROR(VLOOKUP($D$2,COLORES[],2,FALSE),0)))+E15) *(1-_xlfn.XLOOKUP(1,(DESC_PROV[LINEA]=$B$2)*(DESC_PROV[LISTA]=$C$2),DESC_PROV[DESCUENTO])), ((B15*(1+IFERROR(VLOOKUP($D$2,COLORES[],2,FALSE),0)))+E15) *(1-_xlfn.XLOOKUP(1,(DESC_PROV[LINEA]=$B$2)*(DESC_PROV[LISTA]=$C$2),DESC_PROV[DESCUENTO])) *(1+VLOOKUP($C$2,LISTAS[],2,FALSE)) *(1+VLOOKUP($C$2,LISTAS[],3,FALSE)) ) /5,0)*5,0)} -> 49380 | I15: {=IFERROR( ROUND( IF($A$2="COSTO", ((B15*(1+IFERROR(VLOOKUP($D$2,COLORES[],2,FALSE),0))) + C15 + E15) *(1-_xlfn.XLOOKUP(1,(DESC_PROV[LINEA]=$B$2)*(DESC_PROV[LISTA]=$C$2),DESC_PROV[DESCUENTO])), ((B15*(1+IFERROR(VLOOKUP($D$2,COLORES[],2,FALSE),0))) + C15 + E15) *(1-_xlfn.XLOOKUP(1,(DESC_PROV[LINEA]=$B$2)*(DESC_PROV[LISTA]=$C$2),DESC_PROV[DESCUENTO])) *(1+VLOOKUP($C$2,LISTAS[],2,FALSE)) *(1+VLOOKUP($C$2,LISTAS[],3,FALSE)) ) /5,0)*5,0)} -> 61545 | J15: {=IFERROR( ROUND( IF($A$2="COSTO", (D15*(1+IFERROR(VLOOKUP($D$2,COLORES[],2,FALSE),0))) *(1-_xlfn.XLOOKUP(1,(DESC_PROV[LINEA]=$B$2)*(DESC_PROV[LISTA]=$C$2),DESC_PROV[DESCUENTO])), (D15*(1+IFERROR(VLOOKUP($D$2,COLORES[],2,FALSE),0))) *(1-_xlfn.XLOOKUP(1,(DESC_PROV[LINEA]=$B$2)*(DESC_PROV[LISTA]=$C$2),DESC_PROV[DESCUENTO])) *(1+VLOOKUP($C$2,LISTAS[],2,FALSE)) *(1+VLOOKUP($C$2,LISTAS[],4,FALSE)) ) /5,0)*5,0)} -> 19490 | K15: {=IFERROR( ROUND( IF($A$2="COSTO", (B15*(1+IFERROR(VLOOKUP($D$2,COLORES[],2,FALSE),0))+E15) *(1+VLOOKUP($C$2,LISTAS[],5,FALSE)) *(1-_xlfn.XLOOKUP(1,(DESC_PROV[LINEA]=$B$2)*(DESC_PROV[LISTA]=$C$2),DESC_PROV[DESCUENTO])), (B15*(1+IFERROR(VLOOKUP($D$2,COLORES[],2,FALSE),0))+E15) *(1-_xlfn.XLOOKUP(1,(DESC_PROV[LINEA]=$B$2)*(DESC_PROV[LISTA]=$C$2),DESC_PROV[DESCUENTO])) *(1+VLOOKUP($C$2,LISTAS[],5,FALSE)) *(1+VLOOKUP($C$2,LISTAS[],2,FALSE)) *(1+VLOOKUP($C$2,LISTAS[],3,FALSE)) ) /5,0)*5,0)} -> 64190
A16: 100x60 | B16: 37307 | C16: 9809 | D16: 14428 | E16: 6967 | G16: 100x60 | H16: {=IFERROR( ROUND( IF($A$2="COSTO", ((B16*(1+IFERROR(VLOOKUP($D$2,COLORES[],2,FALSE),0)))+E16) *(1-_xlfn.XLOOKUP(1,(DESC_PROV[LINEA]=$B$2)*(DESC_PROV[LISTA]=$C$2),DESC_PROV[DESCUENTO])), ((B16*(1+IFERROR(VLOOKUP($D$2,COLORES[],2,FALSE),0)))+E16) *(1-_xlfn.XLOOKUP(1,(DESC_PROV[LINEA]=$B$2)*(DESC_PROV[LISTA]=$C$2),DESC_PROV[DESCUENTO])) *(1+VLOOKUP($C$2,LISTAS[],2,FALSE)) *(1+VLOOKUP($C$2,LISTAS[],3,FALSE)) ) /5,0)*5,0)} -> 54910 | I16: {=IFERROR( ROUND( IF($A$2="COSTO", ((B16*(1+IFERROR(VLOOKUP($D$2,COLORES[],2,FALSE),0))) + C16 + E16) *(1-_xlfn.XLOOKUP(1,(DESC_PROV[LINEA]=$B$2)*(DESC_PROV[LISTA]=$C$2),DESC_PROV[DESCUENTO])), ((B16*(1+IFERROR(VLOOKUP($D$2,COLORES[],2,FALSE),0))) + C16 + E16) *(1-_xlfn.XLOOKUP(1,(DESC_PROV[LINEA]=$B$2)*(DESC_PROV[LISTA]=$C$2),DESC_PROV[DESCUENTO])) *(1+VLOOKUP($C$2,LISTAS[],2,FALSE)) *(1+VLOOKUP($C$2,LISTAS[],3,FALSE)) ) /5,0)*5,0)} -> 67075 | J16: {=IFERROR( ROUND( IF($A$2="COSTO", (D16*(1+IFERROR(VLOOKUP($D$2,COLORES[],2,FALSE),0))) *(1-_xlfn.XLOOKUP(1,(DESC_PROV[LINEA]=$B$2)*(DESC_PROV[LISTA]=$C$2),DESC_PROV[DESCUENTO])), (D16*(1+IFERROR(VLOOKUP($D$2,COLORES[],2,FALSE),0))) *(1-_xlfn.XLOOKUP(1,(DESC_PROV[LINEA]=$B$2)*(DESC_PROV[LISTA]=$C$2),DESC_PROV[DESCUENTO])) *(1+VLOOKUP($C$2,LISTAS[],2,FALSE)) *(1+VLOOKUP($C$2,LISTAS[],4,FALSE)) ) /5,0)*5,0)} -> 22025 | K16: {=IFERROR( ROUND( IF($A$2="COSTO", (B16*(1+IFERROR(VLOOKUP($D$2,COLORES[],2,FALSE),0))+E16) *(1+VLOOKUP($C$2,LISTAS[],5,FALSE)) *(1-_xlfn.XLOOKUP(1,(DESC_PROV[LINEA]=$B$2)*(DESC_PROV[LISTA]=$C$2),DESC_PROV[DESCUENTO])), (B16*(1+IFERROR(VLOOKUP($D$2,COLORES[],2,FALSE),0))+E16) *(1-_xlfn.XLOOKUP(1,(DESC_PROV[LINEA]=$B$2)*(DESC_PROV[LISTA]=$C$2),DESC_PROV[DESCUENTO])) *(1+VLOOKUP($C$2,LISTAS[],5,FALSE)) *(1+VLOOKUP($C$2,LISTAS[],2,FALSE)) *(1+VLOOKUP($C$2,LISTAS[],3,FALSE)) ) /5,0)*5,0)} -> 71380
A17: 120x60 | B17: 40485 | C17: 9809 | D17: 16088 | E17: 8512 | G17: 120x60 | H17: {=IFERROR( ROUND( IF($A$2="COSTO", ((B17*(1+IFERROR(VLOOKUP($D$2,COLORES[],2,FALSE),0)))+E17) *(1-_xlfn.XLOOKUP(1,(DESC_PROV[LINEA]=$B$2)*(DESC_PROV[LISTA]=$C$2),DESC_PROV[DESCUENTO])), ((B17*(1+IFERROR(VLOOKUP($D$2,COLORES[],2,FALSE),0)))+E17) *(1-_xlfn.XLOOKUP(1,(DESC_PROV[LINEA]=$B$2)*(DESC_PROV[LISTA]=$C$2),DESC_PROV[DESCUENTO])) *(1+VLOOKUP($C$2,LISTAS[],2,FALSE)) *(1+VLOOKUP($C$2,LISTAS[],3,FALSE)) ) /5,0)*5,0)} -> 60765 | I17: {=IFERROR( ROUND( IF($A$2="COSTO", ((B17*(1+IFERROR(VLOOKUP($D$2,COLORES[],2,FALSE),0))) + C17 + E17) *(1-_xlfn.XLOOKUP(1,(DESC_PROV[LINEA]=$B$2)*(DESC_PROV[LISTA]=$C$2),DESC_PROV[DESCUENTO])), ((B17*(1+IFERROR(VLOOKUP($D$2,COLORES[],2,FALSE),0))) + C17 + E17) *(1-_xlfn.XLOOKUP(1,(DESC_PROV[LINEA]=$B$2)*(DESC_PROV[LISTA]=$C$2),DESC_PROV[DESCUENTO])) *(1+VLOOKUP($C$2,LISTAS[],2,FALSE)) *(1+VLOOKUP($C$2,LISTAS[],3,FALSE)) ) /5,0)*5,0)} -> 72930 | J17: {=IFERROR( ROUND( IF($A$2="COSTO", (D17*(1+IFERROR(VLOOKUP($D$2,COLORES[],2,FALSE),0))) *(1-_xlfn.XLOOKUP(1,(DESC_PROV[LINEA]=$B$2)*(DESC_PROV[LISTA]=$C$2),DESC_PROV[DESCUENTO])), (D17*(1+IFERROR(VLOOKUP($D$2,COLORES[],2,FALSE),0))) *(1-_xlfn.XLOOKUP(1,(DESC_PROV[LINEA]=$B$2)*(DESC_PROV[LISTA]=$C$2),DESC_PROV[DESCUENTO])) *(1+VLOOKUP($C$2,LISTAS[],2,FALSE)) *(1+VLOOKUP($C$2,LISTAS[],4,FALSE)) ) /5,0)*5,0)} -> 24555 | K17: {=IFERROR( ROUND( IF($A$2="COSTO", (B17*(1+IFERROR(VLOOKUP($D$2,COLORES[],2,FALSE),0))+E17) *(1+VLOOKUP($C$2,LISTAS[],5,FALSE)) *(1-_xlfn.XLOOKUP(1,(DESC_PROV[LINEA]=$B$2)*(DESC_PROV[LISTA]=$C$2),DESC_PROV[DESCUENTO])), (B17*(1+IFERROR(VLOOKUP($D$2,COLORES[],2,FALSE),0))+E17) *(1-_xlfn.XLOOKUP(1,(DESC_PROV[LINEA]=$B$2)*(DESC_PROV[LISTA]=$C$2),DESC_PROV[DESCUENTO])) *(1+VLOOKUP($C$2,LISTAS[],5,FALSE)) *(1+VLOOKUP($C$2,LISTAS[],2,FALSE)) *(1+VLOOKUP($C$2,LISTAS[],3,FALSE)) ) /5,0)*5,0)} -> 78995
A18: 150x60 | B18: 45975 | C18: 9809 | D18: 18577 | E18: 10838 | G18: 150x60 | H18: {=IFERROR( ROUND( IF($A$2="COSTO", ((B18*(1+IFERROR(VLOOKUP($D$2,COLORES[],2,FALSE),0)))+E18) *(1-_xlfn.XLOOKUP(1,(DESC_PROV[LINEA]=$B$2)*(DESC_PROV[LISTA]=$C$2),DESC_PROV[DESCUENTO])), ((B18*(1+IFERROR(VLOOKUP($D$2,COLORES[],2,FALSE),0)))+E18) *(1-_xlfn.XLOOKUP(1,(DESC_PROV[LINEA]=$B$2)*(DESC_PROV[LISTA]=$C$2),DESC_PROV[DESCUENTO])) *(1+VLOOKUP($C$2,LISTAS[],2,FALSE)) *(1+VLOOKUP($C$2,LISTAS[],3,FALSE)) ) /5,0)*5,0)} -> 70460 | I18: {=IFERROR( ROUND( IF($A$2="COSTO", ((B18*(1+IFERROR(VLOOKUP($D$2,COLORES[],2,FALSE),0))) + C18 + E18) *(1-_xlfn.XLOOKUP(1,(DESC_PROV[LINEA]=$B$2)*(DESC_PROV[LISTA]=$C$2),DESC_PROV[DESCUENTO])), ((B18*(1+IFERROR(VLOOKUP($D$2,COLORES[],2,FALSE),0))) + C18 + E18) *(1-_xlfn.XLOOKUP(1,(DESC_PROV[LINEA]=$B$2)*(DESC_PROV[LISTA]=$C$2),DESC_PROV[DESCUENTO])) *(1+VLOOKUP($C$2,LISTAS[],2,FALSE)) *(1+VLOOKUP($C$2,LISTAS[],3,FALSE)) ) /5,0)*5,0)} -> 82625 | J18: {=IFERROR( ROUND( IF($A$2="COSTO", (D18*(1+IFERROR(VLOOKUP($D$2,COLORES[],2,FALSE),0))) *(1-_xlfn.XLOOKUP(1,(DESC_PROV[LINEA]=$B$2)*(DESC_PROV[LISTA]=$C$2),DESC_PROV[DESCUENTO])), (D18*(1+IFERROR(VLOOKUP($D$2,COLORES[],2,FALSE),0))) *(1-_xlfn.XLOOKUP(1,(DESC_PROV[LINEA]=$B$2)*(DESC_PROV[LISTA]=$C$2),DESC_PROV[DESCUENTO])) *(1+VLOOKUP($C$2,LISTAS[],2,FALSE)) *(1+VLOOKUP($C$2,LISTAS[],4,FALSE)) ) /5,0)*5,0)} -> 28355 | K18: {=IFERROR( ROUND( IF($A$2="COSTO", (B18*(1+IFERROR(VLOOKUP($D$2,COLORES[],2,FALSE),0))+E18) *(1+VLOOKUP($C$2,LISTAS[],5,FALSE)) *(1-_xlfn.XLOOKUP(1,(DESC_PROV[LINEA]=$B$2)*(DESC_PROV[LISTA]=$C$2),DESC_PROV[DESCUENTO])), (B18*(1+IFERROR(VLOOKUP($D$2,COLORES[],2,FALSE),0))+E18) *(1-_xlfn.XLOOKUP(1,(DESC_PROV[LINEA]=$B$2)*(DESC_PROV[LISTA]=$C$2),DESC_PROV[DESCUENTO])) *(1+VLOOKUP($C$2,LISTAS[],5,FALSE)) *(1+VLOOKUP($C$2,LISTAS[],2,FALSE)) *(1+VLOOKUP($C$2,LISTAS[],3,FALSE)) ) /5,0)*5,0)} -> 91595
A19: 180x60 | B19: 50407 | C19: 9809 | D19: 21067 | E19: 13159 | G19: 180x60 | H19: {=IFERROR( ROUND( IF($A$2="COSTO", ((B19*(1+IFERROR(VLOOKUP($D$2,COLORES[],2,FALSE),0)))+E19) *(1-_xlfn.XLOOKUP(1,(DESC_PROV[LINEA]=$B$2)*(DESC_PROV[LISTA]=$C$2),DESC_PROV[DESCUENTO])), ((B19*(1+IFERROR(VLOOKUP($D$2,COLORES[],2,FALSE),0)))+E19) *(1-_xlfn.XLOOKUP(1,(DESC_PROV[LINEA]=$B$2)*(DESC_PROV[LISTA]=$C$2),DESC_PROV[DESCUENTO])) *(1+VLOOKUP($C$2,LISTAS[],2,FALSE)) *(1+VLOOKUP($C$2,LISTAS[],3,FALSE)) ) /5,0)*5,0)} -> 78835 | I19: {=IFERROR( ROUND( IF($A$2="COSTO", ((B19*(1+IFERROR(VLOOKUP($D$2,COLORES[],2,FALSE),0))) + C19 + E19) *(1-_xlfn.XLOOKUP(1,(DESC_PROV[LINEA]=$B$2)*(DESC_PROV[LISTA]=$C$2),DESC_PROV[DESCUENTO])), ((B19*(1+IFERROR(VLOOKUP($D$2,COLORES[],2,FALSE),0))) + C19 + E19) *(1-_xlfn.XLOOKUP(1,(DESC_PROV[LINEA]=$B$2)*(DESC_PROV[LISTA]=$C$2),DESC_PROV[DESCUENTO])) *(1+VLOOKUP($C$2,LISTAS[],2,FALSE)) *(1+VLOOKUP($C$2,LISTAS[],3,FALSE)) ) /5,0)*5,0)} -> 91000 | J19: {=IFERROR( ROUND( IF($A$2="COSTO", (D19*(1+IFERROR(VLOOKUP($D$2,COLORES[],2,FALSE),0))) *(1-_xlfn.XLOOKUP(1,(DESC_PROV[LINEA]=$B$2)*(DESC_PROV[LISTA]=$C$2),DESC_PROV[DESCUENTO])), (D19*(1+IFERROR(VLOOKUP($D$2,COLORES[],2,FALSE),0))) *(1-_xlfn.XLOOKUP(1,(DESC_PROV[LINEA]=$B$2)*(DESC_PROV[LISTA]=$C$2),DESC_PROV[DESCUENTO])) *(1+VLOOKUP($C$2,LISTAS[],2,FALSE)) *(1+VLOOKUP($C$2,LISTAS[],4,FALSE)) ) /5,0)*5,0)} -> 32155 | K19: {=IFERROR( ROUND( IF($A$2="COSTO", (B19*(1+IFERROR(VLOOKUP($D$2,COLORES[],2,FALSE),0))+E19) *(1+VLOOKUP($C$2,LISTAS[],5,FALSE)) *(1-_xlfn.XLOOKUP(1,(DESC_PROV[LINEA]=$B$2)*(DESC_PROV[LISTA]=$C$2),DESC_PROV[DESCUENTO])), (B19*(1+IFERROR(VLOOKUP($D$2,COLORES[],2,FALSE),0))+E19) *(1-_xlfn.XLOOKUP(1,(DESC_PROV[LINEA]=$B$2)*(DESC_PROV[LISTA]=$C$2),DESC_PROV[DESCUENTO])) *(1+VLOOKUP($C$2,LISTAS[],5,FALSE)) *(1+VLOOKUP($C$2,LISTAS[],2,FALSE)) *(1+VLOOKUP($C$2,LISTAS[],3,FALSE)) ) /5,0)*5,0)} -> 102485
... A59: 240x200 | B59: 121758 | C59: 32697 | D59: 58222 | E59: 71204 | G59: 240x200 | H59: {=IFERROR( ROUND( IF($A$2="COSTO", ((B59*(1+IFERROR(VLOOKUP($D$2,COLORES[],2,FALSE),0)))+E59) *(1-_xlfn.XLOOKUP(1,(DESC_PROV[LINEA]=$B$2)*(DESC_PROV[LISTA]=$C$2),DESC_PROV[DESCUENTO])), ((B59*(1+IFERROR(VLOOKUP($D$2,COLORES[],2,FALSE),0)))+E59) *(1-_xlfn.XLOOKUP(1,(DESC_PROV[LINEA]=$B$2)*(DESC_PROV[LISTA]=$C$2),DESC_PROV[DESCUENTO])) *(1+VLOOKUP($C$2,LISTAS[],2,FALSE)) *(1+VLOOKUP($C$2,LISTAS[],3,FALSE)) ) /5,0)*5,0)} -> 239310 | I59: {=IFERROR( ROUND( IF($A$2="COSTO", ((B59*(1+IFERROR(VLOOKUP($D$2,COLORES[],2,FALSE),0))) + C59 + E59) *(1-_xlfn.XLOOKUP(1,(DESC_PROV[LINEA]=$B$2)*(DESC_PROV[LISTA]=$C$2),DESC_PROV[DESCUENTO])), ((B59*(1+IFERROR(VLOOKUP($D$2,COLORES[],2,FALSE),0))) + C59 + E59) *(1-_xlfn.XLOOKUP(1,(DESC_PROV[LINEA]=$B$2)*(DESC_PROV[LISTA]=$C$2),DESC_PROV[DESCUENTO])) *(1+VLOOKUP($C$2,LISTAS[],2,FALSE)) *(1+VLOOKUP($C$2,LISTAS[],3,FALSE)) ) /5,0)*5,0)} -> 279860 | J59: {=IFERROR( ROUND( IF($A$2="COSTO", (D59*(1+IFERROR(VLOOKUP($D$2,COLORES[],2,FALSE),0))) *(1-_xlfn.XLOOKUP(1,(DESC_PROV[LINEA]=$B$2)*(DESC_PROV[LISTA]=$C$2),DESC_PROV[DESCUENTO])), (D59*(1+IFERROR(VLOOKUP($D$2,COLORES[],2,FALSE),0))) *(1-_xlfn.XLOOKUP(1,(DESC_PROV[LINEA]=$B$2)*(DESC_PROV[LISTA]=$C$2),DESC_PROV[DESCUENTO])) *(1+VLOOKUP($C$2,LISTAS[],2,FALSE)) *(1+VLOOKUP($C$2,LISTAS[],4,FALSE)) ) /5,0)*5,0)} -> 88870 | K59: {=IFERROR( ROUND( IF($A$2="COSTO", (B59*(1+IFERROR(VLOOKUP($D$2,COLORES[],2,FALSE),0))+E59) *(1+VLOOKUP($C$2,LISTAS[],5,FALSE)) *(1-_xlfn.XLOOKUP(1,(DESC_PROV[LINEA]=$B$2)*(DESC_PROV[LISTA]=$C$2),DESC_PROV[DESCUENTO])), (B59*(1+IFERROR(VLOOKUP($D$2,COLORES[],2,FALSE),0))+E59) *(1-_xlfn.XLOOKUP(1,(DESC_PROV[LINEA]=$B$2)*(DESC_PROV[LISTA]=$C$2),DESC_PROV[DESCUENTO])) *(1+VLOOKUP($C$2,LISTAS[],5,FALSE)) *(1+VLOOKUP($C$2,LISTAS[],2,FALSE)) *(1+VLOOKUP($C$2,LISTAS[],3,FALSE)) ) /5,0)*5,0)} -> 311105
A60: 240x205 | B60: =B59*(1+5%) -> 127845.9 | C60: =C59*(1+5%) -> 34331.85 | D60: =D59*(1+5%) -> 61133.1 | E60: =E59*(1+5%) -> 74764.2 | G60: 240x205 | H60: {=IFERROR( ROUND( IF($A$2="COSTO", ((B60*(1+IFERROR(VLOOKUP($D$2,COLORES[],2,FALSE),0)))+E60) *(1-_xlfn.XLOOKUP(1,(DESC_PROV[LINEA]=$B$2)*(DESC_PROV[LISTA]=$C$2),DESC_PROV[DESCUENTO])), ((B60*(1+IFERROR(VLOOKUP($D$2,COLORES[],2,FALSE),0)))+E60) *(1-_xlfn.XLOOKUP(1,(DESC_PROV[LINEA]=$B$2)*(DESC_PROV[LISTA]=$C$2),DESC_PROV[DESCUENTO])) *(1+VLOOKUP($C$2,LISTAS[],2,FALSE)) *(1+VLOOKUP($C$2,LISTAS[],3,FALSE)) ) /5,0)*5,0)} -> 251275 | I60: {=IFERROR( ROUND( IF($A$2="COSTO", ((B60*(1+IFERROR(VLOOKUP($D$2,COLORES[],2,FALSE),0))) + C60 + E60) *(1-_xlfn.XLOOKUP(1,(DESC_PROV[LINEA]=$B$2)*(DESC_PROV[LISTA]=$C$2),DESC_PROV[DESCUENTO])), ((B60*(1+IFERROR(VLOOKUP($D$2,COLORES[],2,FALSE),0))) + C60 + E60) *(1-_xlfn.XLOOKUP(1,(DESC_PROV[LINEA]=$B$2)*(DESC_PROV[LISTA]=$C$2),DESC_PROV[DESCUENTO])) *(1+VLOOKUP($C$2,LISTAS[],2,FALSE)) *(1+VLOOKUP($C$2,LISTAS[],3,FALSE)) ) /5,0)*5,0)} -> 293855 | J60: {=IFERROR( ROUND( IF($A$2="COSTO", (D60*(1+IFERROR(VLOOKUP($D$2,COLORES[],2,FALSE),0))) *(1-_xlfn.XLOOKUP(1,(DESC_PROV[LINEA]=$B$2)*(DESC_PROV[LISTA]=$C$2),DESC_PROV[DESCUENTO])), (D60*(1+IFERROR(VLOOKUP($D$2,COLORES[],2,FALSE),0))) *(1-_xlfn.XLOOKUP(1,(DESC_PROV[LINEA]=$B$2)*(DESC_PROV[LISTA]=$C$2),DESC_PROV[DESCUENTO])) *(1+VLOOKUP($C$2,LISTAS[],2,FALSE)) *(1+VLOOKUP($C$2,LISTAS[],4,FALSE)) ) /5,0)*5,0)} -> 93315 | K60: {=IFERROR( ROUND( IF($A$2="COSTO", (B60*(1+IFERROR(VLOOKUP($D$2,COLORES[],2,FALSE),0))+E60) *(1+VLOOKUP($C$2,LISTAS[],5,FALSE)) *(1-_xlfn.XLOOKUP(1,(DESC_PROV[LINEA]=$B$2)*(DESC_PROV[LISTA]=$C$2),DESC_PROV[DESCUENTO])), (B60*(1+IFERROR(VLOOKUP($D$2,COLORES[],2,FALSE),0))+E60) *(1-_xlfn.XLOOKUP(1,(DESC_PROV[LINEA]=$B$2)*(DESC_PROV[LISTA]=$C$2),DESC_PROV[DESCUENTO])) *(1+VLOOKUP($C$2,LISTAS[],5,FALSE)) *(1+VLOOKUP($C$2,LISTAS[],2,FALSE)) *(1+VLOOKUP($C$2,LISTAS[],3,FALSE)) ) /5,0)*5,0)} -> 326660

Sheet mosquiteros
A1: MODO | B1: LINEA | C1: LISTA | D1: COLOR | E1: COLOR
A2: =CONTROL!B4 -> VENTA | B2: HERRERO | C2: GUILLE | D2: =CONTROL!D4 -> BLANCO | E2: ='ventana herrero'!C2 -> AMARILLA
A5: MOSQUITEROS (VENTANA COLOCADA)
A6: Medidas | B6: MOSQUITERO | D6: Medidas | E6: MOSQUITERO
A7: 60x50 | B7: 11094 | D7: 60x50 | E7: =IFERROR( ROUND( IF($A$2="COSTO", B7 *(1+IFERROR(VLOOKUP($D$2,COLORES[],2,FALSE),0)) *(1+VLOOKUP($C$2,LISTAS[],6,FALSE)), B7 *(1+IFERROR(VLOOKUP($D$2,COLORES[],2,FALSE),0)) *(1+VLOOKUP($C$2,LISTAS[],6,FALSE)) *(1+_xlfn.XLOOKUP($C$2,LISTAS[Lista],LISTAS[Mosq])) ),0),0) -> 22046
A8: 80x50 | B8: 12830 | D8: 80x50 | E8: =IFERROR( ROUND( IF($A$2="COSTO", B8 *(1+IFERROR(VLOOKUP($D$2,COLORES[],2,FALSE),0)) *(1+VLOOKUP($C$2,LISTAS[],6,FALSE)), B8 *(1+IFERROR(VLOOKUP($D$2,COLORES[],2,FALSE),0)) *(1+VLOOKUP($C$2,LISTAS[],6,FALSE)) *(1+_xlfn.XLOOKUP($C$2,LISTAS[Lista],LISTAS[Mosq])) ),0),0) -> 25496
A9: 100x50 | B9: 14565 | D9: 100x50 | E9: =IFERROR( ROUND( IF($A$2="COSTO", B9 *(1+IFERROR(VLOOKUP($D$2,COLORES[],2,FALSE),0)) *(1+VLOOKUP($C$2,LISTAS[],6,FALSE)), B9 *(1+IFERROR(VLOOKUP($D$2,COLORES[],2,FALSE),0)) *(1+VLOOKUP($C$2,LISTAS[],6,FALSE)) *(1+_xlfn.XLOOKUP($C$2,LISTAS[Lista],LISTAS[Mosq])) ),0),0) -> 28944
A10: 120x50 | B10: 16300 | D10: 120x50 | E10: =IFERROR( ROUND( IF($A$2="COSTO", B10 *(1+IFERROR(VLOOKUP($D$2,COLORES[],2,FALSE),0)) *(1+VLOOKUP($C$2,LISTAS[],6,FALSE)), B10 *(1+IFERROR(VLOOKUP($D$2,COLORES[],2,FALSE),0)) *(1+VLOOKUP($C$2,LISTAS[],6,FALSE)) *(1+_xlfn.XLOOKUP($C$2,LISTAS[Lista],LISTAS[Mosq])) ),0),0) -> 32391
A11: 150x50 | B11: 18905 | D11: 150x50 | E11: =IFERROR( ROUND( IF($A$2="COSTO", B11 *(1+IFERROR(VLOOKUP($D$2,COLORES[],2,FALSE),0)) *(1+VLOOKUP($C$2,LISTAS[],6,FALSE)), B11 *(1+IFERROR(VLOOKUP($D$2,COLORES[],2,FALSE),0)) *(1+VLOOKUP($C$2,LISTAS[],6,FALSE)) *(1+_xlfn.XLOOKUP($C$2,LISTAS[Lista],LISTAS[Mosq])) ),0),0) -> 37568
A12: 180x50 | B12: 21508 | D12: 180x50 | E12: =IFERROR( ROUND( IF($A$2="COSTO", B12 *(1+IFERROR(VLOOKUP($D$2,COLORES[],2,FALSE),0)) *(1+VLOOKUP($C$2,LISTAS[],6,FALSE)), B12 *(1+IFERROR(VLOOKUP($D$2,COLORES[],2,FALSE),0)) *(1+VLOOKUP($C$2,LISTAS[],6,FALSE)) *(1+_xlfn.XLOOKUP($C$2,LISTAS[Lista],LISTAS[Mosq])) ),0),0) -> 42741
A13: 200x50 | B13: 23244 | D13: 200x50 | E13: =IFERROR( ROUND( IF($A$2="COSTO", B13 *(1+IFERROR(VLOOKUP($D$2,COLORES[],2,FALSE),0)) *(1+VLOOKUP($C$2,LISTAS[],6,FALSE)), B13 *(1+IFERROR(VLOOKUP($D$2,COLORES[],2,FALSE),0)) *(1+VLOOKUP($C$2,LISTAS[],6,FALSE)) *(1+_xlfn.XLOOKUP($C$2,LISTAS[Lista],LISTAS[Mosq])) ),0),0) -> 46190
A14: 80x80 | B14: 17580 | D14: 80x80 | E14: =IFERROR( ROUND( IF($A$2="COSTO", B14 *(1+IFERROR(VLOOKUP($D$2,COLORES[],2,FALSE),0)) *(1+VLOOKUP($C$2,LISTAS[],6,FALSE)), B14 *(1+IFERROR(VLOOKUP($D$2,COLORES[],2,FALSE),0)) *(1+VLOOKUP($C$2,LISTAS[],6,FALSE)) *(1+_xlfn.XLOOKUP($C$2,LISTAS[Lista],LISTAS[Mosq])) ),0),0) -> 34935
A15: 100x80 | B15: 19772 | D15: 100x80 | E15: =IFERROR( ROUND( IF($A$2="COSTO", B15 *(1+IFERROR(VLOOKUP($D$2,COLORES[],2,FALSE),0)) *(1+VLOOKUP($C$2,LISTAS[],6,FALSE)), B15 *(1+IFERROR(VLOOKUP($D$2,COLORES[],2,FALSE),0)) *(1+VLOOKUP($C$2,LISTAS[],6,FALSE)) *(1+_xlfn.XLOOKUP($C$2,LISTAS[Lista],LISTAS[Mosq])) ),0),0) -> 39291
A16: 120x80 | B16: 21965 | D16: 120x80 | E16: =IFERROR( ROUND( IF($A$2="COSTO", B16 *(1+IFERROR(VLOOKUP($D$2,COLORES[],2,FALSE),0)) *(1+VLOOKUP($C$2,LISTAS[],6,FALSE)), B16 *(1+IFERROR(VLOOKUP($D$2,COLORES[],2,FALSE),0)) *(1+VLOOKUP($C$2,LISTAS[],6,FALSE)) *(1+_xlfn.XLOOKUP($C$2,LISTAS[Lista],LISTAS[Mosq])) ),0),0) -> 43649
A17: 150x80 | B17: 25254 | D17: 150x80 | E17: =IFERROR( ROUND( IF($A$2="COSTO", B17 *(1+IFERROR(VLOOKUP($D$2,COLORES[],2,FALSE),0)) *(1+VLOOKUP($C$2,LISTAS[],6,FALSE)), B17 *(1+IFERROR(VLOOKUP($D$2,COLORES[],2,FALSE),0)) *(1+VLOOKUP($C$2,LISTAS[],6,FALSE)) *(1+_xlfn.XLOOKUP($C$2,LISTAS[Lista],LISTAS[Mosq])) ),0),0) -> 50185
A18: 180x80 | B18: 28542 | D18: 180x80 | E18: =IFERROR( ROUND( IF($A$2="COSTO", B18 *(1+IFERROR(VLOOKUP($D$2,COLORES[],2,FALSE),0)) *(1+VLOOKUP($C$2,LISTAS[],6,FALSE)), B18 *(1+IFERROR(VLOOKUP($D$2,COLORES[],2,FALSE),0)) *(1+VLOOKUP($C$2,LISTAS[],6,FALSE)) *(1+_xlfn.XLOOKUP($C$2,LISTAS[Lista],LISTAS[Mosq])) ),0),0) -> 56719
... A60: 240x205 | B60: 74000 | D60: 240x205 | E60: =IFERROR( ROUND( IF($A$2="COSTO", B60 *(1+IFERROR(VLOOKUP($D$2,COLORES[],2,FALSE),0)) *(1+VLOOKUP($C$2,LISTAS[],6,FALSE)), B60 *(1+IFERROR(VLOOKUP($D$2,COLORES[],2,FALSE),0)) *(1+VLOOKUP($C$2,LISTAS[],6,FALSE)) *(1+_xlfn.XLOOKUP($C$2,LISTAS[Lista],LISTAS[Mosq])) ),0),0) -> 147053

Sheet rajas herrero
A1: MODO | B1: LINEA | C1: LISTA | D1: COLOR
A2: =CONTROL!B4 -> VENTA | B2: HERRERO | C2: =CONTROL!C4 -> AMARILLA | D2: =CONTROL!D4 -> BLANCO
A5: RAJAS DE ABRIR HERRERO | K5: RAJAS DE ABRIR HERRERO
A6: Medidas | B6: sin vidrio | C6: 3mm | D6: 4mm | E6: 5mm | F6: esmerilado | G6: fantasia | H6: 3+3 | K6: Medidas | L6: 3mm | M6: 4mm | N6: 5mm | O6: esmerilado | P6: fantasia | Q6: 3+3
A7: 40x40 | B7: 30411 | C7: 2308 | D7: 2796 | E7: 3683 | F7: 7973 | G7: 3077 | H7: 11924 | K7: 40x40 | L7: {=IFERROR( ROUND( IF($A$2="COSTO", ((B7*(1+IFERROR(VLOOKUP($D$2,COLORES[],2,FALSE),0)))+C7) *(1-_xlfn.XLOOKUP(1,(DESC_PROV[LINEA]=$B$2)*(DESC_PROV[LISTA]=$C$2),DESC_PROV[DESCUENTO])), ((B7*(1+IFERROR(VLOOKUP($D$2,COLORES[],2,FALSE),0)))+C7) *(1-_xlfn.XLOOKUP(1,(DESC_PROV[LINEA]=$B$2)*(DESC_PROV[LISTA]=$C$2),DESC_PROV[DESCUENTO])) *(1+VLOOKUP($C$2,LISTAS[],2,FALSE)) *(1+VLOOKUP($C$2,LISTAS[],3,FALSE)) ) /5,0)*5,0)} -> 40580 | M7: {=IFERROR( ROUND( IF($A$2="COSTO", ((B7*(1+IFERROR(VLOOKUP($D$2,COLORES[],2,FALSE),0)))+D7) *(1-_xlfn.XLOOKUP(1,(DESC_PROV[LINEA]=$B$2)*(DESC_PROV[LISTA]=$C$2),DESC_PROV[DESCUENTO])), ((B7*(1+IFERROR(VLOOKUP($D$2,COLORES[],2,FALSE),0)))+D7) *(1-_xlfn.XLOOKUP(1,(DESC_PROV[LINEA]=$B$2)*(DESC_PROV[LISTA]=$C$2),DESC_PROV[DESCUENTO])) *(1+VLOOKUP($C$2,LISTAS[],2,FALSE)) *(1+VLOOKUP($C$2,LISTAS[],3,FALSE)) ) /5,0)*5,0)} -> 41185 | N7: {=IFERROR( ROUND( IF($A$2="COSTO", ((B7*(1+IFERROR(VLOOKUP($D$2,COLORES[],2,FALSE),0)))+E7) *(1-_xlfn.XLOOKUP(1,(DESC_PROV[LINEA]=$B$2)*(DESC_PROV[LISTA]=$C$2),DESC_PROV[DESCUENTO])), ((B7*(1+IFERROR(VLOOKUP($D$2,COLORES[],2,FALSE),0)))+E7) *(1-_xlfn.XLOOKUP(1,(DESC_PROV[LINEA]=$B$2)*(DESC_PROV[LISTA]=$C$2),DESC_PROV[DESCUENTO])) *(1+VLOOKUP($C$2,LISTAS[],2,FALSE)) *(1+VLOOKUP($C$2,LISTAS[],3,FALSE)) ) /5,0)*5,0)} -> 42285 | O7: {=IFERROR( ROUND( IF($A$2="COSTO", ((B7*(1+IFERROR(VLOOKUP($D$2,COLORES[],2,FALSE),0)))+F7) *(1-_xlfn.XLOOKUP(1,(DESC_PROV[LINEA]=$B$2)*(DESC_PROV[LISTA]=$C$2),DESC_PROV[DESCUENTO])), ((B7*(1+IFERROR(VLOOKUP($D$2,COLORES[],2,FALSE),0)))+F7) *(1-_xlfn.XLOOKUP(1,(DESC_PROV[LINEA]=$B$2)*(DESC_PROV[LISTA]=$C$2),DESC_PROV[DESCUENTO])) *(1+VLOOKUP($C$2,LISTAS[],2,FALSE)) *(1+VLOOKUP($C$2,LISTAS[],3,FALSE)) ) /5,0)*5,0)} -> 47605 | P7: {=IFERROR( ROUND( IF($A$2="COSTO", ((B7*(1+IFERROR(VLOOKUP($D$2,COLORES[],2,FALSE),0)))+G7) *(1-_xlfn.XLOOKUP(1,(DESC_PROV[LINEA]=$B$2)*(DESC_PROV[LISTA]=$C$2),DESC_PROV[DESCUENTO])), ((B7*(1+IFERROR(VLOOKUP($D$2,COLORES[],2,FALSE),0)))+G7) *(1-_xlfn.XLOOKUP(1,(DESC_PROV[LINEA]=$B$2)*(DESC_PROV[LISTA]=$C$2),DESC_PROV[DESCUENTO])) *(1+VLOOKUP($C$2,LISTAS[],2,FALSE)) *(1+VLOOKUP($C$2,LISTAS[],3,FALSE)) ) /5,0)*5,0)} -> 41530 | Q7: {=IFERROR( ROUND( IF($A$2="COSTO", ((B7*(1+IFERROR(VLOOKUP($D$2,COLORES[],2,FALSE),0)))+H7) *(1-_xlfn.XLOOKUP(1,(DESC_PROV[LINEA]=$B$2)*(DESC_PROV[LISTA]=$C$2),DESC_PROV[DESCUENTO])), ((B7*(1+IFERROR(VLOOKUP($D$2,COLORES[],2,FALSE),0)))+H7) *(1-_xlfn.XLOOKUP(1,(DESC_PROV[LINEA]=$B$2)*(DESC_PROV[LISTA]=$C$2),DESC_PROV[DESCUENTO])) *(1+VLOOKUP($C$2,LISTAS[],2,FALSE)) *(1+VLOOKUP($C$2,LISTAS[],3,FALSE)) ) /5,0)*5,0)} -> 52505
A8: 50x40 | B8: 32505 | C8: 3077 | D8: 3729 | E8: 4914 | F8: 10634 | G8: 4109 | H8: 15910 | K8: 50x40 | L8: {=IFERROR( ROUND( IF($A$2="COSTO", ((B8*(1+IFERROR(VLOOKUP($D$2,COLORES[],2,FALSE),0)))+C8) *(1-_xlfn.XLOOKUP(1,(DESC_PROV[LINEA]=$B$2)*(DESC_PROV[LISTA]=$C$2),DESC_PROV[DESCUENTO])), ((B8*(1+IFERROR(VLOOKUP($D$2,COLORES[],2,FALSE),0)))+C8) *(1-_xlfn.XLOOKUP(1,(DESC_PROV[LINEA]=$B$2)*(DESC_PROV[LISTA]=$C$2),DESC_PROV[DESCUENTO])) *(1+VLOOKUP($C$2,LISTAS[],2,FALSE)) *(1+VLOOKUP($C$2,LISTAS[],3,FALSE)) ) /5,0)*5,0)} -> 44130 | M8: {=IFERROR( ROUND( IF($A$2="COSTO", ((B8*(1+IFERROR(VLOOKUP($D$2,COLORES[],2,FALSE),0)))+D8) *(1-_xlfn.XLOOKUP(1,(DESC_PROV[LINEA]=$B$2)*(DESC_PROV[LISTA]=$C$2),DESC_PROV[DESCUENTO])), ((B8*(1+IFERROR(VLOOKUP($D$2,COLORES[],2,FALSE),0)))+D8) *(1-_xlfn.XLOOKUP(1,(DESC_PROV[LINEA]=$B$2)*(DESC_PROV[LISTA]=$C$2),DESC_PROV[DESCUENTO])) *(1+VLOOKUP($C$2,LISTAS[],2,FALSE)) *(1+VLOOKUP($C$2,LISTAS[],3,FALSE)) ) /5,0)*5,0)} -> 44935 | N8: {=IFERROR( ROUND( IF($A$2="COSTO", ((B8*(1+IFERROR(VLOOKUP($D$2,COLORES[],2,FALSE),0)))+E8) *(1-_xlfn.XLOOKUP(1,(DESC_PROV[LINEA]=$B$2)*(DESC_PROV[LISTA]=$C$2),DESC_PROV[DESCUENTO])), ((B8*(1+IFERROR(VLOOKUP($D$2,COLORES[],2,FALSE),0)))+E8) *(1-_xlfn.XLOOKUP(1,(DESC_PROV[LINEA]=$B$2)*(DESC_PROV[LISTA]=$C$2),DESC_PROV[DESCUENTO])) *(1+VLOOKUP($C$2,LISTAS[],2,FALSE)) *(1+VLOOKUP($C$2,LISTAS[],3,FALSE)) ) /5,0)*5,0)} -> 46405 | O8: {=IFERROR( ROUND( IF($A$2="COSTO", ((B8*(1+IFERROR(VLOOKUP($D$2,COLORES[],2,FALSE),0)))+F8) *(1-_xlfn.XLOOKUP(1,(DESC_PROV[LINEA]=$B$2)*(DESC_PROV[LISTA]=$C$2),DESC_PROV[DESCUENTO])), ((B8*(1+IFERROR(VLOOKUP($D$2,COLORES[],2,FALSE),0)))+F8) *(1-_xlfn.XLOOKUP(1,(DESC_PROV[LINEA]=$B$2)*(DESC_PROV[LISTA]=$C$2),DESC_PROV[DESCUENTO])) *(1+VLOOKUP($C$2,LISTAS[],2,FALSE)) *(1+VLOOKUP($C$2,LISTAS[],3,FALSE)) ) /5,0)*5,0)} -> 53500 | P8: {=IFERROR( ROUND( IF($A$2="COSTO", ((B8*(1+IFERROR(VLOOKUP($D$2,COLORES[],2,FALSE),0)))+G8) *(1-_xlfn.XLOOKUP(1,(DESC_PROV[LINEA]=$B$2)*(DESC_PROV[LISTA]=$C$2),DESC_PROV[DESCUENTO])), ((B8*(1+IFERROR(VLOOKUP($D$2,COLORES[],2,FALSE),0)))+G8) *(1-_xlfn.XLOOKUP(1,(DESC_PROV[LINEA]=$B$2)*(DESC_PROV[LISTA]=$C$2),DESC_PROV[DESCUENTO])) *(1+VLOOKUP($C$2,LISTAS[],2,FALSE)) *(1+VLOOKUP($C$2,LISTAS[],3,FALSE)) ) /5,0)*5,0)} -> 45410 | Q8: {=IFERROR( ROUND( IF($A$2="COSTO", ((B8*(1+IFERROR(VLOOKUP($D$2,COLORES[],2,FALSE),0)))+H8) *(1-_xlfn.XLOOKUP(1,(DESC_PROV[LINEA]=$B$2)*(DESC_PROV[LISTA]=$C$2),DESC_PROV[DESCUENTO])), ((B8*(1+IFERROR(VLOOKUP($D$2,COLORES[],2,FALSE),0)))+H8) *(1-_xlfn.XLOOKUP(1,(DESC_PROV[LINEA]=$B$2)*(DESC_PROV[LISTA]=$C$2),DESC_PROV[DESCUENTO])) *(1+VLOOKUP($C$2,LISTAS[],2,FALSE)) *(1+VLOOKUP($C$2,LISTAS[],3,FALSE)) ) /5,0)*5,0)} -> 60045
A9: 60x40 | B9: 34605 | C9: 3846 | D9: 4661 | E9: 6145 | F9: 13294 | G9: 5140 | H9: 19896 | K9: 60x40 | L9: {=IFERROR( ROUND( IF($A$2="COSTO", ((B9*(1+IFERROR(VLOOKUP($D$2,COLORES[],2,FALSE),0)))+C9) *(1-_xlfn.XLOOKUP(1,(DESC_PROV[LINEA]=$B$2)*(DESC_PROV[LISTA]=$C$2),DESC_PROV[DESCUENTO])), ((B9*(1+IFERROR(VLOOKUP($D$2,COLORES[],2,FALSE),0)))+C9) *(1-_xlfn.XLOOKUP(1,(DESC_PROV[LINEA]=$B$2)*(DESC_PROV[LISTA]=$C$2),DESC_PROV[DESCUENTO])) *(1+VLOOKUP($C$2,LISTAS[],2,FALSE)) *(1+VLOOKUP($C$2,LISTAS[],3,FALSE)) ) /5,0)*5,0)} -> 47685 | M9: {=IFERROR( ROUND( IF($A$2="COSTO", ((B9*(1+IFERROR(VLOOKUP($D$2,COLORES[],2,FALSE),0)))+D9) *(1-_xlfn.XLOOKUP(1,(DESC_PROV[LINEA]=$B$2)*(DESC_PROV[LISTA]=$C$2),DESC_PROV[DESCUENTO])), ((B9*(1+IFERROR(VLOOKUP($D$2,COLORES[],2,FALSE),0)))+D9) *(1-_xlfn.XLOOKUP(1,(DESC_PROV[LINEA]=$B$2)*(DESC_PROV[LISTA]=$C$2),DESC_PROV[DESCUENTO])) *(1+VLOOKUP($C$2,LISTAS[],2,FALSE)) *(1+VLOOKUP($C$2,LISTAS[],3,FALSE)) ) /5,0)*5,0)} -> 48700 | N9: {=IFERROR( ROUND( IF($A$2="COSTO", ((B9*(1+IFERROR(VLOOKUP($D$2,COLORES[],2,FALSE),0)))+E9) *(1-_xlfn.XLOOKUP(1,(DESC_PROV[LINEA]=$B$2)*(DESC_PROV[LISTA]=$C$2),DESC_PROV[DESCUENTO])), ((B9*(1+IFERROR(VLOOKUP($D$2,COLORES[],2,FALSE),0)))+E9) *(1-_xlfn.XLOOKUP(1,(DESC_PROV[LINEA]=$B$2)*(DESC_PROV[LISTA]=$C$2),DESC_PROV[DESCUENTO])) *(1+VLOOKUP($C$2,LISTAS[],2,FALSE)) *(1+VLOOKUP($C$2,LISTAS[],3,FALSE)) ) /5,0)*5,0)} -> 50540 | O9: {=IFERROR( ROUND( IF($A$2="COSTO", ((B9*(1+IFERROR(VLOOKUP($D$2,COLORES[],2,FALSE),0)))+F9) *(1-_xlfn.XLOOKUP(1,(DESC_PROV[LINEA]=$B$2)*(DESC_PROV[LISTA]=$C$2),DESC_PROV[DESCUENTO])), ((B9*(1+IFERROR(VLOOKUP($D$2,COLORES[],2,FALSE),0)))+F9) *(1-_xlfn.XLOOKUP(1,(DESC_PROV[LINEA]=$B$2)*(DESC_PROV[LISTA]=$C$2),DESC_PROV[DESCUENTO])) *(1+VLOOKUP($C$2,LISTAS[],2,FALSE)) *(1+VLOOKUP($C$2,LISTAS[],3,FALSE)) ) /5,0)*5,0)} -> 59405 | P9: {=IFERROR( ROUND( IF($A$2="COSTO", ((B9*(1+IFERROR(VLOOKUP($D$2,COLORES[],2,FALSE),0)))+G9) *(1-_xlfn.XLOOKUP(1,(DESC_PROV[LINEA]=$B$2)*(DESC_PROV[LISTA]=$C$2),DESC_PROV[DESCUENTO])), ((B9*(1+IFERROR(VLOOKUP($D$2,COLORES[],2,FALSE),0)))+G9) *(1-_xlfn.XLOOKUP(1,(DESC_PROV[LINEA]=$B$2)*(DESC_PROV[LISTA]=$C$2),DESC_PROV[DESCUENTO])) *(1+VLOOKUP($C$2,LISTAS[],2,FALSE)) *(1+VLOOKUP($C$2,LISTAS[],3,FALSE)) ) /5,0)*5,0)} -> 49290 | Q9: {=IFERROR( ROUND( IF($A$2="COSTO", ((B9*(1+IFERROR(VLOOKUP($D$2,COLORES[],2,FALSE),0)))+H9) *(1-_xlfn.XLOOKUP(1,(DESC_PROV[LINEA]=$B$2)*(DESC_PROV[LISTA]=$C$2),DESC_PROV[DESCUENTO])), ((B9*(1+IFERROR(VLOOKUP($D$2,COLORES[],2,FALSE),0)))+H9) *(1-_xlfn.XLOOKUP(1,(DESC_PROV[LINEA]=$B$2)*(DESC_PROV[LISTA]=$C$2),DESC_PROV[DESCUENTO])) *(1+VLOOKUP($C$2,LISTAS[],2,FALSE)) *(1+VLOOKUP($C$2,LISTAS[],3,FALSE)) ) /5,0)*5,0)} -> 67590
A10: 70x40 | B10: 36700 | C10: 4616 | D10: 5593 | E10: 7376 | F10: 15955 | G10: 6172 | H10: 23881 | K10: 70x40 | L10: {=IFERROR( ROUND( IF($A$2="COSTO", ((B10*(1+IFERROR(VLOOKUP($D$2,COLORES[],2,FALSE),0)))+C10) *(1-_xlfn.XLOOKUP(1,(DESC_PROV[LINEA]=$B$2)*(DESC_PROV[LISTA]=$C$2),DESC_PROV[DESCUENTO])), ((B10*(1+IFERROR(VLOOKUP($D$2,COLORES[],2,FALSE),0)))+C10) *(1-_xlfn.XLOOKUP(1,(DESC_PROV[LINEA]=$B$2)*(DESC_PROV[LISTA]=$C$2),DESC_PROV[DESCUENTO])) *(1+VLOOKUP($C$2,LISTAS[],2,FALSE)) *(1+VLOOKUP($C$2,LISTAS[],3,FALSE)) ) /5,0)*5,0)} -> 51240 | M10: {=IFERROR( ROUND( IF($A$2="COSTO", ((B10*(1+IFERROR(VLOOKUP($D$2,COLORES[],2,FALSE),0)))+D10) *(1-_xlfn.XLOOKUP(1,(DESC_PROV[LINEA]=$B$2)*(DESC_PROV[LISTA]=$C$2),DESC_PROV[DESCUENTO])), ((B10*(1+IFERROR(VLOOKUP($D$2,COLORES[],2,FALSE),0)))+D10) *(1-_xlfn.XLOOKUP(1,(DESC_PROV[LINEA]=$B$2)*(DESC_PROV[LISTA]=$C$2),DESC_PROV[DESCUENTO])) *(1+VLOOKUP($C$2,LISTAS[],2,FALSE)) *(1+VLOOKUP($C$2,LISTAS[],3,FALSE)) ) /5,0)*5,0)} -> 52450 | N10: {=IFERROR( ROUND( IF($A$2="COSTO", ((B10*(1+IFERROR(VLOOKUP($D$2,COLORES[],2,FALSE),0)))+E10) *(1-_xlfn.XLOOKUP(1,(DESC_PROV[LINEA]=$B$2)*(DESC_PROV[LISTA]=$C$2),DESC_PROV[DESCUENTO])), ((B10*(1+IFERROR(VLOOKUP($D$2,COLORES[],2,FALSE),0)))+E10) *(1-_xlfn.XLOOKUP(1,(DESC_PROV[LINEA]=$B$2)*(DESC_PROV[LISTA]=$C$2),DESC_PROV[DESCUENTO])) *(1+VLOOKUP($C$2,LISTAS[],2,FALSE)) *(1+VLOOKUP($C$2,LISTAS[],3,FALSE)) ) /5,0)*5,0)} -> 54665 | O10: {=IFERROR( ROUND( IF($A$2="COSTO", ((B10*(1+IFERROR(VLOOKUP($D$2,COLORES[],2,FALSE),0)))+F10) *(1-_xlfn.XLOOKUP(1,(DESC_PROV[LINEA]=$B$2)*(DESC_PROV[LISTA]=$C$2),DESC_PROV[DESCUENTO])), ((B10*(1+IFERROR(VLOOKUP($D$2,COLORES[],2,FALSE),0)))+F10) *(1-_xlfn.XLOOKUP(1,(DESC_PROV[LINEA]=$B$2)*(DESC_PROV[LISTA]=$C$2),DESC_PROV[DESCUENTO])) *(1+VLOOKUP($C$2,LISTAS[],2,FALSE)) *(1+VLOOKUP($C$2,LISTAS[],3,FALSE)) ) /5,0)*5,0)} -> 65305 | P10: {=IFERROR( ROUND( IF($A$2="COSTO", ((B10*(1+IFERROR(VLOOKUP($D$2,COLORES[],2,FALSE),0)))+G10) *(1-_xlfn.XLOOKUP(1,(DESC_PROV[LINEA]=$B$2)*(DESC_PROV[LISTA]=$C$2),DESC_PROV[DESCUENTO])), ((B10*(1+IFERROR(VLOOKUP($D$2,COLORES[],2,FALSE),0)))+G10) *(1-_xlfn.XLOOKUP(1,(DESC_PROV[LINEA]=$B$2)*(DESC_PROV[LISTA]=$C$2),DESC_PROV[DESCUENTO])) *(1+VLOOKUP($C$2,LISTAS[],2,FALSE)) *(1+VLOOKUP($C$2,LISTAS[],3,FALSE)) ) /5,0)*5,0)} -> 53170 | Q10: {=IFERROR( ROUND( IF($A$2="COSTO", ((B10*(1+IFERROR(VLOOKUP($D$2,COLORES[],2,FALSE),0)))+H10) *(1-_xlfn.XLOOKUP(1,(DESC_PROV[LINEA]=$B$2)*(DESC_PROV[LISTA]=$C$2),DESC_PROV[DESCUENTO])), ((B10*(1+IFERROR(VLOOKUP($D$2,COLORES[],2,FALSE),0)))+H10) *(1-_xlfn.XLOOKUP(1,(DESC_PROV[LINEA]=$B$2)*(DESC_PROV[LISTA]=$C$2),DESC_PROV[DESCUENTO])) *(1+VLOOKUP($C$2,LISTAS[],2,FALSE)) *(1+VLOOKUP($C$2,LISTAS[],3,FALSE)) ) /5,0)*5,0)} -> 75135
A11: 80x40 | B11: 38794 | C11: 5385 | D11: 6525 | E11: 8607 | F11: 18616 | G11: 7204 | H11: 27867 | K11: 80x40 | L11: {=IFERROR( ROUND( IF($A$2="COSTO", ((B11*(1+IFERROR(VLOOKUP($D$2,COLORES[],2,FALSE),0)))+C11) *(1-_xlfn.XLOOKUP(1,(DESC_PROV[LINEA]=$B$2)*(DESC_PROV[LISTA]=$C$2),DESC_PROV[DESCUENTO])), ((B11*(1+IFERROR(VLOOKUP($D$2,COLORES[],2,FALSE),0)))+C11) *(1-_xlfn.XLOOKUP(1,(DESC_PROV[LINEA]=$B$2)*(DESC_PROV[LISTA]=$C$2),DESC_PROV[DESCUENTO])) *(1+VLOOKUP($C$2,LISTAS[],2,FALSE)) *(1+VLOOKUP($C$2,LISTAS[],3,FALSE)) ) /5,0)*5,0)} -> 54790 | M11: {=IFERROR( ROUND( IF($A$2="COSTO", ((B11*(1+IFERROR(VLOOKUP($D$2,COLORES[],2,FALSE),0)))+D11) *(1-_xlfn.XLOOKUP(1,(DESC_PROV[LINEA]=$B$2)*(DESC_PROV[LISTA]=$C$2),DESC_PROV[DESCUENTO])), ((B11*(1+IFERROR(VLOOKUP($D$2,COLORES[],2,FALSE),0)))+D11) *(1-_xlfn.XLOOKUP(1,(DESC_PROV[LINEA]=$B$2)*(DESC_PROV[LISTA]=$C$2),DESC_PROV[DESCUENTO])) *(1+VLOOKUP($C$2,LISTAS[],2,FALSE)) *(1+VLOOKUP($C$2,LISTAS[],3,FALSE)) ) /5,0)*5,0)} -> 56205 | N11: {=IFERROR( ROUND( IF($A$2="COSTO", ((B11*(1+IFERROR(VLOOKUP($D$2,COLORES[],2,FALSE),0)))+E11) *(1-_xlfn.XLOOKUP(1,(DESC_PROV[LINEA]=$B$2)*(DESC_PROV[LISTA]=$C$2),DESC_PROV[DESCUENTO])), ((B11*(1+IFERROR(VLOOKUP($D$2,COLORES[],2,FALSE),0)))+E11) *(1-_xlfn.XLOOKUP(1,(DESC_PROV[LINEA]=$B$2)*(DESC_PROV[LISTA]=$C$2),DESC_PROV[DESCUENTO])) *(1+VLOOKUP($C$2,LISTAS[],2,FALSE)) *(1+VLOOKUP($C$2,LISTAS[],3,FALSE)) ) /5,0)*5,0)} -> 58785 | O11: {=IFERROR( ROUND( IF($A$2="COSTO", ((B11*(1+IFERROR(VLOOKUP($D$2,COLORES[],2,FALSE),0)))+F11) *(1-_xlfn.XLOOKUP(1,(DESC_PROV[LINEA]=$B$2)*(DESC_PROV[LISTA]=$C$2),DESC_PROV[DESCUENTO])), ((B11*(1+IFERROR(VLOOKUP($D$2,COLORES[],2,FALSE),0)))+F11) *(1-_xlfn.XLOOKUP(1,(DESC_PROV[LINEA]=$B$2)*(DESC_PROV[LISTA]=$C$2),DESC_PROV[DESCUENTO])) *(1+VLOOKUP($C$2,LISTAS[],2,FALSE)) *(1+VLOOKUP($C$2,LISTAS[],3,FALSE)) ) /5,0)*5,0)} -> 71200 | P11: {=IFERROR( ROUND( IF($A$2="COSTO", ((B11*(1+IFERROR(VLOOKUP($D$2,COLORES[],2,FALSE),0)))+G11) *(1-_xlfn.XLOOKUP(1,(DESC_PROV[LINEA]=$B$2)*(DESC_PROV[LISTA]=$C$2),DESC_PROV[DESCUENTO])), ((B11*(1+IFERROR(VLOOKUP($D$2,COLORES[],2,FALSE),0)))+G11) *(1-_xlfn.XLOOKUP(1,(DESC_PROV[LINEA]=$B$2)*(DESC_PROV[LISTA]=$C$2),DESC_PROV[DESCUENTO])) *(1+VLOOKUP($C$2,LISTAS[],2,FALSE)) *(1+VLOOKUP($C$2,LISTAS[],3,FALSE)) ) /5,0)*5,0)} -> 57045 | Q11: {=IFERROR( ROUND( IF($A$2="COSTO", ((B11*(1+IFERROR(VLOOKUP($D$2,COLORES[],2,FALSE),0)))+H11) *(1-_xlfn.XLOOKUP(1,(DESC_PROV[LINEA]=$B$2)*(DESC_PROV[LISTA]=$C$2),DESC_PROV[DESCUENTO])), ((B11*(1+IFERROR(VLOOKUP($D$2,COLORES[],2,FALSE),0)))+H11) *(1-_xlfn.XLOOKUP(1,(DESC_PROV[LINEA]=$B$2)*(DESC_PROV[LISTA]=$C$2),DESC_PROV[DESCUENTO])) *(1+VLOOKUP($C$2,LISTAS[],2,FALSE)) *(1+VLOOKUP($C$2,LISTAS[],3,FALSE)) ) /5,0)*5,0)} -> 82675
A12: 90x40 | B12: 40888 | C12: 6154 | D12: 7457 | E12: 9837 | F12: 21277 | G12: 8236 | H12: 31852 | K12: 90x40 | L12: {=IFERROR( ROUND( IF($A$2="COSTO", ((B12*(1+IFERROR(VLOOKUP($D$2,COLORES[],2,FALSE),0)))+C12) *(1-_xlfn.XLOOKUP(1,(DESC_PROV[LINEA]=$B$2)*(DESC_PROV[LISTA]=$C$2),DESC_PROV[DESCUENTO])), ((B12*(1+IFERROR(VLOOKUP($D$2,COLORES[],2,FALSE),0)))+C12) *(1-_xlfn.XLOOKUP(1,(DESC_PROV[LINEA]=$B$2)*(DESC_PROV[LISTA]=$C$2),DESC_PROV[DESCUENTO])) *(1+VLOOKUP($C$2,LISTAS[],2,FALSE)) *(1+VLOOKUP($C$2,LISTAS[],3,FALSE)) ) /5,0)*5,0)} -> 58340 | M12: {=IFERROR( ROUND( IF($A$2="COSTO", ((B12*(1+IFERROR(VLOOKUP($D$2,COLORES[],2,FALSE),0)))+D12) *(1-_xlfn.XLOOKUP(1,(DESC_PROV[LINEA]=$B$2)*(DESC_PROV[LISTA]=$C$2),DESC_PROV[DESCUENTO])), ((B12*(1+IFERROR(VLOOKUP($D$2,COLORES[],2,FALSE),0)))+D12) *(1-_xlfn.XLOOKUP(1,(DESC_PROV[LINEA]=$B$2)*(DESC_PROV[LISTA]=$C$2),DESC_PROV[DESCUENTO])) *(1+VLOOKUP($C$2,LISTAS[],2,FALSE)) *(1+VLOOKUP($C$2,LISTAS[],3,FALSE)) ) /5,0)*5,0)} -> 59955 | N12: {=IFERROR( ROUND( IF($A$2="COSTO", ((B12*(1+IFERROR(VLOOKUP($D$2,COLORES[],2,FALSE),0)))+E12) *(1-_xlfn.XLOOKUP(1,(DESC_PROV[LINEA]=$B$2)*(DESC_PROV[LISTA]=$C$2),DESC_PROV[DESCUENTO])), ((B12*(1+IFERROR(VLOOKUP($D$2,COLORES[],2,FALSE),0)))+E12) *(1-_xlfn.XLOOKUP(1,(DESC_PROV[LINEA]=$B$2)*(DESC_PROV[LISTA]=$C$2),DESC_PROV[DESCUENTO])) *(1+VLOOKUP($C$2,LISTAS[],2,FALSE)) *(1+VLOOKUP($C$2,LISTAS[],3,FALSE)) ) /5,0)*5,0)} -> 62910 | O12: {=IFERROR( ROUND( IF($A$2="COSTO", ((B12*(1+IFERROR(VLOOKUP($D$2,COLORES[],2,FALSE),0)))+F12) *(1-_xlfn.XLOOKUP(1,(DESC_PROV[LINEA]=$B$2)*(DESC_PROV[LISTA]=$C$2),DESC_PROV[DESCUENTO])), ((B12*(1+IFERROR(VLOOKUP($D$2,COLORES[],2,FALSE),0)))+F12) *(1-_xlfn.XLOOKUP(1,(DESC_PROV[LINEA]=$B$2)*(DESC_PROV[LISTA]=$C$2),DESC_PROV[DESCUENTO])) *(1+VLOOKUP($C$2,LISTAS[],2,FALSE)) *(1+VLOOKUP($C$2,LISTAS[],3,FALSE)) ) /5,0)*5,0)} -> 77095 | P12: {=IFERROR( ROUND( IF($A$2="COSTO", ((B12*(1+IFERROR(VLOOKUP($D$2,COLORES[],2,FALSE),0)))+G12) *(1-_xlfn.XLOOKUP(1,(DESC_PROV[LINEA]=$B$2)*(DESC_PROV[LISTA]=$C$2),DESC_PROV[DESCUENTO])), ((B12*(1+IFERROR(VLOOKUP($D$2,COLORES[],2,FALSE),0)))+G12) *(1-_xlfn.XLOOKUP(1,(DESC_PROV[LINEA]=$B$2)*(DESC_PROV[LISTA]=$C$2),DESC_PROV[DESCUENTO])) *(1+VLOOKUP($C$2,LISTAS[],2,FALSE)) *(1+VLOOKUP($C$2,LISTAS[],3,FALSE)) ) /5,0)*5,0)} -> 60925 | Q12: {=IFERROR( ROUND( IF($A$2="COSTO", ((B12*(1+IFERROR(VLOOKUP($D$2,COLORES[],2,FALSE),0)))+H12) *(1-_xlfn.XLOOKUP(1,(DESC_PROV[LINEA]=$B$2)*(DESC_PROV[LISTA]=$C$2),DESC_PROV[DESCUENTO])), ((B12*(1+IFERROR(VLOOKUP($D$2,COLORES[],2,FALSE),0)))+H12) *(1-_xlfn.XLOOKUP(1,(DESC_PROV[LINEA]=$B$2)*(DESC_PROV[LISTA]=$C$2),DESC_PROV[DESCUENTO])) *(1+VLOOKUP($C$2,LISTAS[],2,FALSE)) *(1+VLOOKUP($C$2,LISTAS[],3,FALSE)) ) /5,0)*5,0)} -> 90210
A13: 100x40 | B13: 42983 | C13: 6923 | D13: 8389 | E13: 11068 | F13: 23937 | G13: 9267 | H13: 35838 | K13: 100x40 | L13: {=IFERROR( ROUND( IF($A$2="COSTO", ((B13*(1+IFERROR(VLOOKUP($D$2,COLORES[],2,FALSE),0)))+C13) *(1-_xlfn.XLOOKUP(1,(DESC_PROV[LINEA]=$B$2)*(DESC_PROV[LISTA]=$C$2),DESC_PROV[DESCUENTO])), ((B13*(1+IFERROR(VLOOKUP($D$2,COLORES[],2,FALSE),0)))+C13) *(1-_xlfn.XLOOKUP(1,(DESC_PROV[LINEA]=$B$2)*(DESC_PROV[LISTA]=$C$2),DESC_PROV[DESCUENTO])) *(1+VLOOKUP($C$2,LISTAS[],2,FALSE)) *(1+VLOOKUP($C$2,LISTAS[],3,FALSE)) ) /5,0)*5,0)} -> 61895 | M13: {=IFERROR( ROUND( IF($A$2="COSTO", ((B13*(1+IFERROR(VLOOKUP($D$2,COLORES[],2,FALSE),0)))+D13) *(1-_xlfn.XLOOKUP(1,(DESC_PROV[LINEA]=$B$2)*(DESC_PROV[LISTA]=$C$2),DESC_PROV[DESCUENTO])), ((B13*(1+IFERROR(VLOOKUP($D$2,COLORES[],2,FALSE),0)))+D13) *(1-_xlfn.XLOOKUP(1,(DESC_PROV[LINEA]=$B$2)*(DESC_PROV[LISTA]=$C$2),DESC_PROV[DESCUENTO])) *(1+VLOOKUP($C$2,LISTAS[],2,FALSE)) *(1+VLOOKUP($C$2,LISTAS[],3,FALSE)) ) /5,0)*5,0)} -> 63710 | N13: {=IFERROR( ROUND( IF($A$2="COSTO", ((B13*(1+IFERROR(VLOOKUP($D$2,COLORES[],2,FALSE),0)))+E13) *(1-_xlfn.XLOOKUP(1,(DESC_PROV[LINEA]=$B$2)*(DESC_PROV[LISTA]=$C$2),DESC_PROV[DESCUENTO])), ((B13*(1+IFERROR(VLOOKUP($D$2,COLORES[],2,FALSE),0)))+E13) *(1-_xlfn.XLOOKUP(1,(DESC_PROV[LINEA]=$B$2)*(DESC_PROV[LISTA]=$C$2),DESC_PROV[DESCUENTO])) *(1+VLOOKUP($C$2,LISTAS[],2,FALSE)) *(1+VLOOKUP($C$2,LISTAS[],3,FALSE)) ) /5,0)*5,0)} -> 67035 | O13: {=IFERROR( ROUND( IF($A$2="COSTO", ((B13*(1+IFERROR(VLOOKUP($D$2,COLORES[],2,FALSE),0)))+F13) *(1-_xlfn.XLOOKUP(1,(DESC_PROV[LINEA]=$B$2)*(DESC_PROV[LISTA]=$C$2),DESC_PROV[DESCUENTO])), ((B13*(1+IFERROR(VLOOKUP($D$2,COLORES[],2,FALSE),0)))+F13) *(1-_xlfn.XLOOKUP(1,(DESC_PROV[LINEA]=$B$2)*(DESC_PROV[LISTA]=$C$2),DESC_PROV[DESCUENTO])) *(1+VLOOKUP($C$2,LISTAS[],2,FALSE)) *(1+VLOOKUP($C$2,LISTAS[],3,FALSE)) ) /5,0)*5,0)} -> 82995 | P13: {=IFERROR( ROUND( IF($A$2="COSTO", ((B13*(1+IFERROR(VLOOKUP($D$2,COLORES[],2,FALSE),0)))+G13) *(1-_xlfn.XLOOKUP(1,(DESC_PROV[LINEA]=$B$2)*(DESC_PROV[LISTA]=$C$2),DESC_PROV[DESCUENTO])), ((B13*(1+IFERROR(VLOOKUP($D$2,COLORES[],2,FALSE),0)))+G13) *(1-_xlfn.XLOOKUP(1,(DESC_PROV[LINEA]=$B$2)*(DESC_PROV[LISTA]=$C$2),DESC_PROV[DESCUENTO])) *(1+VLOOKUP($C$2,LISTAS[],2,FALSE)) *(1+VLOOKUP($C$2,LISTAS[],3,FALSE)) ) /5,0)*5,0)} -> 64800 | Q13: {=IFERROR( ROUND( IF($A$2="COSTO", ((B13*(1+IFERROR(VLOOKUP($D$2,COLORES[],2,FALSE),0)))+H13) *(1-_xlfn.XLOOKUP(1,(DESC_PROV[LINEA]=$B$2)*(DESC_PROV[LISTA]=$C$2),DESC_PROV[DESCUENTO])), ((B13*(1+IFERROR(VLOOKUP($D$2,COLORES[],2,FALSE),0)))+H13) *(1-_xlfn.XLOOKUP(1,(DESC_PROV[LINEA]=$B$2)*(DESC_PROV[LISTA]=$C$2),DESC_PROV[DESCUENTO])) *(1+VLOOKUP($C$2,LISTAS[],2,FALSE)) *(1+VLOOKUP($C$2,LISTAS[],3,FALSE)) ) /5,0)*5,0)} -> 97755
A14: 40x50 | B14: 32505 | C14: 3077 | D14: 3729 | E14: 4914 | F14: 10634 | G14: 4109 | H14: 15910 | K14: 40x50 | L14: {=IFERROR( ROUND( IF($A$2="COSTO", ((B14*(1+IFERROR(VLOOKUP($D$2,COLORES[],2,FALSE),0)))+C14) *(1-_xlfn.XLOOKUP(1,(DESC_PROV[LINEA]=$B$2)*(DESC_PROV[LISTA]=$C$2),DESC_PROV[DESCUENTO])), ((B14*(1+IFERROR(VLOOKUP($D$2,COLORES[],2,FALSE),0)))+C14) *(1-_xlfn.XLOOKUP(1,(DESC_PROV[LINEA]=$B$2)*(DESC_PROV[LISTA]=$C$2),DESC_PROV[DESCUENTO])) *(1+VLOOKUP($C$2,LISTAS[],2,FALSE)) *(1+VLOOKUP($C$2,LISTAS[],3,FALSE)) ) /5,0)*5,0)} -> 44130 | M14: {=IFERROR( ROUND( IF($A$2="COSTO", ((B14*(1+IFERROR(VLOOKUP($D$2,COLORES[],2,FALSE),0)))+D14) *(1-_xlfn.XLOOKUP(1,(DESC_PROV[LINEA]=$B$2)*(DESC_PROV[LISTA]=$C$2),DESC_PROV[DESCUENTO])), ((B14*(1+IFERROR(VLOOKUP($D$2,COLORES[],2,FALSE),0)))+D14) *(1-_xlfn.XLOOKUP(1,(DESC_PROV[LINEA]=$B$2)*(DESC_PROV[LISTA]=$C$2),DESC_PROV[DESCUENTO])) *(1+VLOOKUP($C$2,LISTAS[],2,FALSE)) *(1+VLOOKUP($C$2,LISTAS[],3,FALSE)) ) /5,0)*5,0)} -> 44935 | N14: {=IFERROR( ROUND( IF($A$2="COSTO", ((B14*(1+IFERROR(VLOOKUP($D$2,COLORES[],2,FALSE),0)))+E14) *(1-_xlfn.XLOOKUP(1,(DESC_PROV[LINEA]=$B$2)*(DESC_PROV[LISTA]=$C$2),DESC_PROV[DESCUENTO])), ((B14*(1+IFERROR(VLOOKUP($D$2,COLORES[],2,FALSE),0)))+E14) *(1-_xlfn.XLOOKUP(1,(DESC_PROV[LINEA]=$B$2)*(DESC_PROV[LISTA]=$C$2),DESC_PROV[DESCUENTO])) *(1+VLOOKUP($C$2,LISTAS[],2,FALSE)) *(1+VLOOKUP($C$2,LISTAS[],3,FALSE)) ) /5,0)*5,0)} -> 46405 | O14: {=IFERROR( ROUND( IF($A$2="COSTO", ((B14*(1+IFERROR(VLOOKUP($D$2,COLORES[],2,FALSE),0)))+F14) *(1-_xlfn.XLOOKUP(1,(DESC_PROV[LINEA]=$B$2)*(DESC_PROV[LISTA]=$C$2),DESC_PROV[DESCUENTO])), ((B14*(1+IFERROR(VLOOKUP($D$2,COLORES[],2,FALSE),0)))+F14) *(1-_xlfn.XLOOKUP(1,(DESC_PROV[LINEA]=$B$2)*(DESC_PROV[LISTA]=$C$2),DESC_PROV[DESCUENTO])) *(1+VLOOKUP($C$2,LISTAS[],2,FALSE)) *(1+VLOOKUP($C$2,LISTAS[],3,FALSE)) ) /5,0)*5,0)} -> 53500 | P14: {=IFERROR( ROUND( IF($A$2="COSTO", ((B14*(1+IFERROR(VLOOKUP($D$2,COLORES[],2,FALSE),0)))+G14) *(1-_xlfn.XLOOKUP(1,(DESC_PROV[LINEA]=$B$2)*(DESC_PROV[LISTA]=$C$2),DESC_PROV[DESCUENTO])), ((B14*(1+IFERROR(VLOOKUP($D$2,COLORES[],2,FALSE),0)))+G14) *(1-_xlfn.XLOOKUP(1,(DESC_PROV[LINEA]=$B$2)*(DESC_PROV[LISTA]=$C$2),DESC_PROV[DESCUENTO])) *(1+VLOOKUP($C$2,LISTAS[],2,FALSE)) *(1+VLOOKUP($C$2,LISTAS[],3,FALSE)) ) /5,0)*5,0)} -> 45410 | Q14: {=IFERROR( ROUND( IF($A$2="COSTO", ((B14*(1+IFERROR(VLOOKUP($D$2,COLORES[],2,FALSE),0)))+H14) *(1-_xlfn.XLOOKUP(1,(DESC_PROV[LINEA]=$B$2)*(DESC_PROV[LISTA]=$C$2),DESC_PROV[DESCUENTO])), ((B14*(1+IFERROR(VLOOKUP($D$2,COLORES[],2,FALSE),0)))+H14) *(1-_xlfn.XLOOKUP(1,(DESC_PROV[LINEA]=$B$2)*(DESC_PROV[LISTA]=$C$2),DESC_PROV[DESCUENTO])) *(1+VLOOKUP($C$2,LISTAS[],2,FALSE)) *(1+VLOOKUP($C$2,LISTAS[],3,FALSE)) ) /5,0)*5,0)} -> 60045
A15: 50x50 | B15: 34605 | C15: 4109 | D15: 4968 | E15: 6561 | F15: 14172 | G15: 5475 | H15: 21210 | K15: 50x50 | L15: {=IFERROR( ROUND( IF($A$2="COSTO", ((B15*(1+IFERROR(VLOOKUP($D$2,COLORES[],2,FALSE),0)))+C15) *(1-_xlfn.XLOOKUP(1,(DESC_PROV[LINEA]=$B$2)*(DESC_PROV[LISTA]=$C$2),DESC_PROV[DESCUENTO])), ((B15*(1+IFERROR(VLOOKUP($D$2,COLORES[],2,FALSE),0)))+C15) *(1-_xlfn.XLOOKUP(1,(DESC_PROV[LINEA]=$B$2)*(DESC_PROV[LISTA]=$C$2),DESC_PROV[DESCUENTO])) *(1+VLOOKUP($C$2,LISTAS[],2,FALSE)) *(1+VLOOKUP($C$2,LISTAS[],3,FALSE)) ) /5,0)*5,0)} -> 48015 | M15: {=IFERROR( ROUND( IF($A$2="COSTO", ((B15*(1+IFERROR(VLOOKUP($D$2,COLORES[],2,FALSE),0)))+D15) *(1-_xlfn.XLOOKUP(1,(DESC_PROV[LINEA]=$B$2)*(DESC_PROV[LISTA]=$C$2),DESC_PROV[DESCUENTO])), ((B15*(1+IFERROR(VLOOKUP($D$2,COLORES[],2,FALSE),0)))+D15) *(1-_xlfn.XLOOKUP(1,(DESC_PROV[LINEA]=$B$2)*(DESC_PROV[LISTA]=$C$2),DESC_PROV[DESCUENTO])) *(1+VLOOKUP($C$2,LISTAS[],2,FALSE)) *(1+VLOOKUP($C$2,LISTAS[],3,FALSE)) ) /5,0)*5,0)} -> 49080 | N15: {=IFERROR( ROUND( IF($A$2="COSTO", ((B15*(1+IFERROR(VLOOKUP($D$2,COLORES[],2,FALSE),0)))+E15) *(1-_xlfn.XLOOKUP(1,(DESC_PROV[LINEA]=$B$2)*(DESC_PROV[LISTA]=$C$2),DESC_PROV[DESCUENTO])), ((B15*(1+IFERROR(VLOOKUP($D$2,COLORES[],2,FALSE),0)))+E15) *(1-_xlfn.XLOOKUP(1,(DESC_PROV[LINEA]=$B$2)*(DESC_PROV[LISTA]=$C$2),DESC_PROV[DESCUENTO])) *(1+VLOOKUP($C$2,LISTAS[],2,FALSE)) *(1+VLOOKUP($C$2,LISTAS[],3,FALSE)) ) /5,0)*5,0)} -> 51055 | O15: {=IFERROR( ROUND( IF($A$2="COSTO", ((B15*(1+IFERROR(VLOOKUP($D$2,COLORES[],2,FALSE),0)))+F15) *(1-_xlfn.XLOOKUP(1,(DESC_PROV[LINEA]=$B$2)*(DESC_PROV[LISTA]=$C$2),DESC_PROV[DESCUENTO])), ((B15*(1+IFERROR(VLOOKUP($D$2,COLORES[],2,FALSE),0)))+F15) *(1-_xlfn.XLOOKUP(1,(DESC_PROV[LINEA]=$B$2)*(DESC_PROV[LISTA]=$C$2),DESC_PROV[DESCUENTO])) *(1+VLOOKUP($C$2,LISTAS[],2,FALSE)) *(1+VLOOKUP($C$2,LISTAS[],3,FALSE)) ) /5,0)*5,0)} -> 60495 | P15: {=IFERROR( ROUND( IF($A$2="COSTO", ((B15*(1+IFERROR(VLOOKUP($D$2,COLORES[],2,FALSE),0)))+G15) *(1-_xlfn.XLOOKUP(1,(DESC_PROV[LINEA]=$B$2)*(DESC_PROV[LISTA]=$C$2),DESC_PROV[DESCUENTO])), ((B15*(1+IFERROR(VLOOKUP($D$2,COLORES[],2,FALSE),0)))+G15) *(1-_xlfn.XLOOKUP(1,(DESC_PROV[LINEA]=$B$2)*(DESC_PROV[LISTA]=$C$2),DESC_PROV[DESCUENTO])) *(1+VLOOKUP($C$2,LISTAS[],2,FALSE)) *(1+VLOOKUP($C$2,LISTAS[],3,FALSE)) ) /5,0)*5,0)} -> 49705 | Q15: {=IFERROR( ROUND( IF($A$2="COSTO", ((B15*(1+IFERROR(VLOOKUP($D$2,COLORES[],2,FALSE),0)))+H15) *(1-_xlfn.XLOOKUP(1,(DESC_PROV[LINEA]=$B$2)*(DESC_PROV[LISTA]=$C$2),DESC_PROV[DESCUENTO])), ((B15*(1+IFERROR(VLOOKUP($D$2,COLORES[],2,FALSE),0)))+H15) *(1-_xlfn.XLOOKUP(1,(DESC_PROV[LINEA]=$B$2)*(DESC_PROV[LISTA]=$C$2),DESC_PROV[DESCUENTO])) *(1+VLOOKUP($C$2,LISTAS[],2,FALSE)) *(1+VLOOKUP($C$2,LISTAS[],3,FALSE)) ) /5,0)*5,0)} -> 69220
