Workbook

Sheet CONTROL
B3: MODO | C3: LISTA | D3: COLOR
B4: VENTA | C4: AMARILLA | D4: BLANCO

Sheet CONFIG
A1: Lista | B1: Flete | C1: Ganancia | D1: Mosq | E1: Repartido | F1: Cobra | G1: Extra | J1: LISTAS | K1: COLORES | L1: LINEAS
A2: AMARILLA | B2: 0.06 | C2: 0.3 | D2: 0.6 | E2: 0.3 | F2: 0 | G2: 0.1 | J2: AMARILLA | K2: NEGRO | L2: HERRERO
A3: AZUL | B3: 0.1 | C3: 0.3 | D3: 0.6 | E3: 0.3 | F3: 0 | G3: 0.1 | J3: AZUL | K3: BLANCO | L3: MODENA
A4: VERDE | B4: 0.15 | C4: 0.35 | D4: 0.6 | E4: 0.3 | F4: 0 | G4: 0.1 | J4: VERDE | K4: BRONCE
A5: EMA | B5: 0.15 | C5: 0.4 | D5: 0.6 | E5: 0.3 | F5: 0 | G5: 0.1 | J5: EMA | K5: SIMIL MADERA
A6: GUILLE | B6: 0 | C6: 0.5 | D6: 0.6 | E6: 0 | F6: 0.242 | G6: 0.1 | J6: GUILLE
A9: COLOR | B9: % | D9: LINEA | F9: ANCHO_PUERTAS | H9: TIPO | I9: FACTOR
A10: NEGRO | B10: 0.3 | D10: HERRERO | F10: 0.8 | H10: CORREDIZO | I10: 1
A11: BLANCO | B11: 0 | D11: MODENA | F11: 0.7 | H11: ABRIR | I11: 1.05
A12: BRONCE | B12: 0.45 | F12: 0.9
A13: SIMIL MADERA | B13: 2.8
A18: LINEA | B18: LISTA | C18: DESCUENTO
A19: HERRERO | B19: AMARILLA | C19: 0.1
A20: HERRERO | B20: AZUL | C20: 0.12
A21: HERRERO | B21: VERDE | C21: 0.12
A22: MODENA | B22: AMARILLA | C22: 0.07
A23: MODENA | B23: AZUL | C23: 0.07
A24: MODENA | B24: VERDE | C24: 0.07
A31: TIPO | B31: FLETE | C31: GANANCIA | E31: PARAMETRO | F31: VALOR
A32: PVC | B32: 0.15 | C32: 0.4 | E32: DESCUENTO_GENERAL | F32: 0.05

Sheet ventana herrero
A1: MODO | B1: LINEA | C1: LISTA | D1: COLOR
A2: =CONTROL!B4 -> VENTA | B2: HERRERO | C2: =CONTROL!C4 -> AMARILLA | D2: =CONTROL!D4 -> BLANCO
A4: VENTANA HERRERO PAPU | G4: VENTANAS HERRERO VENTA
A6: medidas | B6: sin_vidrio | C6: guia | D6: mosquitero | E6: vidrio | G6: medidas | H6: vidrio_entero | I6: guia | J6: mosquitero | K6: vidrio rep
A7: 60x0,40 | B7: 25119 | C7: 6884 | D7: 9262 | E7: 2556 | G7: 60x0,40 | H7: =IFERROR( ROUND( IF($A$2="COSTO", ((B7*(1+IFERROR(VLOOKUP($D$2,COLORES[],2,FALSE),0)))+E7) *(1-SUMPRODUCT( (DESC_PROV[LINEA]=$B$2)* (DESC_PROV[LISTA]=$C$2)* (DESC_PROV[DESCUENTO]) )), ((B7*(1+IFERROR(VLOOKUP($D$2,COLORES[],2,FALSE),0)))+E7) *(1-SUMPRODUCT( (DESC_PROV[LINEA]=$B$2)* (DESC_PROV[LISTA]=$C$2)* (DESC_PROV[DESCUENTO]) )) *(1+VLOOKUP($C$2,LISTAS[],2,FALSE)) *(1+0.1) ) /5,0)*5,0) -> 29040 | I7: =IFERROR( ROUND( IF($A$2="COSTO", ((B7*(1+IFERROR(VLOOKUP($D$2,COLORES[],2,FALSE),0)))+C7) *(1-SUMPRODUCT( (DESC_PROV[LINEA]=$B$2)* (DESC_PROV[LISTA]=$C$2)* (DESC_PROV[DESCUENTO]) )), ((B7*(1+IFERROR(VLOOKUP($D$2,COLORES[],2,FALSE),0)))+C7) *(1-SUMPRODUCT( (DESC_PROV[LINEA]=$B$2)* (DESC_PROV[LISTA]=$C$2)* (DESC_PROV[DESCUENTO]) )) *(1+VLOOKUP($C$2,LISTAS[],2,FALSE)) *(1+0.1) ) /5,0)*5,0) -> 33585 | J7: =IFERROR( ROUND( IF($A$2="COSTO", (D7*(1+IFERROR(VLOOKUP($D$2,COLORES[],2,FALSE),0))) *(1-SUMPRODUCT( (DESC_PROV[LINEA]=$B$2)* (DESC_PROV[LISTA]=$C$2)* (DESC_PROV[DESCUENTO]) )), (D7*(1+IFERROR(VLOOKUP($D$2,COLORES[],2,FALSE),0))) *(1-SUMPRODUCT( (DESC_PROV[LINEA]=$B$2)* (DESC_PROV[LISTA]=$C$2)* (DESC_PROV[DESCUENTO]) )) *(1+VLOOKUP($C$2,LISTAS[],2,FALSE)) *(1+0.1) ) /5,0)*5,0) -> 9720 | K7: =IFERROR( ROUND( IF($A$2="COSTO", ((B7*(1+IFERROR(VLOOKUP($D$2,COLORES[],2,FALSE),0)))+C7+E7) *(1-SUMPRODUCT( (DESC_PROV[LINEA]=$B$2)* (DESC_PROV[LISTA]=$C$2)* (DESC_PROV[DESCUENTO]) )), ((B7*(1+IFERROR(VLOOKUP($D$2,COLORES[],2,FALSE),0)))+C7+E7) *(1-SUMPRODUCT( (DESC_PROV[LINEA]=$B$2)* (DESC_PROV[LISTA]=$C$2)* (DESC_PROV[DESCUENTO]) )) *(1+VLOOKUP($C$2,LISTAS[],2,FALSE)) *(1+0.1) ) /5,0)*5,0) -> 36265
A8: 80x0,40 | B8: 30829 | C8: 6884 | D8: 10394 | E8: 3570 | G8: 80x0,40 | H8: =IFERROR( ROUND( IF($A$2="COSTO", ((B8*(1+IFERROR(VLOOKUP($D$2,COLORES[],2,FALSE),0)))+E8) *(1-SUMPRODUCT( (DESC_PROV[LINEA]=$B$2)* (DESC_PROV[LISTA]=$C$2)* (DESC_PROV[DESCUENTO]) )), ((B8*(1+IFERROR(VLOOKUP($D$2,COLORES[],2,FALSE),0)))+E8) *(1-SUMPRODUCT( (DESC_PROV[LINEA]=$B$2)* (DESC_PROV[LISTA]=$C$2)* (DESC_PROV[DESCUENTO]) )) *(1+VLOOKUP($C$2,LISTAS[],2,FALSE)) *(1+VLOOKUP($C$2,LISTAS[],3,FALSE)) ) /5,0)*5,0) -> 42660 | I8: =IFERROR( ROUND( IF($A$2="COSTO", ((B8*(1+IFERROR(VLOOKUP($D$2,COLORES[],2,FALSE),0))) + C8 + E8) *(1-SUMPRODUCT( (DESC_PROV[LINEA]=$B$2)* (DESC_PROV[LISTA]=$C$2)* (DESC_PROV[DESCUENTO]) )), ((B8*(1+IFERROR(VLOOKUP($D$2,COLORES[],2,FALSE),0))) + C8 + E8) *(1-SUMPRODUCT( (DESC_PROV[LINEA]=$B$2)* (DESC_PROV[LISTA]=$C$2)* (DESC_PROV[DESCUENTO]) )) *(1+VLOOKUP($C$2,LISTAS[],2,FALSE)) *(1+VLOOKUP($C$2,LISTAS[],3,FALSE)) ) /5,0)*5,0) -> 51200 | J8: =IFERROR( ROUND( IF($A$2="COSTO", (D8*(1+IFERROR(VLOOKUP($D$2,COLORES[],2,FALSE),0))) *(1-SUMPRODUCT( (DESC_PROV[LINEA]=$B$2)* (DESC_PROV[LISTA]=$C$2)* (DESC_PROV[DESCUENTO]) )), (D8*(1+IFERROR(VLOOKUP($D$2,COLORES[],2,FALSE),0))) *(1-SUMPRODUCT( (DESC_PROV[LINEA]=$B$2)* (DESC_PROV[LISTA]=$C$2)* (DESC_PROV[DESCUENTO]) )) *(1+VLOOKUP($C$2,LISTAS[],2,FALSE)) *(1+VLOOKUP($C$2,LISTAS[],4,FALSE)) ) /5,0)*5,0) -> 15865 | K8: =IFERROR( ROUND( IF($A$2="COSTO", (B8*(1+IFERROR(VLOOKUP($D$2,COLORES[],2,FALSE),0))+E8) *(1+VLOOKUP($C$2,LISTAS[],5,FALSE)) *(1-SUMPRODUCT( (DESC_PROV[LINEA]=$B$2)* (DESC_PROV[LISTA]=$C$2)* (DESC_PROV[DESCUENTO]) )), (B8*(1+IFERROR(VLOOKUP($D$2,COLORES[],2,FALSE),0))+E8) *(1-SUMPRODUCT( (DESC_PROV[LINEA]=$B$2)* (DESC_PROV[LISTA]=$C$2)* (DESC_PROV[DESCUENTO]) )) *(1+VLOOKUP($C$2,LISTAS[],5,FALSE)) *(1+VLOOKUP($C$2,LISTAS[],2,FALSE)) *(1+VLOOKUP($C$2,LISTAS[],3,FALSE)) ) /5,0)*5,0) -> 55460
A9: 100x0,40 | B9: 33195 | C9: 6884 | D9: 11917 | E9: 4590 | G9: 100x0,40 | H9: =IFERROR( ROUND( IF($A$2="COSTO", ((B9*(1+IFERROR(VLOOKUP($D$2,COLORES[],2,FALSE),0)))+E9) *(1-SUMPRODUCT( (DESC_PROV[LINEA]=$B$2)* (DESC_PROV[LISTA]=$C$2)* (DESC_PROV[DESCUENTO]) )), ((B9*(1+IFERROR(VLOOKUP($D$2,COLORES[],2,FALSE),0)))+E9) *(1-SUMPRODUCT( (DESC_PROV[LINEA]=$B$2)* (DESC_PROV[LISTA]=$C$2)* (DESC_PROV[DESCUENTO]) )) *(1+VLOOKUP($C$2,LISTAS[],2,FALSE)) *(1+VLOOKUP($C$2,LISTAS[],3,FALSE)) ) /5,0)*5,0) -> 46860 | I9: =IFERROR( ROUND( IF($A$2="COSTO", ((B9*(1+IFERROR(VLOOKUP($D$2,COLORES[],2,FALSE),0))) + C9 + E9) *(1-SUMPRODUCT( (DESC_PROV[LINEA]=$B$2)* (DESC_PROV[LISTA]=$C$2)* (DESC_PROV[DESCUENTO]) )), ((B9*(1+IFERROR(VLOOKUP($D$2,COLORES[],2,FALSE),0))) + C9 + E9) *(1-SUMPRODUCT( (DESC_PROV[LINEA]=$B$2)* (DESC_PROV[LISTA]=$C$2)* (DESC_PROV[DESCUENTO]) )) *(1+VLOOKUP($C$2,LISTAS[],2,FALSE)) *(1+VLOOKUP($C$2,LISTAS[],3,FALSE)) ) /5,0)*5,0) -> 55400 | J9: =IFERROR( ROUND( IF($A$2="COSTO", (D9*(1+IFERROR(VLOOKUP($D$2,COLORES[],2,FALSE),0))) *(1-SUMPRODUCT( (DESC_PROV[LINEA]=$B$2)* (DESC_PROV[LISTA]=$C$2)* (DESC_PROV[DESCUENTO]) )), (D9*(1+IFERROR(VLOOKUP($D$2,COLORES[],2,FALSE),0))) *(1-SUMPRODUCT( (DESC_PROV[LINEA]=$B$2)* (DESC_PROV[LISTA]=$C$2)* (DESC_PROV[DESCUENTO]) )) *(1+VLOOKUP($C$2,LISTAS[],2,FALSE)) *(1+VLOOKUP($C$2,LISTAS[],4,FALSE)) ) /5,0)*5,0) -> 18190 | K9: =IFERROR( ROUND( IF($A$2="COSTO", (B9*(1+IFERROR(VLOOKUP($D$2,COLORES[],2,FALSE),0))+E9) *(1+VLOOKUP($C$2,LISTAS[],5,FALSE)) *(1-SUMPRODUCT( (DESC_PROV[LINEA]=$B$2)* (DESC_PROV[LISTA]=$C$2)* (DESC_PROV[DESCUENTO]) )), (B9*(1+IFERROR(VLOOKUP($D$2,COLORES[],2,FALSE),0))+E9) *(1-SUMPRODUCT( (DESC_PROV[LINEA]=$B$2)* (DESC_PROV[LISTA]=$C$2)* (DESC_PROV[DESCUENTO]) )) *(1+VLOOKUP($C$2,LISTAS[],5,FALSE)) *(1+VLOOKUP($C$2,LISTAS[],2,FALSE)) *(1+VLOOKUP($C$2,LISTAS[],3,FALSE)) ) /5,0)*5,0) -> 60920
A10: 120x0,40 | B10: 36677 | C10: 6884 | D10: 13440 | E10: 5622 | G10: 120x0,40 | H10: =IFERROR( ROUND( IF($A$2="COSTO", ((B10*(1+IFERROR(VLOOKUP($D$2,COLORES[],2,FALSE),0)))+E10) *(1-SUMPRODUCT( (DESC_PROV[LINEA]=$B$2)* (DESC_PROV[LISTA]=$C$2)* (DESC_PROV[DESCUENTO]) )), ((B10*(1+IFERROR(VLOOKUP($D$2,COLORES[],2,FALSE),0)))+E10) *(1-SUMPRODUCT( (DESC_PROV[LINEA]=$B$2)* (DESC_PROV[LISTA]=$C$2)* (DESC_PROV[DESCUENTO]) )) *(1+VLOOKUP($C$2,LISTAS[],2,FALSE)) *(1+VLOOKUP($C$2,LISTAS[],3,FALSE)) ) /5,0)*5,0) -> 52460 | I10: =IFERROR( ROUND( IF($A$2="COSTO", ((B10*(1+IFERROR(VLOOKUP($D$2,COLORES[],2,FALSE),0))) + C10 + E10) *(1-SUMPRODUCT( (DESC_PROV[LINEA]=$B$2)* (DESC_PROV[LISTA]=$C$2)* (DESC_PROV[DESCUENTO]) )), ((B10*(1+IFERROR(VLOOKUP($D$2,COLORES[],2,FALSE),0))) + C10 + E10) *(1-SUMPRODUCT( (DESC_PROV[LINEA]=$B$2)* (DESC_PROV[LISTA]=$C$2)* (DESC_PROV[DESCUENTO]) )) *(1+VLOOKUP($C$2,LISTAS[],2,FALSE)) *(1+VLOOKUP($C$2,LISTAS[],3,FALSE)) ) /5,0)*5,0) -> 60995 | J10: =IFERROR( ROUND( IF($A$2="COSTO", (D10*(1+IFERROR(VLOOKUP($D$2,COLORES[],2,FALSE),0))) *(1-SUMPRODUCT( (DESC_PROV[LINEA]=$B$2)* (DESC_PROV[LISTA]=$C$2)* (DESC_PROV[DESCUENTO]) )), (D10*(1+IFERROR(VLOOKUP($D$2,COLORES[],2,FALSE),0))) *(1-SUMPRODUCT( (DESC_PROV[LINEA]=$B$2)* (DESC_PROV[LISTA]=$C$2)* (DESC_PROV[DESCUENTO]) )) *(1+VLOOKUP($C$2,LISTAS[],2,FALSE)) *(1+VLOOKUP($C$2,LISTAS[],4,FALSE)) ) /5,0)*5,0) -> 20515 | K10: =IFERROR( ROUND( IF($A$2="COSTO", (B10*(1+IFERROR(VLOOKUP($D$2,COLORES[],2,FALSE),0))+E10) *(1+VLOOKUP($C$2,LISTAS[],5,FALSE)) *(1-SUMPRODUCT( (DESC_PROV[LINEA]=$B$2)* (DESC_PROV[LISTA]=$C$2)* (DESC_PROV[DESCUENTO]) )), (B10*(1+IFERROR(VLOOKUP($D$2,COLORES[],2,FALSE),0))+E10) *(1-SUMPRODUCT( (DESC_PROV[LINEA]=$B$2)* (DESC_PROV[LISTA]=$C$2)* (DESC_PROV[DESCUENTO]) )) *(1+VLOOKUP($C$2,LISTAS[],5,FALSE)) *(1+VLOOKUP($C$2,LISTAS[],2,FALSE)) *(1+VLOOKUP($C$2,LISTAS[],3,FALSE)) ) /5,0)*5,0) -> 68195
A11: 150x0,40 | B11: 42456 | C11: 6884 | D11: 15725 | E11: 7140 | G11: 150x0,40 | H11: =IFERROR( ROUND( IF($A$2="COSTO", ((B11*(1+IFERROR(VLOOKUP($D$2,COLORES[],2,FALSE),0)))+E11) *(1-SUMPRODUCT( (DESC_PROV[LINEA]=$B$2)* (DESC_PROV[LISTA]=$C$2)* (DESC_PROV[DESCUENTO]) )), ((B11*(1+IFERROR(VLOOKUP($D$2,COLORES[],2,FALSE),0)))+E11) *(1-SUMPRODUCT( (DESC_PROV[LINEA]=$B$2)* (DESC_PROV[LISTA]=$C$2)* (DESC_PROV[DESCUENTO]) )) *(1+VLOOKUP($C$2,LISTAS[],2,FALSE)) *(1+VLOOKUP($C$2,LISTAS[],3,FALSE)) ) /5,0)*5,0) -> 61510 | I11: =IFERROR( ROUND( IF($A$2="COSTO", ((B11*(1+IFERROR(VLOOKUP($D$2,COLORES[],2,FALSE),0))) + C11 + E11) *(1-SUMPRODUCT( (DESC_PROV[LINEA]=$B$2)* (DESC_PROV[LISTA]=$C$2)* (DESC_PROV[DESCUENTO]) )), ((B11*(1+IFERROR(VLOOKUP($D$2,COLORES[],2,FALSE),0))) + C11 + E11) *(1-SUMPRODUCT( (DESC_PROV[LINEA]=$B$2)* (DESC_PROV[LISTA]=$C$2)* (DESC_PROV[DESCUENTO]) )) *(1+VLOOKUP($C$2,LISTAS[],2,FALSE)) *(1+VLOOKUP($C$2,LISTAS[],3,FALSE)) ) /5,0)*5,0) -> 70045 | J11: =IFERROR( ROUND( IF($A$2="COSTO", (D11*(1+IFERROR(VLOOKUP($D$2,COLORES[],2,FALSE),0))) *(1-SUMPRODUCT( (DESC_PROV[LINEA]=$B$2)* (DESC_PROV[LISTA]=$C$2)* (DESC_PROV[DESCUENTO]) )), (D11*(1+IFERROR(VLOOKUP($D$2,COLORES[],2,FALSE),0))) *(1-SUMPRODUCT( (DESC_PROV[LINEA]=$B$2)* (DESC_PROV[LISTA]=$C$2)* (DESC_PROV[DESCUENTO]) )) *(1+VLOOKUP($C$2,LISTAS[],2,FALSE)) *(1+VLOOKUP($C$2,LISTAS[],4,FALSE)) ) /5,0)*5,0) -> 24005 | K11: =IFERROR( ROUND( IF($A$2="COSTO", (B11*(1+IFERROR(VLOOKUP($D$2,COLORES[],2,FALSE),0))+E11) *(1+VLOOKUP($C$2,LISTAS[],5,FALSE)) *(1-SUMPRODUCT( (DESC_PROV[LINEA]=$B$2)* (DESC_PROV[LISTA]=$C$2)* (DESC_PROV[DESCUENTO]) )), (B11*(1+IFERROR(VLOOKUP($D$2,COLORES[],2,FALSE),0))+E11) *(1-SUMPRODUCT( (DESC_PROV[LINEA]=$B$2)* (DESC_PROV[LISTA]=$C$2)* (DESC_PROV[DESCUENTO]) )) *(1+VLOOKUP($C$2,LISTAS[],5,FALSE)) *(1+VLOOKUP($C$2,LISTAS[],2,FALSE)) *(1+VLOOKUP($C$2,LISTAS[],3,FALSE)) ) /5,0)*5,0) -> 79960
A12: 180x0,40 | B12: 47121 | C12: 6884 | D12: 18010 | E12: 8676 | G12: 180x0,40 | H12: =IFERROR( ROUND( IF($A$2="COSTO", ((B12*(1+IFERROR(VLOOKUP($D$2,COLORES[],2,FALSE),0)))+E12) *(1-SUMPRODUCT( (DESC_PROV[LINEA]=$B$2)* (DESC_PROV[LISTA]=$C$2)* (DESC_PROV[DESCUENTO]) )), ((B12*(1+IFERROR(VLOOKUP($D$2,COLORES[],2,FALSE),0)))+E12) *(1-SUMPRODUCT( (DESC_PROV[LINEA]=$B$2)* (DESC_PROV[LISTA]=$C$2)* (DESC_PROV[DESCUENTO]) )) *(1+VLOOKUP($C$2,LISTAS[],2,FALSE)) *(1+VLOOKUP($C$2,LISTAS[],3,FALSE)) ) /5,0)*5,0) -> 69200 | I12: =IFERROR( ROUND( IF($A$2="COSTO", ((B12*(1+IFERROR(VLOOKUP($D$2,COLORES[],2,FALSE),0))) + C12 + E12) *(1-SUMPRODUCT( (DESC_PROV[LINEA]=$B$2)* (DESC_PROV[LISTA]=$C$2)* (DESC_PROV[DESCUENTO]) )), ((B12*(1+IFERROR(VLOOKUP($D$2,COLORES[],2,FALSE),0))) + C12 + E12) *(1-SUMPRODUCT( (DESC_PROV[LINEA]=$B$2)* (DESC_PROV[LISTA]=$C$2)* (DESC_PROV[DESCUENTO]) )) *(1+VLOOKUP($C$2,LISTAS[],2,FALSE)) *(1+VLOOKUP($C$2,LISTAS[],3,FALSE)) ) /5,0)*5,0) -> 77735 | J12: =IFERROR( ROUND( IF($A$2="COSTO", (D12*(1+IFERROR(VLOOKUP($D$2,COLORES[],2,FALSE),0))) *(1-SUMPRODUCT( (DESC_PROV[LINEA]=$B$2)* (DESC_PROV[LISTA]=$C$2)* (DESC_PROV[DESCUENTO]) )), (D12*(1+IFERROR(VLOOKUP($D$2,COLORES[],2,FALSE),0))) *(1-SUMPRODUCT( (DESC_PROV[LINEA]=$B$2)* (DESC_PROV[LISTA]=$C$2)* (DESC_PROV[DESCUENTO]) )) *(1+VLOOKUP($C$2,LISTAS[],2,FALSE)) *(1+VLOOKUP($C$2,LISTAS[],4,FALSE)) ) /5,0)*5,0) -> 27490 | K12: =IFERROR( ROUND( IF($A$2="COSTO", (B12*(1+IFERROR(VLOOKUP($D$2,COLORES[],2,FALSE),0))+E12) *(1+VLOOKUP($C$2,LISTAS[],5,FALSE)) *(1-SUMPRODUCT( (DESC_PROV[LINEA]=$B$2)* (DESC_PROV[LISTA]=$C$2)* (DESC_PROV[DESCUENTO]) )), (B12*(1+IFERROR(VLOOKUP($D$2,COLORES[],2,FALSE),0))+E12) *(1-SUMPRODUCT( (DESC_PROV[LINEA]=$B$2)* (DESC_PROV[LISTA]=$C$2)* (DESC_PROV[DESCUENTO]) )) *(1+VLOOKUP($C$2,LISTAS[],5,FALSE)) *(1+VLOOKUP($C$2,LISTAS[],2,FALSE)) *(1+VLOOKUP($C$2,LISTAS[],3,FALSE)) ) /5,0)*5,0) -> 89960
A13: 200x0,40 | B13: 52273 | C13: 6884 | D13: 19533 | E13: 9696 | G13: 200x0,40 | H13: =IFERROR( ROUND( IF($A$2="COSTO", ((B13*(1+IFERROR(VLOOKUP($D$2,COLORES[],2,FALSE),0)))+E13) *(1-SUMPRODUCT( (DESC_PROV[LINEA]=$B$2)* (DESC_PROV[LISTA]=$C$2)* (DESC_PROV[DESCUENTO]) )), ((B13*(1+IFERROR(VLOOKUP($D$2,COLORES[],2,FALSE),0)))+E13) *(1-SUMPRODUCT( (DESC_PROV[LINEA]=$B$2)* (DESC_PROV[LISTA]=$C$2)* (DESC_PROV[DESCUENTO]) )) *(1+VLOOKUP($C$2,LISTAS[],2,FALSE)) *(1+VLOOKUP($C$2,LISTAS[],3,FALSE)) ) /5,0)*5,0) -> 76855 | I13: =IFERROR( ROUND( IF($A$2="COSTO", ((B13*(1+IFERROR(VLOOKUP($D$2,COLORES[],2,FALSE),0))) + C13 + E13) *(1-SUMPRODUCT( (DESC_PROV[LINEA]=$B$2)* (DESC_PROV[LISTA]=$C$2)* (DESC_PROV[DESCUENTO]) )), ((B13*(1+IFERROR(VLOOKUP($D$2,COLORES[],2,FALSE),0))) + C13 + E13) *(1-SUMPRODUCT( (DESC_PROV[LINEA]=$B$2)* (DESC_PROV[LISTA]=$C$2)* (DESC_PROV[DESCUENTO]) )) *(1+VLOOKUP($C$2,LISTAS[],2,FALSE)) *(1+VLOOKUP($C$2,LISTAS[],3,FALSE)) ) /5,0)*5,0) -> 85390 | J13: =IFERROR( ROUND( IF($A$2="COSTO", (D13*(1+IFERROR(VLOOKUP($D$2,COLORES[],2,FALSE),0))) *(1-SUMPRODUCT( (DESC_PROV[LINEA]=$B$2)* (DESC_PROV[LISTA]=$C$2)* (DESC_PROV[DESCUENTO]) )), (D13*(1+IFERROR(VLOOKUP($D$2,COLORES[],2,FALSE),0))) *(1-SUMPRODUCT( (DESC_PROV[LINEA]=$B$2)* (DESC_PROV[LISTA]=$C$2)* (DESC_PROV[DESCUENTO]) )) *(1+VLOOKUP($C$2,LISTAS[],2,FALSE)) *(1+VLOOKUP($C$2,LISTAS[],4,FALSE)) ) /5,0)*5,0) -> 29815 | K13: =IFERROR( ROUND( IF($A$2="COSTO", (B13*(1+IFERROR(VLOOKUP($D$2,COLORES[],2,FALSE),0))+E13) *(1+VLOOKUP($C$2,LISTAS[],5,FALSE)) *(1-SUMPRODUCT( (DESC_PROV[LINEA]=$B$2)* (DESC_PROV[LISTA]=$C$2)* (DESC_PROV[DESCUENTO]) )), (B13*(1+IFERROR(VLOOKUP($D$2,COLORES[],2,FALSE),0))+E13) *(1-SUMPRODUCT( (DESC_PROV[LINEA]=$B$2)* (DESC_PROV[LISTA]=$C$2)* (DESC_PROV[DESCUENTO]) )) *(1+VLOOKUP($C$2,LISTAS[],5,FALSE)) *(1+VLOOKUP($C$2,LISTAS[],2,FALSE)) *(1+VLOOKUP($C$2,LISTAS[],3,FALSE)) ) /5,0)*5,0) -> 99910
A14: 60x0,60 | B14: 29942 | C14: 10325 | D14: 11693 | E14: 4254 | G14: 60x0,60 | H14: =IFERROR( ROUND( IF($A$2="COSTO", ((B14*(1+IFERROR(VLOOKUP($D$2,COLORES[],2,FALSE),0)))+E14) *(1-SUMPRODUCT( (DESC_PROV[LINEA]=$B$2)* (DESC_PROV[LISTA]=$C$2)* (DESC_PROV[DESCUENTO]) )), ((B14*(1+IFERROR(VLOOKUP($D$2,COLORES[],2,FALSE),0)))+E14) *(1-SUMPRODUCT( (DESC_PROV[LINEA]=$B$2)* (DESC_PROV[LISTA]=$C$2)* (DESC_PROV[DESCUENTO]) )) *(1+VLOOKUP($C$2,LISTAS[],2,FALSE)) *(1+VLOOKUP($C$2,LISTAS[],3,FALSE)) ) /5,0)*5,0) -> 42410 | I14: =IFERROR( ROUND( IF($A$2="COSTO", ((B14*(1+IFERROR(VLOOKUP($D$2,COLORES[],2,FALSE),0))) + C14 + E14) *(1-SUMPRODUCT( (DESC_PROV[LINEA]=$B$2)* (DESC_PROV[LISTA]=$C$2)* (DESC_PROV[DESCUENTO]) )), ((B14*(1+IFERROR(VLOOKUP($D$2,COLORES[],2,FALSE),0))) + C14 + E14) *(1-SUMPRODUCT( (DESC_PROV[LINEA]=$B$2)* (DESC_PROV[LISTA]=$C$2)* (DESC_PROV[DESCUENTO]) )) *(1+VLOOKUP($C$2,LISTAS[],2,FALSE)) *(1+VLOOKUP($C$2,LISTAS[],3,FALSE)) ) /5,0)*5,0) -> 55215 | J14: =IFERROR( ROUND( IF($A$2="COSTO", (D14*(1+IFERROR(VLOOKUP($D$2,COLORES[],2,FALSE),0))) *(1-SUMPRODUCT( (DESC_PROV[LINEA]=$B$2)* (DESC_PROV[LISTA]=$C$2)* (DESC_PROV[DESCUENTO]) )), (D14*(1+IFERROR(VLOOKUP($D$2,COLORES[],2,FALSE),0))) *(1-SUMPRODUCT( (DESC_PROV[LINEA]=$B$2)* (DESC_PROV[LISTA]=$C$2)* (DESC_PROV[DESCUENTO]) )) *(1+VLOOKUP($C$2,LISTAS[],2,FALSE)) *(1+VLOOKUP($C$2,LISTAS[],4,FALSE)) ) /5,0)*5,0) -> 17850 | K14: =IFERROR( ROUND( IF($A$2="COSTO", (B14*(1+IFERROR(VLOOKUP($D$2,COLORES[],2,FALSE),0))+E14) *(1+VLOOKUP($C$2,LISTAS[],5,FALSE)) *(1-SUMPRODUCT( (DESC_PROV[LINEA]=$B$2)* (DESC_PROV[LISTA]=$C$2)* (DESC_PROV[DESCUENTO]) )), (B14*(1+IFERROR(VLOOKUP($D$2,COLORES[],2,FALSE),0))+E14) *(1-SUMPRODUCT( (DESC_PROV[LINEA]=$B$2)* (DESC_PROV[LISTA]=$C$2)* (DESC_PROV[DESCUENTO]) )) *(1+VLOOKUP($C$2,LISTAS[],5,FALSE)) *(1+VLOOKUP($C$2,LISTAS[],2,FALSE)) *(1+VLOOKUP($C$2,LISTAS[],3,FALSE)) ) /5,0)*5,0) -> 55135
A15: 80x0,60 | B15: 36210 | C15: 10325 | D15: 13440 | E15: 5952 | G15: 80x0,60 | H15: =IFERROR( ROUND( IF($A$2="COSTO", ((B15*(1+IFERROR(VLOOKUP($D$2,COLORES[],2,FALSE),0)))+E15) *(1-SUMPRODUCT( (DESC_PROV[LINEA]=$B$2)* (DESC_PROV[LISTA]=$C$2)* (DESC_PROV[DESCUENTO]) )), ((B15*(1+IFERROR(VLOOKUP($D$2,COLORES[],2,FALSE),0)))+E15) *(1-SUMPRODUCT( (DESC_PROV[LINEA]=$B$2)* (DESC_PROV[LISTA]=$C$2)* (DESC_PROV[DESCUENTO]) )) *(1+VLOOKUP($C$2,LISTAS[],2,FALSE)) *(1+VLOOKUP($C$2,LISTAS[],3,FALSE)) ) /5,0)*5,0) -> 52290 | I15: =IFERROR( ROUND( IF($A$2="COSTO", ((B15*(1+IFERROR(VLOOKUP($D$2,COLORES[],2,FALSE),0))) + C15 + E15) *(1-SUMPRODUCT( (DESC_PROV[LINEA]=$B$2)* (DESC_PROV[LISTA]=$C$2)* (DESC_PROV[DESCUENTO]) )), ((B15*(1+IFERROR(VLOOKUP($D$2,COLORES[],2,FALSE),0))) + C15 + E15) *(1-SUMPRODUCT( (DESC_PROV[LINEA]=$B$2)* (DESC_PROV[LISTA]=$C$2)* (DESC_PROV[DESCUENTO]) )) *(1+VLOOKUP($C$2,LISTAS[],2,FALSE)) *(1+VLOOKUP($C$2,LISTAS[],3,FALSE)) ) /5,0)*5,0) -> 65095 | J15: =IFERROR( ROUND( IF($A$2="COSTO", (D15*(1+IFERROR(VLOOKUP($D$2,COLORES[],2,FALSE),0))) *(1-SUMPRODUCT( (DESC_PROV[LINEA]=$B$2)* (DESC_PROV[LISTA]=$C$2)* (DESC_PROV[DESCUENTO]) )), (D15*(1+IFERROR(VLOOKUP($D$2,COLORES[],2,FALSE),0))) *(1-SUMPRODUCT( (DESC_PROV[LINEA]=$B$2)* (DESC_PROV[LISTA]=$C$2)* (DESC_PROV[DESCUENTO]) )) *(1+VLOOKUP($C$2,LISTAS[],2,FALSE)) *(1+VLOOKUP($C$2,LISTAS[],4,FALSE)) ) /5,0)*5,0) -> 20515 | K15: =IFERROR( ROUND( IF($A$2="COSTO", (B15*(1+IFERROR(VLOOKUP($D$2,COLORES[],2,FALSE),0))+E15) *(1+VLOOKUP($C$2,LISTAS[],5,FALSE)) *(1-SUMPRODUCT( (DESC_PROV[LINEA]=$B$2)* (DESC_PROV[LISTA]=$C$2)* (DESC_PROV[DESCUENTO]) )), (B15*(1+IFERROR(VLOOKUP($D$2,COLORES[],2,FALSE),0))+E15) *(1-SUMPRODUCT( (DESC_PROV[LINEA]=$B$2)* (DESC_PROV[LISTA]=$C$2)* (DESC_PROV[DESCUENTO]) )) *(1+VLOOKUP($C$2,LISTAS[],5,FALSE)) *(1+VLOOKUP($C$2,LISTAS[],2,FALSE)) *(1+VLOOKUP($C$2,LISTAS[],3,FALSE)) ) /5,0)*5,0) -> 67975
A16: 100x0,60 | B16: 39270 | C16: 10325 | D16: 15187 | E16: 7656 | G16: 100x0,60 | H16: =IFERROR( ROUND( IF($A$2="COSTO", ((B16*(1+IFERROR(VLOOKUP($D$2,COLORES[],2,FALSE),0)))+E16) *(1-SUMPRODUCT( (DESC_PROV[LINEA]=$B$2)* (DESC_PROV[LISTA]=$C$2)* (DESC_PROV[DESCUENTO]) )), ((B16*(1+IFERROR(VLOOKUP($D$2,COLORES[],2,FALSE),0)))+E16) *(1-SUMPRODUCT( (DESC_PROV[LINEA]=$B$2)* (DESC_PROV[LISTA]=$C$2)* (DESC_PROV[DESCUENTO]) )) *(1+VLOOKUP($C$2,LISTAS[],2,FALSE)) *(1+VLOOKUP($C$2,LISTAS[],3,FALSE)) ) /5,0)*5,0) -> 58200 | I16: =IFERROR( ROUND( IF($A$2="COSTO", ((B16*(1+IFERROR(VLOOKUP($D$2,COLORES[],2,FALSE),0))) + C16 + E16) *(1-SUMPRODUCT( (DESC_PROV[LINEA]=$B$2)* (DESC_PROV[LISTA]=$C$2)* (DESC_PROV[DESCUENTO]) )), ((B16*(1+IFERROR(VLOOKUP($D$2,COLORES[],2,FALSE),0))) + C16 + E16) *(1-SUMPRODUCT( (DESC_PROV[LINEA]=$B$2)* (DESC_PROV[LISTA]=$C$2)* (DESC_PROV[DESCUENTO]) )) *(1+VLOOKUP($C$2,LISTAS[],2,FALSE)) *(1+VLOOKUP($C$2,LISTAS[],3,FALSE)) ) /5,0)*5,0) -> 71005 | J16: =IFERROR( ROUND( IF($A$2="COSTO", (D16*(1+IFERROR(VLOOKUP($D$2,COLORES[],2,FALSE),0))) *(1-SUMPRODUCT( (DESC_PROV[LINEA]=$B$2)* (DESC_PROV[LISTA]=$C$2)* (DESC_PROV[DESCUENTO]) )), (D16*(1+IFERROR(VLOOKUP($D$2,COLORES[],2,FALSE),0))) *(1-SUMPRODUCT( (DESC_PROV[LINEA]=$B$2)* (DESC_PROV[LISTA]=$C$2)* (DESC_PROV[DESCUENTO]) )) *(1+VLOOKUP($C$2,LISTAS[],2,FALSE)) *(1+VLOOKUP($C$2,LISTAS[],4,FALSE)) ) /5,0)*5,0) -> 23180 | K16: =IFERROR( ROUND( IF($A$2="COSTO", (B16*(1+IFERROR(VLOOKUP($D$2,COLORES[],2,FALSE),0))+E16) *(1+VLOOKUP($C$2,LISTAS[],5,FALSE)) *(1-SUMPRODUCT( (DESC_PROV[LINEA]=$B$2)* (DESC_PROV[LISTA]=$C$2)* (DESC_PROV[DESCUENTO]) )), (B16*(1+IFERROR(VLOOKUP($D$2,COLORES[],2,FALSE),0))+E16) *(1-SUMPRODUCT( (DESC_PROV[LINEA]=$B$2)* (DESC_PROV[LISTA]=$C$2)* (DESC_PROV[DESCUENTO]) )) *(1+VLOOKUP($C$2,LISTAS[],5,FALSE)) *(1+VLOOKUP($C$2,LISTAS[],2,FALSE)) *(1+VLOOKUP($C$2,LISTAS[],3,FALSE)) ) /5,0)*5,0) -> 75655
A17: 120x0,60 | B17: 42616 | C17: 10325 | D17: 16934 | E17: 9354 | G17: 120x0,60 | H17: =IFERROR( ROUND( IF($A$2="COSTO", ((B17*(1+IFERROR(VLOOKUP($D$2,COLORES[],2,FALSE),0)))+E17) *(1-SUMPRODUCT( (DESC_PROV[LINEA]=$B$2)* (DESC_PROV[LISTA]=$C$2)* (DESC_PROV[DESCUENTO]) )), ((B17*(1+IFERROR(VLOOKUP($D$2,COLORES[],2,FALSE),0)))+E17) *(1-SUMPRODUCT( (DESC_PROV[LINEA]=$B$2)* (DESC_PROV[LISTA]=$C$2)* (DESC_PROV[DESCUENTO]) )) *(1+VLOOKUP($C$2,LISTAS[],2,FALSE)) *(1+VLOOKUP($C$2,LISTAS[],3,FALSE)) ) /5,0)*5,0) -> 64455 | I17: =IFERROR( ROUND( IF($A$2="COSTO", ((B17*(1+IFERROR(VLOOKUP($D$2,COLORES[],2,FALSE),0))) + C17 + E17) *(1-SUMPRODUCT( (DESC_PROV[LINEA]=$B$2)* (DESC_PROV[LISTA]=$C$2)* (DESC_PROV[DESCUENTO]) )), ((B17*(1+IFERROR(VLOOKUP($D$2,COLORES[],2,FALSE),0))) + C17 + E17) *(1-SUMPRODUCT( (DESC_PROV[LINEA]=$B$2)* (DESC_PROV[LISTA]=$C$2)* (DESC_PROV[DESCUENTO]) )) *(1+VLOOKUP($C$2,LISTAS[],2,FALSE)) *(1+VLOOKUP($C$2,LISTAS[],3,FALSE)) ) /5,0)*5,0) -> 77260 | J17: =IFERROR( ROUND( IF($A$2="COSTO", (D17*(1+IFERROR(VLOOKUP($D$2,COLORES[],2,FALSE),0))) *(1-SUMPRODUCT( (DESC_PROV[LINEA]=$B$2)* (DESC_PROV[LISTA]=$C$2)* (DESC_PROV[DESCUENTO]) )), (D17*(1+IFERROR(VLOOKUP($D$2,COLORES[],2,FALSE),0))) *(1-SUMPRODUCT( (DESC_PROV[LINEA]=$B$2)* (DESC_PROV[LISTA]=$C$2)* (DESC_PROV[DESCUENTO]) )) *(1+VLOOKUP($C$2,LISTAS[],2,FALSE)) *(1+VLOOKUP($C$2,LISTAS[],4,FALSE)) ) /5,0)*5,0) -> 25850 | K17: =IFERROR( ROUND( IF($A$2="COSTO", (B17*(1+IFERROR(VLOOKUP($D$2,COLORES[],2,FALSE),0))+E17) *(1+VLOOKUP($C$2,LISTAS[],5,FALSE)) *(1-SUMPRODUCT( (DESC_PROV[LINEA]=$B$2)* (DESC_PROV[LISTA]=$C$2)* (DESC_PROV[DESCUENTO]) )), (B17*(1+IFERROR(VLOOKUP($D$2,COLORES[],2,FALSE),0))+E17) *(1-SUMPRODUCT( (DESC_PROV[LINEA]=$B$2)* (DESC_PROV[LISTA]=$C$2)* (DESC_PROV[DESCUENTO]) )) *(1+VLOOKUP($C$2,LISTAS[],5,FALSE)) *(1+VLOOKUP($C$2,LISTAS[],2,FALSE)) *(1+VLOOKUP($C$2,LISTAS[],3,FALSE)) ) /5,0)*5,0) -> 83790
A18: 150x0,60 | B18: 48395 | C18: 10325 | D18: 19555 | E18: 11910 | G18: 150x0,60 | H18: =IFERROR( ROUND( IF($A$2="COSTO", ((B18*(1+IFERROR(VLOOKUP($D$2,COLORES[],2,FALSE),0)))+E18) *(1-SUMPRODUCT( (DESC_PROV[LINEA]=$B$2)* (DESC_PROV[LISTA]=$C$2)* (DESC_PROV[DESCUENTO]) )), ((B18*(1+IFERROR(VLOOKUP($D$2,COLORES[],2,FALSE),0)))+E18) *(1-SUMPRODUCT( (DESC_PROV[LINEA]=$B$2)* (DESC_PROV[LISTA]=$C$2)* (DESC_PROV[DESCUENTO]) )) *(1+VLOOKUP($C$2,LISTAS[],2,FALSE)) *(1+VLOOKUP($C$2,LISTAS[],3,FALSE)) ) /5,0)*5,0) -> 74790 | I18: =IFERROR( ROUND( IF($A$2="COSTO", ((B18*(1+IFERROR(VLOOKUP($D$2,COLORES[],2,FALSE),0))) + C18 + E18) *(1-SUMPRODUCT( (DESC_PROV[LINEA]=$B$2)* (DESC_PROV[LISTA]=$C$2)* (DESC_PROV[DESCUENTO]) )), ((B18*(1+IFERROR(VLOOKUP($D$2,COLORES[],2,FALSE),0))) + C18 + E18) *(1-SUMPRODUCT( (DESC_PROV[LINEA]=$B$2)* (DESC_PROV[LISTA]=$C$2)* (DESC_PROV[DESCUENTO]) )) *(1+VLOOKUP($C$2,LISTAS[],2,FALSE)) *(1+VLOOKUP($C$2,LISTAS[],3,FALSE)) ) /5,0)*5,0) -> 87595 | J18: =IFERROR( ROUND( IF($A$2="COSTO", (D18*(1+IFERROR(VLOOKUP($D$2,COLORES[],2,FALSE),0))) *(1-SUMPRODUCT( (DESC_PROV[LINEA]=$B$2)* (DESC_PROV[LISTA]=$C$2)* (DESC_PROV[DESCUENTO]) )), (D18*(1+IFERROR(VLOOKUP($D$2,COLORES[],2,FALSE),0))) *(1-SUMPRODUCT( (DESC_PROV[LINEA]=$B$2)* (DESC_PROV[LISTA]=$C$2)* (DESC_PROV[DESCUENTO]) )) *(1+VLOOKUP($C$2,LISTAS[],2,FALSE)) *(1+VLOOKUP($C$2,LISTAS[],4,FALSE)) ) /5,0)*5,0) -> 29850 | K18: =IFERROR( ROUND( IF($A$2="COSTO", (B18*(1+IFERROR(VLOOKUP($D$2,COLORES[],2,FALSE),0))+E18) *(1+VLOOKUP($C$2,LISTAS[],5,FALSE)) *(1-SUMPRODUCT( (DESC_PROV[LINEA]=$B$2)* (DESC_PROV[LISTA]=$C$2)* (DESC_PROV[DESCUENTO]) )), (B18*(1+IFERROR(VLOOKUP($D$2,COLORES[],2,FALSE),0))+E18) *(1-SUMPRODUCT( (DESC_PROV[LINEA]=$B$2)* (DESC_PROV[LISTA]=$C$2)* (DESC_PROV[DESCUENTO]) )) *(1+VLOOKUP($C$2,LISTAS[],5,FALSE)) *(1+VLOOKUP($C$2,LISTAS[],2,FALSE)) *(1+VLOOKUP($C$2,LISTAS[],3,FALSE)) ) /5,0)*5,0) -> 97225
A19: 180x0,60 | B19: 53060 | C19: 10325 | D19: 22176 | E19: 14460 | G19: 180x0,60 | H19: =IFERROR( ROUND( IF($A$2="COSTO", ((B19*(1+IFERROR(VLOOKUP($D$2,COLORES[],2,FALSE),0)))+E19) *(1-SUMPRODUCT( (DESC_PROV[LINEA]=$B$2)* (DESC_PROV[LISTA]=$C$2)* (DESC_PROV[DESCUENTO]) )), ((B19*(1+IFERROR(VLOOKUP($D$2,COLORES[],2,FALSE),0)))+E19) *(1-SUMPRODUCT( (DESC_PROV[LINEA]=$B$2)* (DESC_PROV[LISTA]=$C$2)* (DESC_PROV[DESCUENTO]) )) *(1+VLOOKUP($C$2,LISTAS[],2,FALSE)) *(1+VLOOKUP($C$2,LISTAS[],3,FALSE)) ) /5,0)*5,0) -> 83740 | I19: =IFERROR( ROUND( IF($A$2="COSTO", ((B19*(1+IFERROR(VLOOKUP($D$2,COLORES[],2,FALSE),0))) + C19 + E19) *(1-SUMPRODUCT( (DESC_PROV[LINEA]=$B$2)* (DESC_PROV[LISTA]=$C$2)* (DESC_PROV[DESCUENTO]) )), ((B19*(1+IFERROR(VLOOKUP($D$2,COLORES[],2,FALSE),0))) + C19 + E19) *(1-SUMPRODUCT( (DESC_PROV[LINEA]=$B$2)* (DESC_PROV[LISTA]=$C$2)* (DESC_PROV[DESCUENTO]) )) *(1+VLOOKUP($C$2,LISTAS[],2,FALSE)) *(1+VLOOKUP($C$2,LISTAS[],3,FALSE)) ) /5,0)*5,0) -> 96545 | J19: =IFERROR( ROUND( IF($A$2="COSTO", (D19*(1+IFERROR(VLOOKUP($D$2,COLORES[],2,FALSE),0))) *(1-SUMPRODUCT( (DESC_PROV[LINEA]=$B$2)* (DESC_PROV[LISTA]=$C$2)* (DESC_PROV[DESCUENTO]) )), (D19*(1+IFERROR(VLOOKUP($D$2,COLORES[],2,FALSE),0))) *(1-SUMPRODUCT( (DESC_PROV[LINEA]=$B$2)* (DESC_PROV[LISTA]=$C$2)* (DESC_PROV[DESCUENTO]) )) *(1+VLOOKUP($C$2,LISTAS[],2,FALSE)) *(1+VLOOKUP($C$2,LISTAS[],4,FALSE)) ) /5,0)*5,0) -> 33850 | K19: =IFERROR( ROUND( IF($A$2="COSTO", (B19*(1+IFERROR(VLOOKUP($D$2,COLORES[],2,FALSE),0))+E19) *(1+VLOOKUP($C$2,LISTAS[],5,FALSE)) *(1-SUMPRODUCT( (DESC_PROV[LINEA]=$B$2)* (DESC_PROV[LISTA]=$C$2)* (DESC_PROV[DESCUENTO]) )), (B19*(1+IFERROR(VLOOKUP($D$2,COLORES[],2,FALSE),0))+E19) *(1-SUMPRODUCT( (DESC_PROV[LINEA]=$B$2)* (DESC_PROV[LISTA]=$C$2)* (DESC_PROV[DESCUENTO]) )) *(1+VLOOKUP($C$2,LISTAS[],5,FALSE)) *(1+VLOOKUP($C$2,LISTAS[],2,FALSE)) *(1+VLOOKUP($C$2,LISTAS[],3,FALSE)) ) /5,0)*5,0) -> 108860
... A59: 240x200 | B59: 127846 | C59: 34418 | D59: 61286 | E59: 78246 | G59: 240x200 | H59: =IFERROR( ROUND( IF($A$2="COSTO", ((B59*(1+IFERROR(VLOOKUP($D$2,COLORES[],2,FALSE),0)))+E59) *(1-SUMPRODUCT( (DESC_PROV[LINEA]=$B$2)* (DESC_PROV[LISTA]=$C$2)* (DESC_PROV[DESCUENTO]) )), ((B59*(1+IFERROR(VLOOKUP($D$2,COLORES[],2,FALSE),0)))+E59) *(1-SUMPRODUCT( (DESC_PROV[LINEA]=$B$2)* (DESC_PROV[LISTA]=$C$2)* (DESC_PROV[DESCUENTO]) )) *(1+VLOOKUP($C$2,LISTAS[],2,FALSE)) *(1+VLOOKUP($C$2,LISTAS[],3,FALSE)) ) /5,0)*5,0) -> 255595 | I59: =IFERROR( ROUND( IF($A$2="COSTO", ((B59*(1+IFERROR(VLOOKUP($D$2,COLORES[],2,FALSE),0))) + C59 + E59) *(1-SUMPRODUCT( (DESC_PROV[LINEA]=$B$2)* (DESC_PROV[LISTA]=$C$2)* (DESC_PROV[DESCUENTO]) )), ((B59*(1+IFERROR(VLOOKUP($D$2,COLORES[],2,FALSE),0))) + C59 + E59) *(1-SUMPRODUCT( (DESC_PROV[LINEA]=$B$2)* (DESC_PROV[LISTA]=$C$2)* (DESC_PROV[DESCUENTO]) )) *(1+VLOOKUP($C$2,LISTAS[],2,FALSE)) *(1+VLOOKUP($C$2,LISTAS[],3,FALSE)) ) /5,0)*5,0) -> 298280 | J59: =IFERROR( ROUND( IF($A$2="COSTO", (D59*(1+IFERROR(VLOOKUP($D$2,COLORES[],2,FALSE),0))) *(1-SUMPRODUCT( (DESC_PROV[LINEA]=$B$2)* (DESC_PROV[LISTA]=$C$2)* (DESC_PROV[DESCUENTO]) )), (D59*(1+IFERROR(VLOOKUP($D$2,COLORES[],2,FALSE),0))) *(1-SUMPRODUCT( (DESC_PROV[LINEA]=$B$2)* (DESC_PROV[LISTA]=$C$2)* (DESC_PROV[DESCUENTO]) )) *(1+VLOOKUP($C$2,LISTAS[],2,FALSE)) *(1+VLOOKUP($C$2,LISTAS[],4,FALSE)) ) /5,0)*5,0) -> 93545 | K59: =IFERROR( ROUND( IF($A$2="COSTO", (B59*(1+IFERROR(VLOOKUP($D$2,COLORES[],2,FALSE),0))+E59) *(1+VLOOKUP($C$2,LISTAS[],5,FALSE)) *(1-SUMPRODUCT( (DESC_PROV[LINEA]=$B$2)* (DESC_PROV[LISTA]=$C$2)* (DESC_PROV[DESCUENTO]) )), (B59*(1+IFERROR(VLOOKUP($D$2,COLORES[],2,FALSE),0))+E59) *(1-SUMPRODUCT( (DESC_PROV[LINEA]=$B$2)* (DESC_PROV[LISTA]=$C$2)* (DESC_PROV[DESCUENTO]) )) *(1+VLOOKUP($C$2,LISTAS[],5,FALSE)) *(1+VLOOKUP($C$2,LISTAS[],2,FALSE)) *(1+VLOOKUP($C$2,LISTAS[],3,FALSE)) ) /5,0)*5,0) -> 332275
A60: 240x205 | B60: =B59*(1+5%) -> 134238.3 | C60: =C59*(1+5%) -> 36138.9 | D60: =D59*(1+5%) -> 64350.3 | E60: =E59*(1+5%) -> 82158.3 | G60: 240x205 | H60: =IFERROR( ROUND( IF($A$2="COSTO", ((B60*(1+IFERROR(VLOOKUP($D$2,COLORES[],2,FALSE),0)))+E60) *(1-SUMPRODUCT( (DESC_PROV[LINEA]=$B$2)* (DESC_PROV[LISTA]=$C$2)* (DESC_PROV[DESCUENTO]) )), ((B60*(1+IFERROR(VLOOKUP($D$2,COLORES[],2,FALSE),0)))+E60) *(1-SUMPRODUCT( (DESC_PROV[LINEA]=$B$2)* (DESC_PROV[LISTA]=$C$2)* (DESC_PROV[DESCUENTO]) )) *(1+VLOOKUP($C$2,LISTAS[],2,FALSE)) *(1+VLOOKUP($C$2,LISTAS[],3,FALSE)) ) /5,0)*5,0) -> 268375 | I60: =IFERROR( ROUND( IF($A$2="COSTO", ((B60*(1+IFERROR(VLOOKUP($D$2,COLORES[],2,FALSE),0))) + C60 + E60) *(1-SUMPRODUCT( (DESC_PROV[LINEA]=$B$2)* (DESC_PROV[LISTA]=$C$2)* (DESC_PROV[DESCUENTO]) )), ((B60*(1+IFERROR(VLOOKUP($D$2,COLORES[],2,FALSE),0))) + C60 + E60) *(1-SUMPRODUCT( (DESC_PROV[LINEA]=$B$2)* (DESC_PROV[LISTA]=$C$2)* (DESC_PROV[DESCUENTO]) )) *(1+VLOOKUP($C$2,LISTAS[],2,FALSE)) *(1+VLOOKUP($C$2,LISTAS[],3,FALSE)) ) /5,0)*5,0) -> 313195 | J60: =IFERROR( ROUND( IF($A$2="COSTO", (D60*(1+IFERROR(VLOOKUP($D$2,COLORES[],2,FALSE),0))) *(1-SUMPRODUCT( (DESC_PROV[LINEA]=$B$2)* (DESC_PROV[LISTA]=$C$2)* (DESC_PROV[DESCUENTO]) )), (D60*(1+IFERROR(VLOOKUP($D$2,COLORES[],2,FALSE),0))) *(1-SUMPRODUCT( (DESC_PROV[LINEA]=$B$2)* (DESC_PROV[LISTA]=$C$2)* (DESC_PROV[DESCUENTO]) )) *(1+VLOOKUP($C$2,LISTAS[],2,FALSE)) *(1+VLOOKUP($C$2,LISTAS[],4,FALSE)) ) /5,0)*5,0) -> 98225 | K60: =IFERROR( ROUND( IF($A$2="COSTO", (B60*(1+IFERROR(VLOOKUP($D$2,COLORES[],2,FALSE),0))+E60) *(1+VLOOKUP($C$2,LISTAS[],5,FALSE)) *(1-SUMPRODUCT( (DESC_PROV[LINEA]=$B$2)* (DESC_PROV[LISTA]=$C$2)* (DESC_PROV[DESCUENTO]) )), (B60*(1+IFERROR(VLOOKUP($D$2,COLORES[],2,FALSE),0))+E60) *(1-SUMPRODUCT( (DESC_PROV[LINEA]=$B$2)* (DESC_PROV[LISTA]=$C$2)* (DESC_PROV[DESCUENTO]) )) *(1+VLOOKUP($C$2,LISTAS[],5,FALSE)) *(1+VLOOKUP($C$2,LISTAS[],2,FALSE)) *(1+VLOOKUP($C$2,LISTAS[],3,FALSE)) ) /5,0)*5,0) -> 348890

Sheet mosquiteros
A1: MODO | B1: LINEA | C1: LISTA | D1: COLOR | E1: COLOR
A2: =CONTROL!B4 -> VENTA | B2: HERRERO | C2: GUILLE | D2: =CONTROL!D4 -> BLANCO | E2: ='ventana herrero'!C2 -> AMARILLA
A5: MOSQUITEROS (VENTANA COLOCADA)
A6: Medidas | B6: MOSQUITERO | D6: Medidas | E6: MOSQUITERO
A7: 60x0,50 | B7: 11094 | D7: 60x0,50 | E7: =IFERROR( ROUND( IF($A$2="COSTO", B7 *(1+IFERROR(VLOOKUP($D$2,COLORES[],2,FALSE),0)) *(1+VLOOKUP($C$2,LISTAS[],6,FALSE)), B7 *(1+IFERROR(VLOOKUP($D$2,COLORES[],2,FALSE),0)) *(1+VLOOKUP($C$2,LISTAS[],6,FALSE)) *(1+_xlfn.XLOOKUP($C$2,LISTAS[Lista],LISTAS[Mosq])) ),0),0) -> 22046
A8: 80x0,50 | B8: 12830 | D8: 80x0,50 | E8: =IFERROR( ROUND( IF($A$2="COSTO", B8 *(1+IFERROR(VLOOKUP($D$2,COLORES[],2,FALSE),0)) *(1+VLOOKUP($C$2,LISTAS[],6,FALSE)), B8 *(1+IFERROR(VLOOKUP($D$2,COLORES[],2,FALSE),0)) *(1+VLOOKUP($C$2,LISTAS[],6,FALSE)) *(1+_xlfn.XLOOKUP($C$2,LISTAS[Lista],LISTAS[Mosq])) ),0),0) -> 25496
A9: 100x0,50 | B9: 14565 | D9: 100x0,50 | E9: =IFERROR( ROUND( IF($A$2="COSTO", B9 *(1+IFERROR(VLOOKUP($D$2,COLORES[],2,FALSE),0)) *(1+VLOOKUP($C$2,LISTAS[],6,FALSE)), B9 *(1+IFERROR(VLOOKUP($D$2,COLORES[],2,FALSE),0)) *(1+VLOOKUP($C$2,LISTAS[],6,FALSE)) *(1+_xlfn.XLOOKUP($C$2,LISTAS[Lista],LISTAS[Mosq])) ),0),0) -> 28944
A10: 120x0,50 | B10: 16300 | D10: 120x0,50 | E10: =IFERROR( ROUND( IF($A$2="COSTO", B10 *(1+IFERROR(VLOOKUP($D$2,COLORES[],2,FALSE),0)) *(1+VLOOKUP($C$2,LISTAS[],6,FALSE)), B10 *(1+IFERROR(VLOOKUP($D$2,COLORES[],2,FALSE),0)) *(1+VLOOKUP($C$2,LISTAS[],6,FALSE)) *(1+_xlfn.XLOOKUP($C$2,LISTAS[Lista],LISTAS[Mosq])) ),0),0) -> 32391
A11: 150x0,50 | B11: 18905 | D11: 150x0,50 | E11: =IFERROR( ROUND( IF($A$2="COSTO", B11 *(1+IFERROR(VLOOKUP($D$2,COLORES[],2,FALSE),0)) *(1+VLOOKUP($C$2,LISTAS[],6,FALSE)), B11 *(1+IFERROR(VLOOKUP($D$2,COLORES[],2,FALSE),0)) *(1+VLOOKUP($C$2,LISTAS[],6,FALSE)) *(1+_xlfn.XLOOKUP($C$2,LISTAS[Lista],LISTAS[Mosq])) ),0),0) -> 37568
A12: 180x0,50 | B12: 21508 | D12: 180x0,50 | E12: =IFERROR( ROUND( IF($A$2="COSTO", B12 *(1+IFERROR(VLOOKUP($D$2,COLORES[],2,FALSE),0)) *(1+VLOOKUP($C$2,LISTAS[],6,FALSE)), B12 *(1+IFERROR(VLOOKUP($D$2,COLORES[],2,FALSE),0)) *(1+VLOOKUP($C$2,LISTAS[],6,FALSE)) *(1+_xlfn.XLOOKUP($C$2,LISTAS[Lista],LISTAS[Mosq])) ),0),0) -> 42741
A13: 200x0,50 | B13: 23244 | D13: 200x0,50 | E13: =IFERROR( ROUND( IF($A$2="COSTO", B13 *(1+IFERROR(VLOOKUP($D$2,COLORES[],2,FALSE),0)) *(1+VLOOKUP($C$2,LISTAS[],6,FALSE)), B13 *(1+IFERROR(VLOOKUP($D$2,COLORES[],2,FALSE),0)) *(1+VLOOKUP($C$2,LISTAS[],6,FALSE)) *(1+_xlfn.XLOOKUP($C$2,LISTAS[Lista],LISTAS[Mosq])) ),0),0) -> 46190
A14: 80x0,80 | B14: 17580 | D14: 80x0,80 | E14: =IFERROR( ROUND( IF($A$2="COSTO", B14 *(1+IFERROR(VLOOKUP($D$2,COLORES[],2,FALSE),0)) *(1+VLOOKUP($C$2,LISTAS[],6,FALSE)), B14 *(1+IFERROR(VLOOKUP($D$2,COLORES[],2,FALSE),0)) *(1+VLOOKUP($C$2,LISTAS[],6,FALSE)) *(1+_xlfn.XLOOKUP($C$2,LISTAS[Lista],LISTAS[Mosq])) ),0),0) -> 34935
A15: 100x0,80 | B15: 19772 | D15: 100x0,80 | E15: =IFERROR( ROUND( IF($A$2="COSTO", B15 *(1+IFERROR(VLOOKUP($D$2,COLORES[],2,FALSE),0)) *(1+VLOOKUP($C$2,LISTAS[],6,FALSE)), B15 *(1+IFERROR(VLOOKUP($D$2,COLORES[],2,FALSE),0)) *(1+VLOOKUP($C$2,LISTAS[],6,FALSE)) *(1+_xlfn.XLOOKUP($C$2,LISTAS[Lista],LISTAS[Mosq])) ),0),0) -> 39291
A16: 120x0,80 | B16: 21965 | D16: 120x0,80 | E16: =IFERROR( ROUND( IF($A$2="COSTO", B16 *(1+IFERROR(VLOOKUP($D$2,COLORES[],2,FALSE),0)) *(1+VLOOKUP($C$2,LISTAS[],6,FALSE)), B16 *(1+IFERROR(VLOOKUP($D$2,COLORES[],2,FALSE),0)) *(1+VLOOKUP($C$2,LISTAS[],6,FALSE)) *(1+_xlfn.XLOOKUP($C$2,LISTAS[Lista],LISTAS[Mosq])) ),0),0) -> 43649
A17: 150x0,80 | B17: 25254 | D17: 150x0,80 | E17: =IFERROR( ROUND( IF($A$2="COSTO", B17 *(1+IFERROR(VLOOKUP($D$2,COLORES[],2,FALSE),0)) *(1+VLOOKUP($C$2,LISTAS[],6,FALSE)), B17 *(1+IFERROR(VLOOKUP($D$2,COLORES[],2,FALSE),0)) *(1+VLOOKUP($C$2,LISTAS[],6,FALSE)) *(1+_xlfn.XLOOKUP($C$2,LISTAS[Lista],LISTAS[Mosq])) ),0),0) -> 50185
A18: 180x0,80 | B18: 28542 | D18: 180x0,80 | E18: =IFERROR( ROUND( IF($A$2="COSTO", B18 *(1+IFERROR(VLOOKUP($D$2,COLORES[],2,FALSE),0)) *(1+VLOOKUP($C$2,LISTAS[],6,FALSE)), B18 *(1+IFERROR(VLOOKUP($D$2,COLORES[],2,FALSE),0)) *(1+VLOOKUP($C$2,LISTAS[],6,FALSE)) *(1+_xlfn.XLOOKUP($C$2,LISTAS[Lista],LISTAS[Mosq])) ),0),0) -> 56719
... A60: 240x205 | B60: 74000 | D60: 240x205 | E60: =IFERROR( ROUND( IF($A$2="COSTO", B60 *(1+IFERROR(VLOOKUP($D$2,COLORES[],2,FALSE),0)) *(1+VLOOKUP($C$2,LISTAS[],6,FALSE)), B60 *(1+IFERROR(VLOOKUP($D$2,COLORES[],2,FALSE),0)) *(1+VLOOKUP($C$2,LISTAS[],6,FALSE)) *(1+_xlfn.XLOOKUP($C$2,LISTAS[Lista],LISTAS[Mosq])) ),0),0) -> 147053

Sheet rajas herrero
A1: MODO | B1: LINEA | C1: LISTA | D1: COLOR
A2: =CONTROL!B4 -> VENTA | B2: HERRERO | C2: =CONTROL!C4 -> AMARILLA | D2: =CONTROL!D4 -> BLANCO
A5: RAJAS DE ABRIR HERRERO | K5: RAJAS DE ABRIR HERRERO
A6: Medidas | B6: sin vidrio | C6: 3mm | D6: 4mm | E6: 5mm | F6: esmerilado | G6: fantasia | H6: 3+3 | K6: Medidas | L6: 3mm | M6: 4mm | N6: 5mm | O6: esmerilado | P6: fantasia | Q6: 3+3
A7: 40x40 | B7: 30411 | C7: 2448 | D7: 2966 | E7: 3907 | F7: 8458 | G7: 3264 | H7: 12649 | K7: 40x40 | L7: =IFERROR( ROUND( IF($A$2="COSTO", ((B7*(1+IFERROR(VLOOKUP($D$2,COLORES[],2,FALSE),0)))+C7) *(1-SUMPRODUCT( (DESC_PROV[LINEA]=$B$2)* (DESC_PROV[LISTA]=$C$2)* (DESC_PROV[DESCUENTO]) )), ((B7*(1+IFERROR(VLOOKUP($D$2,COLORES[],2,FALSE),0)))+C7) *(1-SUMPRODUCT( (DESC_PROV[LINEA]=$B$2)* (DESC_PROV[LISTA]=$C$2)* (DESC_PROV[DESCUENTO]) )) *(1+VLOOKUP($C$2,LISTAS[],2,FALSE)) *(1+VLOOKUP($C$2,LISTAS[],3,FALSE)) ) /5,0)*5,0) -> 40750 | M7: =IFERROR( ROUND( IF($A$2="COSTO", ((B7*(1+IFERROR(VLOOKUP($D$2,COLORES[],2,FALSE),0)))+D7) *(1-SUMPRODUCT( (DESC_PROV[LINEA]=$B$2)* (DESC_PROV[LISTA]=$C$2)* (DESC_PROV[DESCUENTO]) )), ((B7*(1+IFERROR(VLOOKUP($D$2,COLORES[],2,FALSE),0)))+D7) *(1-SUMPRODUCT( (DESC_PROV[LINEA]=$B$2)* (DESC_PROV[LISTA]=$C$2)* (DESC_PROV[DESCUENTO]) )) *(1+VLOOKUP($C$2,LISTAS[],2,FALSE)) *(1+VLOOKUP($C$2,LISTAS[],3,FALSE)) ) /5,0)*5,0) -> 41395 | N7: =IFERROR( ROUND( IF($A$2="COSTO", ((B7*(1+IFERROR(VLOOKUP($D$2,COLORES[],2,FALSE),0)))+E7) *(1-SUMPRODUCT( (DESC_PROV[LINEA]=$B$2)* (DESC_PROV[LISTA]=$C$2)* (DESC_PROV[DESCUENTO]) )), ((B7*(1+IFERROR(VLOOKUP($D$2,COLORES[],2,FALSE),0)))+E7) *(1-SUMPRODUCT( (DESC_PROV[LINEA]=$B$2)* (DESC_PROV[LISTA]=$C$2)* (DESC_PROV[DESCUENTO]) )) *(1+VLOOKUP($C$2,LISTAS[],2,FALSE)) *(1+VLOOKUP($C$2,LISTAS[],3,FALSE)) ) /5,0)*5,0) -> 42560 | O7: =IFERROR( ROUND( IF($A$2="COSTO", ((B7*(1+IFERROR(VLOOKUP($D$2,COLORES[],2,FALSE),0)))+F7) *(1-SUMPRODUCT( (DESC_PROV[LINEA]=$B$2)* (DESC_PROV[LISTA]=$C$2)* (DESC_PROV[DESCUENTO]) )), ((B7*(1+IFERROR(VLOOKUP($D$2,COLORES[],2,FALSE),0)))+F7) *(1-SUMPRODUCT( (DESC_PROV[LINEA]=$B$2)* (DESC_PROV[LISTA]=$C$2)* (DESC_PROV[DESCUENTO]) )) *(1+VLOOKUP($C$2,LISTAS[],2,FALSE)) *(1+VLOOKUP($C$2,LISTAS[],3,FALSE)) ) /5,0)*5,0) -> 48205 | P7: =IFERROR( ROUND( IF($A$2="COSTO", ((B7*(1+IFERROR(VLOOKUP($D$2,COLORES[],2,FALSE),0)))+G7) *(1-SUMPRODUCT( (DESC_PROV[LINEA]=$B$2)* (DESC_PROV[LISTA]=$C$2)* (DESC_PROV[DESCUENTO]) )), ((B7*(1+IFERROR(VLOOKUP($D$2,COLORES[],2,FALSE),0)))+G7) *(1-SUMPRODUCT( (DESC_PROV[LINEA]=$B$2)* (DESC_PROV[LISTA]=$C$2)* (DESC_PROV[DESCUENTO]) )) *(1+VLOOKUP($C$2,LISTAS[],2,FALSE)) *(1+VLOOKUP($C$2,LISTAS[],3,FALSE)) ) /5,0)*5,0) -> 41765 | Q7: =IFERROR( ROUND( IF($A$2="COSTO", ((B7*(1+IFERROR(VLOOKUP($D$2,COLORES[],2,FALSE),0)))+H7) *(1-SUMPRODUCT( (DESC_PROV[LINEA]=$B$2)* (DESC_PROV[LISTA]=$C$2)* (DESC_PROV[DESCUENTO]) )), ((B7*(1+IFERROR(VLOOKUP($D$2,COLORES[],2,FALSE),0)))+H7) *(1-SUMPRODUCT( (DESC_PROV[LINEA]=$B$2)* (DESC_PROV[LISTA]=$C$2)* (DESC_PROV[DESCUENTO]) )) *(1+VLOOKUP($C$2,LISTAS[],2,FALSE)) *(1+VLOOKUP($C$2,LISTAS[],3,FALSE)) ) /5,0)*5,0) -> 53405
A8: 50x40 | B8: 32505 | C8: 3264 | D8: 3955 | E8: 5213 | F8: 11280 | G8: 4358 | H8: 16877 | K8: 50x40 | L8: =IFERROR( ROUND( IF($A$2="COSTO", ((B8*(1+IFERROR(VLOOKUP($D$2,COLORES[],2,FALSE),0)))+C8) *(1-SUMPRODUCT( (DESC_PROV[LINEA]=$B$2)* (DESC_PROV[LISTA]=$C$2)* (DESC_PROV[DESCUENTO]) )), ((B8*(1+IFERROR(VLOOKUP($D$2,COLORES[],2,FALSE),0)))+C8) *(1-SUMPRODUCT( (DESC_PROV[LINEA]=$B$2)* (DESC_PROV[LISTA]=$C$2)* (DESC_PROV[DESCUENTO]) )) *(1+VLOOKUP($C$2,LISTAS[],2,FALSE)) *(1+VLOOKUP($C$2,LISTAS[],3,FALSE)) ) /5,0)*5,0) -> 44360 | M8: =IFERROR( ROUND( IF($A$2="COSTO", ((B8*(1+IFERROR(VLOOKUP($D$2,COLORES[],2,FALSE),0)))+D8) *(1-SUMPRODUCT( (DESC_PROV[LINEA]=$B$2)* (DESC_PROV[LISTA]=$C$2)* (DESC_PROV[DESCUENTO]) )), ((B8*(1+IFERROR(VLOOKUP($D$2,COLORES[],2,FALSE),0)))+D8) *(1-SUMPRODUCT( (DESC_PROV[LINEA]=$B$2)* (DESC_PROV[LISTA]=$C$2)* (DESC_PROV[DESCUENTO]) )) *(1+VLOOKUP($C$2,LISTAS[],2,FALSE)) *(1+VLOOKUP($C$2,LISTAS[],3,FALSE)) ) /5,0)*5,0) -> 45220 | N8: =IFERROR( ROUND( IF($A$2="COSTO", ((B8*(1+IFERROR(VLOOKUP($D$2,COLORES[],2,FALSE),0)))+E8) *(1-SUMPRODUCT( (DESC_PROV[LINEA]=$B$2)* (DESC_PROV[LISTA]=$C$2)* (DESC_PROV[DESCUENTO]) )), ((B8*(1+IFERROR(VLOOKUP($D$2,COLORES[],2,FALSE),0)))+E8) *(1-SUMPRODUCT( (DESC_PROV[LINEA]=$B$2)* (DESC_PROV[LISTA]=$C$2)* (DESC_PROV[DESCUENTO]) )) *(1+VLOOKUP($C$2,LISTAS[],2,FALSE)) *(1+VLOOKUP($C$2,LISTAS[],3,FALSE)) ) /5,0)*5,0) -> 46780 | O8: =IFERROR( ROUND( IF($A$2="COSTO", ((B8*(1+IFERROR(VLOOKUP($D$2,COLORES[],2,FALSE),0)))+F8) *(1-SUMPRODUCT( (DESC_PROV[LINEA]=$B$2)* (DESC_PROV[LISTA]=$C$2)* (DESC_PROV[DESCUENTO]) )), ((B8*(1+IFERROR(VLOOKUP($D$2,COLORES[],2,FALSE),0)))+F8) *(1-SUMPRODUCT( (DESC_PROV[LINEA]=$B$2)* (DESC_PROV[LISTA]=$C$2)* (DESC_PROV[DESCUENTO]) )) *(1+VLOOKUP($C$2,LISTAS[],2,FALSE)) *(1+VLOOKUP($C$2,LISTAS[],3,FALSE)) ) /5,0)*5,0) -> 54300 | P8: =IFERROR( ROUND( IF($A$2="COSTO", ((B8*(1+IFERROR(VLOOKUP($D$2,COLORES[],2,FALSE),0)))+G8) *(1-SUMPRODUCT( (DESC_PROV[LINEA]=$B$2)* (DESC_PROV[LISTA]=$C$2)* (DESC_PROV[DESCUENTO]) )), ((B8*(1+IFERROR(VLOOKUP($D$2,COLORES[],2,FALSE),0)))+G8) *(1-SUMPRODUCT( (DESC_PROV[LINEA]=$B$2)* (DESC_PROV[LISTA]=$C$2)* (DESC_PROV[DESCUENTO]) )) *(1+VLOOKUP($C$2,LISTAS[],2,FALSE)) *(1+VLOOKUP($C$2,LISTAS[],3,FALSE)) ) /5,0)*5,0) -> 45715 | Q8: =IFERROR( ROUND( IF($A$2="COSTO", ((B8*(1+IFERROR(VLOOKUP($D$2,COLORES[],2,FALSE),0)))+H8) *(1-SUMPRODUCT( (DESC_PROV[LINEA]=$B$2)* (DESC_PROV[LISTA]=$C$2)* (DESC_PROV[DESCUENTO]) )), ((B8*(1+IFERROR(VLOOKUP($D$2,COLORES[],2,FALSE),0)))+H8) *(1-SUMPRODUCT( (DESC_PROV[LINEA]=$B$2)* (DESC_PROV[LISTA]=$C$2)* (DESC_PROV[DESCUENTO]) )) *(1+VLOOKUP($C$2,LISTAS[],2,FALSE)) *(1+VLOOKUP($C$2,LISTAS[],3,FALSE)) ) /5,0)*5,0) -> 61245
A9: 60x40 | B9: 34605 | C9: 4080 | D9: 4944 | E9: 6518 | F9: 14102 | G9: 5453 | H9: 21105 | K9: 60x40 | L9: =IFERROR( ROUND( IF($A$2="COSTO", ((B9*(1+IFERROR(VLOOKUP($D$2,COLORES[],2,FALSE),0)))+C9) *(1-SUMPRODUCT( (DESC_PROV[LINEA]=$B$2)* (DESC_PROV[LISTA]=$C$2)* (DESC_PROV[DESCUENTO]) )), ((B9*(1+IFERROR(VLOOKUP($D$2,COLORES[],2,FALSE),0)))+C9) *(1-SUMPRODUCT( (DESC_PROV[LINEA]=$B$2)* (DESC_PROV[LISTA]=$C$2)* (DESC_PROV[DESCUENTO]) )) *(1+VLOOKUP($C$2,LISTAS[],2,FALSE)) *(1+VLOOKUP($C$2,LISTAS[],3,FALSE)) ) /5,0)*5,0) -> 47975 | M9: =IFERROR( ROUND( IF($A$2="COSTO", ((B9*(1+IFERROR(VLOOKUP($D$2,COLORES[],2,FALSE),0)))+D9) *(1-SUMPRODUCT( (DESC_PROV[LINEA]=$B$2)* (DESC_PROV[LISTA]=$C$2)* (DESC_PROV[DESCUENTO]) )), ((B9*(1+IFERROR(VLOOKUP($D$2,COLORES[],2,FALSE),0)))+D9) *(1-SUMPRODUCT( (DESC_PROV[LINEA]=$B$2)* (DESC_PROV[LISTA]=$C$2)* (DESC_PROV[DESCUENTO]) )) *(1+VLOOKUP($C$2,LISTAS[],2,FALSE)) *(1+VLOOKUP($C$2,LISTAS[],3,FALSE)) ) /5,0)*5,0) -> 49050 | N9: =IFERROR( ROUND( IF($A$2="COSTO", ((B9*(1+IFERROR(VLOOKUP($D$2,COLORES[],2,FALSE),0)))+E9) *(1-SUMPRODUCT( (DESC_PROV[LINEA]=$B$2)* (DESC_PROV[LISTA]=$C$2)* (DESC_PROV[DESCUENTO]) )), ((B9*(1+IFERROR(VLOOKUP($D$2,COLORES[],2,FALSE),0)))+E9) *(1-SUMPRODUCT( (DESC_PROV[LINEA]=$B$2)* (DESC_PROV[LISTA]=$C$2)* (DESC_PROV[DESCUENTO]) )) *(1+VLOOKUP($C$2,LISTAS[],2,FALSE)) *(1+VLOOKUP($C$2,LISTAS[],3,FALSE)) ) /5,0)*5,0) -> 51000 | O9: =IFERROR( ROUND( IF($A$2="COSTO", ((B9*(1+IFERROR(VLOOKUP($D$2,COLORES[],2,FALSE),0)))+F9) *(1-SUMPRODUCT( (DESC_PROV[LINEA]=$B$2)* (DESC_PROV[LISTA]=$C$2)* (DESC_PROV[DESCUENTO]) )), ((B9*(1+IFERROR(VLOOKUP($D$2,COLORES[],2,FALSE),0)))+F9) *(1-SUMPRODUCT( (DESC_PROV[LINEA]=$B$2)* (DESC_PROV[LISTA]=$C$2)* (DESC_PROV[DESCUENTO]) )) *(1+VLOOKUP($C$2,LISTAS[],2,FALSE)) *(1+VLOOKUP($C$2,LISTAS[],3,FALSE)) ) /5,0)*5,0) -> 60405 | P9: =IFERROR( ROUND( IF($A$2="COSTO", ((B9*(1+IFERROR(VLOOKUP($D$2,COLORES[],2,FALSE),0)))+G9) *(1-SUMPRODUCT( (DESC_PROV[LINEA]=$B$2)* (DESC_PROV[LISTA]=$C$2)* (DESC_PROV[DESCUENTO]) )), ((B9*(1+IFERROR(VLOOKUP($D$2,COLORES[],2,FALSE),0)))+G9) *(1-SUMPRODUCT( (DESC_PROV[LINEA]=$B$2)* (DESC_PROV[LISTA]=$C$2)* (DESC_PROV[DESCUENTO]) )) *(1+VLOOKUP($C$2,LISTAS[],2,FALSE)) *(1+VLOOKUP($C$2,LISTAS[],3,FALSE)) ) /5,0)*5,0) -> 49680 | Q9: =IFERROR( ROUND( IF($A$2="COSTO", ((B9*(1+IFERROR(VLOOKUP($D$2,COLORES[],2,FALSE),0)))+H9) *(1-SUMPRODUCT( (DESC_PROV[LINEA]=$B$2)* (DESC_PROV[LISTA]=$C$2)* (DESC_PROV[DESCUENTO]) )), ((B9*(1+IFERROR(VLOOKUP($D$2,COLORES[],2,FALSE),0)))+H9) *(1-SUMPRODUCT( (DESC_PROV[LINEA]=$B$2)* (DESC_PROV[LISTA]=$C$2)* (DESC_PROV[DESCUENTO]) )) *(1+VLOOKUP($C$2,LISTAS[],2,FALSE)) *(1+VLOOKUP($C$2,LISTAS[],3,FALSE)) ) /5,0)*5,0) -> 69090
A10: 70x40 | B10: 36700 | C10: 4896 | D10: 5933 | E10: 7824 | F10: 16925 | G10: 6547 | H10: 25332 | K10: 70x40 | L10: =IFERROR( ROUND( IF($A$2="COSTO", ((B10*(1+IFERROR(VLOOKUP($D$2,COLORES[],2,FALSE),0)))+C10) *(1-SUMPRODUCT( (DESC_PROV[LINEA]=$B$2)* (DESC_PROV[LISTA]=$C$2)* (DESC_PROV[DESCUENTO]) )), ((B10*(1+IFERROR(VLOOKUP($D$2,COLORES[],2,FALSE),0)))+C10) *(1-SUMPRODUCT( (DESC_PROV[LINEA]=$B$2)* (DESC_PROV[LISTA]=$C$2)* (DESC_PROV[DESCUENTO]) )) *(1+VLOOKUP($C$2,LISTAS[],2,FALSE)) *(1+VLOOKUP($C$2,LISTAS[],3,FALSE)) ) /5,0)*5,0) -> 51585 | M10: =IFERROR( ROUND( IF($A$2="COSTO", ((B10*(1+IFERROR(VLOOKUP($D$2,COLORES[],2,FALSE),0)))+D10) *(1-SUMPRODUCT( (DESC_PROV[LINEA]=$B$2)* (DESC_PROV[LISTA]=$C$2)* (DESC_PROV[DESCUENTO]) )), ((B10*(1+IFERROR(VLOOKUP($D$2,COLORES[],2,FALSE),0)))+D10) *(1-SUMPRODUCT( (DESC_PROV[LINEA]=$B$2)* (DESC_PROV[LISTA]=$C$2)* (DESC_PROV[DESCUENTO]) )) *(1+VLOOKUP($C$2,LISTAS[],2,FALSE)) *(1+VLOOKUP($C$2,LISTAS[],3,FALSE)) ) /5,0)*5,0) -> 52875 | N10: =IFERROR( ROUND( IF($A$2="COSTO", ((B10*(1+IFERROR(VLOOKUP($D$2,COLORES[],2,FALSE),0)))+E10) *(1-SUMPRODUCT( (DESC_PROV[LINEA]=$B$2)* (DESC_PROV[LISTA]=$C$2)* (DESC_PROV[DESCUENTO]) )), ((B10*(1+IFERROR(VLOOKUP($D$2,COLORES[],2,FALSE),0)))+E10) *(1-SUMPRODUCT( (DESC_PROV[LINEA]=$B$2)* (DESC_PROV[LISTA]=$C$2)* (DESC_PROV[DESCUENTO]) )) *(1+VLOOKUP($C$2,LISTAS[],2,FALSE)) *(1+VLOOKUP($C$2,LISTAS[],3,FALSE)) ) /5,0)*5,0) -> 55220 | O10: =IFERROR( ROUND( IF($A$2="COSTO", ((B10*(1+IFERROR(VLOOKUP($D$2,COLORES[],2,FALSE),0)))+F10) *(1-SUMPRODUCT( (DESC_PROV[LINEA]=$B$2)* (DESC_PROV[LISTA]=$C$2)* (DESC_PROV[DESCUENTO]) )), ((B10*(1+IFERROR(VLOOKUP($D$2,COLORES[],2,FALSE),0)))+F10) *(1-SUMPRODUCT( (DESC_PROV[LINEA]=$B$2)* (DESC_PROV[LISTA]=$C$2)* (DESC_PROV[DESCUENTO]) )) *(1+VLOOKUP($C$2,LISTAS[],2,FALSE)) *(1+VLOOKUP($C$2,LISTAS[],3,FALSE)) ) /5,0)*5,0) -> 66505 | P10: =IFERROR( ROUND( IF($A$2="COSTO", ((B10*(1+IFERROR(VLOOKUP($D$2,COLORES[],2,FALSE),0)))+G10) *(1-SUMPRODUCT( (DESC_PROV[LINEA]=$B$2)* (DESC_PROV[LISTA]=$C$2)* (DESC_PROV[DESCUENTO]) )), ((B10*(1+IFERROR(VLOOKUP($D$2,COLORES[],2,FALSE),0)))+G10) *(1-SUMPRODUCT( (DESC_PROV[LINEA]=$B$2)* (DESC_PROV[LISTA]=$C$2)* (DESC_PROV[DESCUENTO]) )) *(1+VLOOKUP($C$2,LISTAS[],2,FALSE)) *(1+VLOOKUP($C$2,LISTAS[],3,FALSE)) ) /5,0)*5,0) -> 53635 | Q10: =IFERROR( ROUND( IF($A$2="COSTO", ((B10*(1+IFERROR(VLOOKUP($D$2,COLORES[],2,FALSE),0)))+H10) *(1-SUMPRODUCT( (DESC_PROV[LINEA]=$B$2)* (DESC_PROV[LISTA]=$C$2)* (DESC_PROV[DESCUENTO]) )), ((B10*(1+IFERROR(VLOOKUP($D$2,COLORES[],2,FALSE),0)))+H10) *(1-SUMPRODUCT( (DESC_PROV[LINEA]=$B$2)* (DESC_PROV[LISTA]=$C$2)* (DESC_PROV[DESCUENTO]) )) *(1+VLOOKUP($C$2,LISTAS[],2,FALSE)) *(1+VLOOKUP($C$2,LISTAS[],3,FALSE)) ) /5,0)*5,0) -> 76930
A11: 80x40 | B11: 38794 | C11: 5712 | D11: 6922 | E11: 9130 | F11: 19747 | G11: 7642 | H11: 29560 | K11: 80x40 | L11: =IFERROR( ROUND( IF($A$2="COSTO", ((B11*(1+IFERROR(VLOOKUP($D$2,COLORES[],2,FALSE),0)))+C11) *(1-SUMPRODUCT( (DESC_PROV[LINEA]=$B$2)* (DESC_PROV[LISTA]=$C$2)* (DESC_PROV[DESCUENTO]) )), ((B11*(1+IFERROR(VLOOKUP($D$2,COLORES[],2,FALSE),0)))+C11) *(1-SUMPRODUCT( (DESC_PROV[LINEA]=$B$2)* (DESC_PROV[LISTA]=$C$2)* (DESC_PROV[DESCUENTO]) )) *(1+VLOOKUP($C$2,LISTAS[],2,FALSE)) *(1+VLOOKUP($C$2,LISTAS[],3,FALSE)) ) /5,0)*5,0) -> 55195 | M11: =IFERROR( ROUND( IF($A$2="COSTO", ((B11*(1+IFERROR(VLOOKUP($D$2,COLORES[],2,FALSE),0)))+D11) *(1-SUMPRODUCT( (DESC_PROV[LINEA]=$B$2)* (DESC_PROV[LISTA]=$C$2)* (DESC_PROV[DESCUENTO]) )), ((B11*(1+IFERROR(VLOOKUP($D$2,COLORES[],2,FALSE),0)))+D11) *(1-SUMPRODUCT( (DESC_PROV[LINEA]=$B$2)* (DESC_PROV[LISTA]=$C$2)* (DESC_PROV[DESCUENTO]) )) *(1+VLOOKUP($C$2,LISTAS[],2,FALSE)) *(1+VLOOKUP($C$2,LISTAS[],3,FALSE)) ) /5,0)*5,0) -> 56695 | N11: =IFERROR( ROUND( IF($A$2="COSTO", ((B11*(1+IFERROR(VLOOKUP($D$2,COLORES[],2,FALSE),0)))+E11) *(1-SUMPRODUCT( (DESC_PROV[LINEA]=$B$2)* (DESC_PROV[LISTA]=$C$2)* (DESC_PROV[DESCUENTO]) )), ((B11*(1+IFERROR(VLOOKUP($D$2,COLORES[],2,FALSE),0)))+E11) *(1-SUMPRODUCT( (DESC_PROV[LINEA]=$B$2)* (DESC_PROV[LISTA]=$C$2)* (DESC_PROV[DESCUENTO]) )) *(1+VLOOKUP($C$2,LISTAS[],2,FALSE)) *(1+VLOOKUP($C$2,LISTAS[],3,FALSE)) ) /5,0)*5,0) -> 59435 | O11: =IFERROR( ROUND( IF($A$2="COSTO", ((B11*(1+IFERROR(VLOOKUP($D$2,COLORES[],2,FALSE),0)))+F11) *(1-SUMPRODUCT( (DESC_PROV[LINEA]=$B$2)* (DESC_PROV[LISTA]=$C$2)* (DESC_PROV[DESCUENTO]) )), ((B11*(1+IFERROR(VLOOKUP($D$2,COLORES[],2,FALSE),0)))+F11) *(1-SUMPRODUCT( (DESC_PROV[LINEA]=$B$2)* (DESC_PROV[LISTA]=$C$2)* (DESC_PROV[DESCUENTO]) )) *(1+VLOOKUP($C$2,LISTAS[],2,FALSE)) *(1+VLOOKUP($C$2,LISTAS[],3,FALSE)) ) /5,0)*5,0) -> 72605 | P11: =IFERROR( ROUND( IF($A$2="COSTO", ((B11*(1+IFERROR(VLOOKUP($D$2,COLORES[],2,FALSE),0)))+G11) *(1-SUMPRODUCT( (DESC_PROV[LINEA]=$B$2)* (DESC_PROV[LISTA]=$C$2)* (DESC_PROV[DESCUENTO]) )), ((B11*(1+IFERROR(VLOOKUP($D$2,COLORES[],2,FALSE),0)))+G11) *(1-SUMPRODUCT( (DESC_PROV[LINEA]=$B$2)* (DESC_PROV[LISTA]=$C$2)* (DESC_PROV[DESCUENTO]) )) *(1+VLOOKUP($C$2,LISTAS[],2,FALSE)) *(1+VLOOKUP($C$2,LISTAS[],3,FALSE)) ) /5,0)*5,0) -> 57590 | Q11: =IFERROR( ROUND( IF($A$2="COSTO", ((B11*(1+IFERROR(VLOOKUP($D$2,COLORES[],2,FALSE),0)))+H11) *(1-SUMPRODUCT( (DESC_PROV[LINEA]=$B$2)* (DESC_PROV[LISTA]=$C$2)* (DESC_PROV[DESCUENTO]) )), ((B11*(1+IFERROR(VLOOKUP($D$2,COLORES[],2,FALSE),0)))+H11) *(1-SUMPRODUCT( (DESC_PROV[LINEA]=$B$2)* (DESC_PROV[LISTA]=$C$2)* (DESC_PROV[DESCUENTO]) )) *(1+VLOOKUP($C$2,LISTAS[],2,FALSE)) *(1+VLOOKUP($C$2,LISTAS[],3,FALSE)) ) /5,0)*5,0) -> 84775
A12: 90x40 | B12: 40888 | C12: 6528 | D12: 7910 | E12: 10435 | F12: 22570 | G12: 8736 | H12: 33788 | K12: 90x40 | L12: =IFERROR( ROUND( IF($A$2="COSTO", ((B12*(1+IFERROR(VLOOKUP($D$2,COLORES[],2,FALSE),0)))+C12) *(1-SUMPRODUCT( (DESC_PROV[LINEA]=$B$2)* (DESC_PROV[LISTA]=$C$2)* (DESC_PROV[DESCUENTO]) )), ((B12*(1+IFERROR(VLOOKUP($D$2,COLORES[],2,FALSE),0)))+C12) *(1-SUMPRODUCT( (DESC_PROV[LINEA]=$B$2)* (DESC_PROV[LISTA]=$C$2)* (DESC_PROV[DESCUENTO]) )) *(1+VLOOKUP($C$2,LISTAS[],2,FALSE)) *(1+VLOOKUP($C$2,LISTAS[],3,FALSE)) ) /5,0)*5,0) -> 58805 | M12: =IFERROR( ROUND( IF($A$2="COSTO", ((B12*(1+IFERROR(VLOOKUP($D$2,COLORES[],2,FALSE),0)))+D12) *(1-SUMPRODUCT( (DESC_PROV[LINEA]=$B$2)* (DESC_PROV[LISTA]=$C$2)* (DESC_PROV[DESCUENTO]) )), ((B12*(1+IFERROR(VLOOKUP($D$2,COLORES[],2,FALSE),0)))+D12) *(1-SUMPRODUCT( (DESC_PROV[LINEA]=$B$2)* (DESC_PROV[LISTA]=$C$2)* (DESC_PROV[DESCUENTO]) )) *(1+VLOOKUP($C$2,LISTAS[],2,FALSE)) *(1+VLOOKUP($C$2,LISTAS[],3,FALSE)) ) /5,0)*5,0) -> 60520 | N12: =IFERROR( ROUND( IF($A$2="COSTO", ((B12*(1+IFERROR(VLOOKUP($D$2,COLORES[],2,FALSE),0)))+E12) *(1-SUMPRODUCT( (DESC_PROV[LINEA]=$B$2)* (DESC_PROV[LISTA]=$C$2)* (DESC_PROV[DESCUENTO]) )), ((B12*(1+IFERROR(VLOOKUP($D$2,COLORES[],2,FALSE),0)))+E12) *(1-SUMPRODUCT( (DESC_PROV[LINEA]=$B$2)* (DESC_PROV[LISTA]=$C$2)* (DESC_PROV[DESCUENTO]) )) *(1+VLOOKUP($C$2,LISTAS[],2,FALSE)) *(1+VLOOKUP($C$2,LISTAS[],3,FALSE)) ) /5,0)*5,0) -> 63650 | O12: =IFERROR( ROUND( IF($A$2="COSTO", ((B12*(1+IFERROR(VLOOKUP($D$2,COLORES[],2,FALSE),0)))+F12) *(1-SUMPRODUCT( (DESC_PROV[LINEA]=$B$2)* (DESC_PROV[LISTA]=$C$2)* (DESC_PROV[DESCUENTO]) )), ((B12*(1+IFERROR(VLOOKUP($D$2,COLORES[],2,FALSE),0)))+F12) *(1-SUMPRODUCT( (DESC_PROV[LINEA]=$B$2)* (DESC_PROV[LISTA]=$C$2)* (DESC_PROV[DESCUENTO]) )) *(1+VLOOKUP($C$2,LISTAS[],2,FALSE)) *(1+VLOOKUP($C$2,LISTAS[],3,FALSE)) ) /5,0)*5,0) -> 78700 | P12: =IFERROR( ROUND( IF($A$2="COSTO", ((B12*(1+IFERROR(VLOOKUP($D$2,COLORES[],2,FALSE),0)))+G12) *(1-SUMPRODUCT( (DESC_PROV[LINEA]=$B$2)* (DESC_PROV[LISTA]=$C$2)* (DESC_PROV[DESCUENTO]) )), ((B12*(1+IFERROR(VLOOKUP($D$2,COLORES[],2,FALSE),0)))+G12) *(1-SUMPRODUCT( (DESC_PROV[LINEA]=$B$2)* (DESC_PROV[LISTA]=$C$2)* (DESC_PROV[DESCUENTO]) )) *(1+VLOOKUP($C$2,LISTAS[],2,FALSE)) *(1+VLOOKUP($C$2,LISTAS[],3,FALSE)) ) /5,0)*5,0) -> 61545 | Q12: =IFERROR( ROUND( IF($A$2="COSTO", ((B12*(1+IFERROR(VLOOKUP($D$2,COLORES[],2,FALSE),0)))+H12) *(1-SUMPRODUCT( (DESC_PROV[LINEA]=$B$2)* (DESC_PROV[LISTA]=$C$2)* (DESC_PROV[DESCUENTO]) )), ((B12*(1+IFERROR(VLOOKUP($D$2,COLORES[],2,FALSE),0)))+H12) *(1-SUMPRODUCT( (DESC_PROV[LINEA]=$B$2)* (DESC_PROV[LISTA]=$C$2)* (DESC_PROV[DESCUENTO]) )) *(1+VLOOKUP($C$2,LISTAS[],2,FALSE)) *(1+VLOOKUP($C$2,LISTAS[],3,FALSE)) ) /5,0)*5,0) -> 92615
A13: 100x40 | B13: 42983 | C13: 7344 | D13: 8899 | E13: 11741 | F13: 25392 | G13: 9830 | H13: 38016 | K13: 100x40 | L13: =IFERROR( ROUND( IF($A$2="COSTO", ((B13*(1+IFERROR(VLOOKUP($D$2,COLORES[],2,FALSE),0)))+C13) *(1-SUMPRODUCT( (DESC_PROV[LINEA]=$B$2)* (DESC_PROV[LISTA]=$C$2)* (DESC_PROV[DESCUENTO]) )), ((B13*(1+IFERROR(VLOOKUP($D$2,COLORES[],2,FALSE),0)))+C13) *(1-SUMPRODUCT( (DESC_PROV[LINEA]=$B$2)* (DESC_PROV[LISTA]=$C$2)* (DESC_PROV[DESCUENTO]) )) *(1+VLOOKUP($C$2,LISTAS[],2,FALSE)) *(1+VLOOKUP($C$2,LISTAS[],3,FALSE)) ) /5,0)*5,0) -> 62415 | M13: =IFERROR( ROUND( IF($A$2="COSTO", ((B13*(1+IFERROR(VLOOKUP($D$2,COLORES[],2,FALSE),0)))+D13) *(1-SUMPRODUCT( (DESC_PROV[LINEA]=$B$2)* (DESC_PROV[LISTA]=$C$2)* (DESC_PROV[DESCUENTO]) )), ((B13*(1+IFERROR(VLOOKUP($D$2,COLORES[],2,FALSE),0)))+D13) *(1-SUMPRODUCT( (DESC_PROV[LINEA]=$B$2)* (DESC_PROV[LISTA]=$C$2)* (DESC_PROV[DESCUENTO]) )) *(1+VLOOKUP($C$2,LISTAS[],2,FALSE)) *(1+VLOOKUP($C$2,LISTAS[],3,FALSE)) ) /5,0)*5,0) -> 64345 | N13: =IFERROR( ROUND( IF($A$2="COSTO", ((B13*(1+IFERROR(VLOOKUP($D$2,COLORES[],2,FALSE),0)))+E13) *(1-SUMPRODUCT( (DESC_PROV[LINEA]=$B$2)* (DESC_PROV[LISTA]=$C$2)* (DESC_PROV[DESCUENTO]) )), ((B13*(1+IFERROR(VLOOKUP($D$2,COLORES[],2,FALSE),0)))+E13) *(1-SUMPRODUCT( (DESC_PROV[LINEA]=$B$2)* (DESC_PROV[LISTA]=$C$2)* (DESC_PROV[DESCUENTO]) )) *(1+VLOOKUP($C$2,LISTAS[],2,FALSE)) *(1+VLOOKUP($C$2,LISTAS[],3,FALSE)) ) /5,0)*5,0) -> 67870 | O13: =IFERROR( ROUND( IF($A$2="COSTO", ((B13*(1+IFERROR(VLOOKUP($D$2,COLORES[],2,FALSE),0)))+F13) *(1-SUMPRODUCT( (DESC_PROV[LINEA]=$B$2)* (DESC_PROV[LISTA]=$C$2)* (DESC_PROV[DESCUENTO]) )), ((B13*(1+IFERROR(VLOOKUP($D$2,COLORES[],2,FALSE),0)))+F13) *(1-SUMPRODUCT( (DESC_PROV[LINEA]=$B$2)* (DESC_PROV[LISTA]=$C$2)* (DESC_PROV[DESCUENTO]) )) *(1+VLOOKUP($C$2,LISTAS[],2,FALSE)) *(1+VLOOKUP($C$2,LISTAS[],3,FALSE)) ) /5,0)*5,0) -> 84800 | P13: =IFERROR( ROUND( IF($A$2="COSTO", ((B13*(1+IFERROR(VLOOKUP($D$2,COLORES[],2,FALSE),0)))+G13) *(1-SUMPRODUCT( (DESC_PROV[LINEA]=$B$2)* (DESC_PROV[LISTA]=$C$2)* (DESC_PROV[DESCUENTO]) )), ((B13*(1+IFERROR(VLOOKUP($D$2,COLORES[],2,FALSE),0)))+G13) *(1-SUMPRODUCT( (DESC_PROV[LINEA]=$B$2)* (DESC_PROV[LISTA]=$C$2)* (DESC_PROV[DESCUENTO]) )) *(1+VLOOKUP($C$2,LISTAS[],2,FALSE)) *(1+VLOOKUP($C$2,LISTAS[],3,FALSE)) ) /5,0)*5,0) -> 65500 | Q13: =IFERROR( ROUND( IF($A$2="COSTO", ((B13*(1+IFERROR(VLOOKUP($D$2,COLORES[],2,FALSE),0)))+H13) *(1-SUMPRODUCT( (DESC_PROV[LINEA]=$B$2)* (DESC_PROV[LISTA]=$C$2)* (DESC_PROV[DESCUENTO]) )), ((B13*(1+IFERROR(VLOOKUP($D$2,COLORES[],2,FALSE),0)))+H13) *(1-SUMPRODUCT( (DESC_PROV[LINEA]=$B$2)* (DESC_PROV[LISTA]=$C$2)* (DESC_PROV[DESCUENTO]) )) *(1+VLOOKUP($C$2,LISTAS[],2,FALSE)) *(1+VLOOKUP($C$2,LISTAS[],3,FALSE)) ) /5,0)*5,0) -> 100455
A14: 40x50 | B14: 32505 | C14: 3264 | D14: 3955 | E14: 5213 | F14: 11280 | G14: 4358 | H14: 16877 | K14: 40x50 | L14: =IFERROR( ROUND( IF($A$2="COSTO", ((B14*(1+IFERROR(VLOOKUP($D$2,COLORES[],2,FALSE),0)))+C14) *(1-SUMPRODUCT( (DESC_PROV[LINEA]=$B$2)* (DESC_PROV[LISTA]=$C$2)* (DESC_PROV[DESCUENTO]) )), ((B14*(1+IFERROR(VLOOKUP($D$2,COLORES[],2,FALSE),0)))+C14) *(1-SUMPRODUCT( (DESC_PROV[LINEA]=$B$2)* (DESC_PROV[LISTA]=$C$2)* (DESC_PROV[DESCUENTO]) )) *(1+VLOOKUP($C$2,LISTAS[],2,FALSE)) *(1+VLOOKUP($C$2,LISTAS[],3,FALSE)) ) /5,0)*5,0) -> 44360 | M14: =IFERROR( ROUND( IF($A$2="COSTO", ((B14*(1+IFERROR(VLOOKUP($D$2,COLORES[],2,FALSE),0)))+D14) *(1-SUMPRODUCT( (DESC_PROV[LINEA]=$B$2)* (DESC_PROV[LISTA]=$C$2)* (DESC_PROV[DESCUENTO]) )), ((B14*(1+IFERROR(VLOOKUP($D$2,COLORES[],2,FALSE),0)))+D14) *(1-SUMPRODUCT( (DESC_PROV[LINEA]=$B$2)* (DESC_PROV[LISTA]=$C$2)* (DESC_PROV[DESCUENTO]) )) *(1+VLOOKUP($C$2,LISTAS[],2,FALSE)) *(1+VLOOKUP($C$2,LISTAS[],3,FALSE)) ) /5,0)*5,0) -> 45220 | N14: =IFERROR( ROUND( IF($A$2="COSTO", ((B14*(1+IFERROR(VLOOKUP($D$2,COLORES[],2,FALSE),0)))+E14) *(1-SUMPRODUCT( (DESC_PROV[LINEA]=$B$2)* (DESC_PROV[LISTA]=$C$2)* (DESC_PROV[DESCUENTO]) )), ((B14*(1+IFERROR(VLOOKUP($D$2,COLORES[],2,FALSE),0)))+E14) *(1-SUMPRODUCT( (DESC_PROV[LINEA]=$B$2)* (DESC_PROV[LISTA]=$C$2)* (DESC_PROV[DESCUENTO]) )) *(1+VLOOKUP($C$2,LISTAS[],2,FALSE)) *(1+VLOOKUP($C$2,LISTAS[],3,FALSE)) ) /5,0)*5,0) -> 46780 | O14: =IFERROR( ROUND( IF($A$2="COSTO", ((B14*(1+IFERROR(VLOOKUP($D$2,COLORES[],2,FALSE),0)))+F14) *(1-SUMPRODUCT( (DESC_PROV[LINEA]=$B$2)* (DESC_PROV[LISTA]=$C$2)* (DESC_PROV[DESCUENTO]) )), ((B14*(1+IFERROR(VLOOKUP($D$2,COLORES[],2,FALSE),0)))+F14) *(1-SUMPRODUCT( (DESC_PROV[LINEA]=$B$2)* (DESC_PROV[LISTA]=$C$2)* (DESC_PROV[DESCUENTO]) )) *(1+VLOOKUP($C$2,LISTAS[],2,FALSE)) *(1+VLOOKUP($C$2,LISTAS[],3,FALSE)) ) /5,0)*5,0) -> 54300 | P14: =IFERROR( ROUND( IF($A$2="COSTO", ((B14*(1+IFERROR(VLOOKUP($D$2,COLORES[],2,FALSE),0)))+G14) *(1-SUMPRODUCT( (DESC_PROV[LINEA]=$B$2)* (DESC_PROV[LISTA]=$C$2)* (DESC_PROV[DESCUENTO]) )), ((B14*(1+IFERROR(VLOOKUP($D$2,COLORES[],2,FALSE),0)))+G14) *(1-SUMPRODUCT( (DESC_PROV[LINEA]=$B$2)* (DESC_PROV[LISTA]=$C$2)* (DESC_PROV[DESCUENTO]) )) *(1+VLOOKUP($C$2,LISTAS[],2,FALSE)) *(1+VLOOKUP($C$2,LISTAS[],3,FALSE)) ) /5,0)*5,0) -> 45715 | Q14: =IFERROR( ROUND( IF($A$2="COSTO", ((B14*(1+IFERROR(VLOOKUP($D$2,COLORES[],2,FALSE),0)))+H14) *(1-SUMPRODUCT( (DESC_PROV[LINEA]=$B$2)* (DESC_PROV[LISTA]=$C$2)* (DESC_PROV[DESCUENTO]) )), ((B14*(1+IFERROR(VLOOKUP($D$2,COLORES[],2,FALSE),0)))+H14) *(1-SUMPRODUCT( (DESC_PROV[LINEA]=$B$2)* (DESC_PROV[LISTA]=$C$2)* (DESC_PROV[DESCUENTO]) )) *(1+VLOOKUP($C$2,LISTAS[],2,FALSE)) *(1+VLOOKUP($C$2,LISTAS[],3,FALSE)) ) /5,0)*5,0) -> 61245
A15: 50x50 | B15: 34605 | C15: 4358 | D15: 5270 | E15: 6960 | F15: 15034 | G15: 5808 | H15: 22499 | K15: 50x50 | L15: =IFERROR( ROUND( IF($A$2="COSTO", ((B15*(1+IFERROR(VLOOKUP($D$2,COLORES[],2,FALSE),0)))+C15) *(1-SUMPRODUCT( (DESC_PROV[LINEA]=$B$2)* (DESC_PROV[LISTA]=$C$2)* (DESC_PROV[DESCUENTO]) )), ((B15*(1+IFERROR(VLOOKUP($D$2,COLORES[],2,FALSE),0)))+C15) *(1-SUMPRODUCT( (DESC_PROV[LINEA]=$B$2)* (DESC_PROV[LISTA]=$C$2)* (DESC_PROV[DESCUENTO]) )) *(1+VLOOKUP($C$2,LISTAS[],2,FALSE)) *(1+VLOOKUP($C$2,LISTAS[],3,FALSE)) ) /5,0)*5,0) -> 48320 | M15: =IFERROR( ROUND( IF($A$2="COSTO", ((B15*(1+IFERROR(VLOOKUP($D$2,COLORES[],2,FALSE),0)))+D15) *(1-SUMPRODUCT( (DESC_PROV[LINEA]=$B$2)* (DESC_PROV[LISTA]=$C$2)* (DESC_PROV[DESCUENTO]) )), ((B15*(1+IFERROR(VLOOKUP($D$2,COLORES[],2,FALSE),0)))+D15) *(1-SUMPRODUCT( (DESC_PROV[LINEA]=$B$2)* (DESC_PROV[LISTA]=$C$2)* (DESC_PROV[DESCUENTO]) )) *(1+VLOOKUP($C$2,LISTAS[],2,FALSE)) *(1+VLOOKUP($C$2,LISTAS[],3,FALSE)) ) /5,0)*5,0) -> 49455 | N15: =IFERROR( ROUND( IF($A$2="COSTO", ((B15*(1+IFERROR(VLOOKUP($D$2,COLORES[],2,FALSE),0)))+E15) *(1-SUMPRODUCT( (DESC_PROV[LINEA]=$B$2)* (DESC_PROV[LISTA]=$C$2)* (DESC_PROV[DESCUENTO]) )), ((B15*(1+IFERROR(VLOOKUP($D$2,COLORES[],2,FALSE),0)))+E15) *(1-SUMPRODUCT( (DESC_PROV[LINEA]=$B$2)* (DESC_PROV[LISTA]=$C$2)* (DESC_PROV[DESCUENTO]) )) *(1+VLOOKUP($C$2,LISTAS[],2,FALSE)) *(1+VLOOKUP($C$2,LISTAS[],3,FALSE)) ) /5,0)*5,0) -> 51550 | O15: =IFERROR( ROUND( IF($A$2="COSTO", ((B15*(1+IFERROR(VLOOKUP($D$2,COLORES[],2,FALSE),0)))+F15) *(1-SUMPRODUCT( (DESC_PROV[LINEA]=$B$2)* (DESC_PROV[LISTA]=$C$2)* (DESC_PROV[DESCUENTO]) )), ((B15*(1+IFERROR(VLOOKUP($D$2,COLORES[],2,FALSE),0)))+F15) *(1-SUMPRODUCT( (DESC_PROV[LINEA]=$B$2)* (DESC_PROV[LISTA]=$C$2)* (DESC_PROV[DESCUENTO]) )) *(1+VLOOKUP($C$2,LISTAS[],2,FALSE)) *(1+VLOOKUP($C$2,LISTAS[],3,FALSE)) ) /5,0)*5,0) -> 61560 | P15: =IFERROR( ROUND( IF($A$2="COSTO", ((B15*(1+IFERROR(VLOOKUP($D$2,COLORES[],2,FALSE),0)))+G15) *(1-SUMPRODUCT( (DESC_PROV[LINEA]=$B$2)* (DESC_PROV[LISTA]=$C$2)* (DESC_PROV[DESCUENTO]) )), ((B15*(1+IFERROR(VLOOKUP($D$2,COLORES[],2,FALSE),0)))+G15) *(1-SUMPRODUCT( (DESC_PROV[LINEA]=$B$2)* (DESC_PROV[LISTA]=$C$2)* (DESC_PROV[DESCUENTO]) )) *(1+VLOOKUP($C$2,LISTAS[],2,FALSE)) *(1+VLOOKUP($C$2,LISTAS[],3,FALSE)) ) /5,0)*5,0) -> 50120 | Q15: =IFERROR( ROUND( IF($A$2="COSTO", ((B15*(1+IFERROR(VLOOKUP($D$2,COLORES[],2,FALSE),0)))+H15) *(1-SUMPRODUCT( (DESC_PROV[LINEA]=$B$2)* (DESC_PROV[LISTA]=$C$2)* (DESC_PROV[DESCUENTO]) )), ((B15*(1+IFERROR(VLOOKUP($D$2,COLORES[],2,FALSE),0)))+H15) *(1-SUMPRODUCT( (DESC_PROV[LINEA]=$B$2)* (DESC_PROV[LISTA]=$C$2)* (DESC_PROV[DESCUENTO]) )) *(1+VLOOKUP($C$2,LISTAS[],2,FALSE)) *(1+VLOOKUP($C$2,LISTAS[],3,FALSE)) ) /5,0)*5,0) -> 70820
